Workbook

Sheet Cover
B3: REFINERY OUTAGE ANALYTICS
B4: Capacity Offline (kbd) - Planned & Unplanned - 2027 Scenario & Sensitivity
B7: Primary metric | C7: Capacity offline, thousand barrels/day (kbd) - CAP_OFFLINE_ADJUSTED_KBD
B8: Scope | C8: All US refining units & products; mogas-equivalent shown as a secondary overlay
B9: Data vintage | C9: 46,456 rows | 2010-2038 | PADD {'PAD_DIST': 46456}
B10: Event basis | C10: 19,934 distinct outages (OUTAGE_ID); rows are unit-month slices
B11: Outage type | C11: Binary {PLANNED, UNPLANNED}; UNKNOWN folded into UNPLANNED (desk rule)
B13: Read-Before-Use Caveats
B14: - 2026 & 2027 are PARTIAL / special years - shown grey italic everywhere and never presented as final.
B15: - 2027 is PLANNED-ONLY in the source. Unplanned-2027 is a MODELED scenario, not an actual.
B16: - Comparison guardrail: any Plan+Unplanned or Unplanned comparison vs 2027 shows n/a; only Planned is valid vs 2027.
B17: - 2020-2021 are COVID / Winter-Storm-Uri outliers and are excluded from forecast baselines by default.
B19: Contents
B20: Dashboard | C20: At-a-glance KPIs and headline charts
B21: Summary | C21: Annual table 2016-2027 + targeted year comparisons
B22: Monthly | C22: Total / Planned / Unplanned month x year matrices + seasonality
B23: PADD Charts | C23: Per-PADD planned+unplanned combo charts vs prior years
B24: PADD Detail | C24: PADD x year matrices and unplanned-by-PADD
B25: Units | C25: Unit-category x year matrix + magnitude bars
B26: Refinery Detail | C26: Top refineries, operators and event scatter
B27: Scenario 2027 | C27: Live driver-based 2027 unplanned forecast (dropdowns)
B28: Sensitivity | C28: Two-way heatmap and tornado of the scenario drivers
B29: Mogas Overlay | C29: Secondary mogas-equivalent view
B30: Notes | C30: Sources, methodology and color key

Sheet Dashboard
B2: Outage Dashboard
B3: Headline metrics - latest full year 2025
B5: Total Offline | D5: Unplanned | F5: Unplanned % | H5: Distinct Outages | J5: Top PADD
B6: 38674.074 | D6: 19257.554 | F6: 0.49794479 | H6: 1213 | J6: PADD 5
B8: FY2025 | D8: FY2025 | F8: of total offline | H8: FY2025 | J8: by unplanned kbd
B40: Chart data (capacity offline, kbd)
B41: Year | C41: Planned | D41: Unplanned
B42: 2018 | C42: 20666.894 | D42: 11368.591
B43: 2019 | C43: 24322.195 | D43: 18335.404
B44: 2020 | C44: 25471.736 | D44: 124780.25
B45: 2021 | C45: 25740.734 | D45: 67571.424
B46: 2022 | C46: 24430.711 | D46: 22628.509
B47: 2023 | C47: 26140.246 | D47: 23692.159
B48: 2024 | C48: 20382.496 | D48: 21582.567
B49: 2025 | C49: 19416.52 | D49: 19257.554
B50: 2026 | C50: 12029.062 | D50: 8249.7958
B51: 2027 | C51: 15923.17 | D51: 0
B53: Unplanned by PADD (kbd)
B54: PADD | C54: 2022 | D54: 2023 | E54: 2024 | F54: 2025
B55: PADD 1 | C55: 838.49 | D55: 879.2185 | E55: 758.0088 | F55: 1524.7432
B56: PADD 2 | C56: 6764.0168 | D56: 6640.3387 | E56: 5602.5239 | F56: 2837.6686
B57: PADD 3 | C57: 11315.874 | D57: 11829.262 | E57: 11810.349 | F57: 6051.7432
B58: PADD 4 | C58: 693.9537 | D58: 1470.7124 | E58: 401.7754 | F58: 381.1887
B59: PADD 5 | C59: 3016.1748 | D59: 2872.6275 | E59: 3009.9095 | F59: 8462.2098
B61: Unplanned share by PADD (2025)
B62: PADD 1 | C62: 1524.7432
B63: PADD 2 | C63: 2837.6686
B64: PADD 3 | C64: 6051.7432
B65: PADD 4 | C65: 381.1887
B66: PADD 5 | C66: 8462.2098

Sheet Summary
B2: Annual Summary & Comparisons
B3: Capacity offline (kbd). 2026/27 grey italic; 2027 planned-only.
B6: Annual Capacity Offline (kbd)
B7: Year | C7: Planned | D7: Unplanned | E7: Total | F7: Events | G7: Unpl % | H7: YoY Δ | I7: YoY %
B8: 2016 | C8: 18970.541 | D8: 10026.558 | E8: =C8+D8 -> 0 | F8: 1027 | G8: =IF(E8=0,0,D8/E8) -> 0
B9: 2017 | C9: 19379.438 | D9: 17806.156 | E9: =C9+D9 -> 0 | F9: 1482 | G9: =IF(E9=0,0,D9/E9) -> 0 | H9: =E9-E8 -> 0 | I9: =IF(E8=0,0,H9/E8) -> 0
B10: 2018 | C10: 20666.894 | D10: 11368.591 | E10: =C10+D10 -> 0 | F10: 1360 | G10: =IF(E10=0,0,D10/E10) -> 0 | H10: =E10-E9 -> 0 | I10: =IF(E9=0,0,H10/E9) -> 0
B11: 2019 | C11: 24322.195 | D11: 18335.404 | E11: =C11+D11 -> 0 | F11: 1432 | G11: =IF(E11=0,0,D11/E11) -> 0 | H11: =E11-E10 -> 0 | I11: =IF(E10=0,0,H11/E10) -> 0
B12: 2020 | C12: 25471.736 | D12: 124780.25 | E12: =C12+D12 -> 0 | F12: 3177 | G12: =IF(E12=0,0,D12/E12) -> 0 | H12: =E12-E11 -> 0 | I12: =IF(E11=0,0,H12/E11) -> 0
B13: 2021 | C13: 25740.734 | D13: 67571.424 | E13: =C13+D13 -> 0 | F13: 3060 | G13: =IF(E13=0,0,D13/E13) -> 0 | H13: =E13-E12 -> 0 | I13: =IF(E12=0,0,H13/E12) -> 0
B14: 2022 | C14: 24430.711 | D14: 22628.509 | E14: =C14+D14 -> 0 | F14: 1407 | G14: =IF(E14=0,0,D14/E14) -> 0 | H14: =E14-E13 -> 0 | I14: =IF(E13=0,0,H14/E13) -> 0
B15: 2023 | C15: 26140.246 | D15: 23692.159 | E15: =C15+D15 -> 0 | F15: 1442 | G15: =IF(E15=0,0,D15/E15) -> 0 | H15: =E15-E14 -> 0 | I15: =IF(E14=0,0,H15/E14) -> 0
B16: 2024 | C16: 20382.496 | D16: 21582.567 | E16: =C16+D16 -> 0 | F16: 1529 | G16: =IF(E16=0,0,D16/E16) -> 0 | H16: =E16-E15 -> 0 | I16: =IF(E15=0,0,H16/E15) -> 0
B17: 2025 | C17: 19416.52 | D17: 19257.554 | E17: =C17+D17 -> 0 | F17: 1213 | G17: =IF(E17=0,0,D17/E17) -> 0 | H17: =E17-E16 -> 0 | I17: =IF(E16=0,0,H17/E16) -> 0
B18: 2026 | C18: 12029.062 | D18: 8249.7958 | E18: =C18+D18 -> 0 | F18: 762 | G18: =IF(E18=0,0,D18/E18) -> 0 | H18: =E18-E17 -> 0 | I18: =IF(E17=0,0,H18/E17) -> 0
B19: 2027 | C19: 15923.17 | D19: 0 | E19: =C19+D19 -> 0 | F19: 295 | G19: =IF(E19=0,0,D19/E19) -> 0 | H19: =E19-E18 -> 0 | I19: =IF(E18=0,0,H19/E18) -> 0
B20: Note | C20: 2027 Unplanned = 0 by construction (planned-only year); see Scenario 2027.
B23: Targeted Comparisons (Δ% vs base year)
B24: 2025 → 2026 | C24: 2025 | D24: 2026 | E24: Δ kbd | F24: Δ %
B25: Plan + Unplanned | C25: 38674.074 | D25: 20278.858 | E25: =D25-C25 -> 0 | F25: =IF(C25=0,0,E25/C25) -> 0
B26: Planned | C26: 19416.52 | D26: 12029.062 | E26: =D26-C26 -> 0 | F26: =IF(C26=0,0,E26/C26) -> 0
B27: Unplanned | C27: 19257.554 | D27: 8249.7958 | E27: =D27-C27 -> 0 | F27: =IF(C27=0,0,E27/C27) -> 0
B29: 2025 → 2027 | C29: 2025 | D29: 2027 | E29: Δ kbd | F29: Δ %
B30: Plan + Unplanned | C30: 38674.074 | D30: n/a | E30: n/a | F30: n/a
B31: Planned | C31: 19416.52 | D31: 15923.17 | E31: =D31-C31 -> 0 | F31: =IF(C31=0,0,E31/C31) -> 0
B32: Unplanned | C32: 19257.554 | D32: n/a | E32: n/a | F32: n/a
B34: 2026 → 2027 | C34: 2026 | D34: 2027 | E34: Δ kbd | F34: Δ %
B35: Plan + Unplanned | C35: 20278.858 | D35: n/a | E35: n/a | F35: n/a
B36: Planned | C36: 12029.062 | D36: 15923.17 | E36: =D36-C36 -> 0 | F36: =IF(C36=0,0,E36/C36) -> 0
B37: Unplanned | C37: 8249.7958 | D37: n/a | E37: n/a | F37: n/a
B39: Guardrail: only Planned is comparable vs 2027 (no actual unplanned-2027 exists).

Sheet Monthly
B2: Monthly Detail & Seasonality
B3: Capacity offline (kbd) by month x year.
B6: Total Offline (kbd)
B7: Year | C7: Jan | D7: Feb | E7: Mar | F7: Apr | G7: May | H7: Jun | I7: Jul | J7: Aug | K7: Sep | L7: Oct | M7: Nov | N7: Dec | O7: Total
B8: 2018 | C8: 1861.8575 | D8: 4385.2274 | E8: 3891.1352 | F8: 3200.5971 | G8: 2830.4237 | H8: 1361.831 | I8: 2025.8086 | J8: 1681.6739 | K8: 2841.9706 | L8: 4856.704 | M8: 2295.9006 | N8: 802.355 | O8: =SUM(C8:N8) -> 0
B9: 2019 | C9: 2650.7318 | D9: 4505.4825 | E9: 4628.2857 | F9: 5013.3596 | G9: 3580.2703 | H9: 2407.915 | I9: 1950.0196 | J9: 1652.1333 | K9: 4505.1194 | L9: 6169.3255 | M9: 4039.216 | N9: 1555.7402 | O9: =SUM(C9:N9) -> 0
B10: 2020 | C10: 2838.8157 | D10: 4560.7311 | E10: 5991.9393 | F10: 15337.497 | G10: 15952.93 | H10: 15478.418 | I10: 14921.496 | J10: 14559.496 | K10: 16522.4 | L10: 15931.962 | M10: 13964.712 | N10: 14191.584 | O10: =SUM(C10:N10) -> 0
B11: 2021 | C11: 14117.849 | D11: 19542.512 | E11: 14144.871 | F11: 8194.8163 | G11: 4675.9324 | H11: 3726.4132 | I11: 3463.5479 | J11: 3911.2804 | K11: 7484.5812 | L11: 7180.2097 | M11: 4198.3709 | N11: 2671.7742 | O11: =SUM(C11:N11) -> 0
B12: 2022 | C12: 3778.1429 | D12: 4947.385 | E12: 4010.1805 | F12: 4468.467 | G12: 4077.0188 | H12: 3033.2868 | I12: 3119.4187 | J12: 3037.9164 | K12: 3377.7149 | L12: 5566.1522 | M12: 3205.2054 | N12: 4438.3313 | O12: =SUM(C12:N12) -> 0
B13: 2023 | C13: 5712.3266 | D13: 6813.7157 | E13: 6741.2225 | F13: 6116.2489 | G13: 3819.9794 | H13: 2289.9731 | I13: 1647.0638 | J13: 1759.571 | K13: 3954.8585 | L13: 6931.9118 | M13: 3069.4329 | N13: 976.1005 | O13: =SUM(C13:N13) -> 0
B14: 2024 | C14: 4684.8428 | D14: 8792.021 | E14: 4695.105 | F14: 4532.5513 | G14: 2481.8625 | H14: 2108.9555 | I14: 1985.748 | J14: 1698.4168 | K14: 3566.3252 | L14: 4409.9705 | M14: 2230.0646 | N14: 779.1993 | O14: =SUM(C14:N14) -> 0
B15: 2025 | C15: 3521.0971 | D15: 5027.1616 | E15: 4431.0635 | F15: 5302.0811 | G15: 2654.0926 | H15: 1540.4157 | I15: 1195.17 | J15: 1609.1225 | K15: 3544.1765 | L15: 5848.478 | M15: 3057.862 | N15: 943.353 | O15: =SUM(C15:N15) -> 0
B16: 2026 | C16: 1849.6688 | D16: 3739.2241 | E16: 3152.1816 | F16: 3982.502 | G16: 2203.7437 | H16: 1158.8167 | I16: 375.506 | J16: 251.11 | K16: 1218.8349 | L16: 1640.294 | M16: 697.476 | N16: 9.5 | O16: =SUM(C16:N16) -> 0
B17: 2027 | C17: 1088.333 | D17: 2092.4001 | E17: 2910.1523 | F17: 2004.0124 | G17: 901.152 | H17: 215.305 | I17: 167.5 | J17: 51.06 | K17: 2986.8719 | L17: 2955.9469 | M17: 546.936 | N17: 3.5 | O17: =SUM(C17:N17) -> 0
B19: Planned (kbd)
B20: Year | C20: Jan | D20: Feb | E20: Mar | F20: Apr | G20: May | H20: Jun | I20: Jul | J20: Aug | K20: Sep | L20: Oct | M20: Nov | N20: Dec | O20: Total
B21: 2018 | C21: 1009.223 | D21: 2931.315 | E21: 2998.0815 | F21: 2219.0596 | G21: 1972.1564 | H21: 735.282 | I21: 780.671 | J21: 608.745 | K21: 1625.1402 | L21: 3857.713 | M21: 1616.16 | N21: 313.347 | O21: =SUM(C21:N21) -> 0
B22: 2019 | C22: 1032.795 | D22: 1639.525 | E22: 2278.0599 | F22: 2767.0536 | G22: 2038.469 | H22: 1165.339 | I22: 867.252 | J22: 1015.743 | K22: 3000.6745 | L22: 4596.3532 | M22: 2940.571 | N22: 980.3594 | O22: =SUM(C22:N22) -> 0
B23: 2020 | C23: 1606.7775 | D23: 2668.176 | E23: 2867.6665 | F23: 2237.0325 | G23: 2650.3255 | H23: 2469.553 | I23: 2067.135 | J23: 988.502 | K23: 1794.3145 | L23: 2196.246 | M23: 1840.298 | N23: 2085.71 | O23: =SUM(C23:N23) -> 0
B24: 2021 | C24: 2121.436 | D24: 2520.3674 | E24: 2787.1875 | F24: 2794.8713 | G24: 2380.9854 | H24: 1469.715 | I24: 1742.8955 | J24: 1674.8782 | K24: 2474.59 | L24: 3247.2525 | M24: 1662.6349 | N24: 863.92 | O24: =SUM(C24:N24) -> 0
B25: 2022 | C25: 1641.7355 | D25: 2387.247 | E25: 2112.384 | F25: 2341.9101 | G25: 2161.212 | H25: 1667.875 | I25: 1781.1225 | J25: 1690.934 | K25: 2179.5036 | L25: 3762.534 | M25: 1548.049 | N25: 1156.204 | O25: =SUM(C25:N25) -> 0
B26: 2023 | C26: 2552.9085 | D26: 4134.309 | E26: 3664.6845 | F26: 3647.546 | G26: 2071.2518 | H26: 368.477 | I26: 171.937 | J26: 315.56 | K26: 2423.3365 | L26: 4943.1683 | M26: 1718.509 | N26: 128.5582 | O26: =SUM(C26:N26) -> 0
B27: 2024 | C27: 2251.219 | D27: 3766.8788 | E27: 2643.9494 | F27: 2651.0149 | G27: 1541.172 | H27: 1085.2415 | I27: 512.8795 | J27: 486.4172 | K27: 1721.3308 | L27: 2469.8125 | M27: 1183.0576 | N27: 69.5225 | O27: =SUM(C27:N27) -> 0
B28: 2025 | C28: 2120.1022 | D28: 3003.7811 | E28: 2202.617 | F28: 2680.846 | G28: 900.91 | H28: 370.8306 | I28: 255.7162 | J28: 629.405 | K28: 2057.151 | L28: 3379.727 | M28: 1733.814 | N28: 81.62 | O28: =SUM(C28:N28) -> 0
B29: 2026 | C29: 1062.6823 | D29: 1946.2561 | E29: 2033.7659 | F29: 1938.51 | G29: 1001.3308 | H29: 179.03 | I29: 233.572 | J29: 204.11 | K29: 1171.8349 | L29: 1593.294 | M29: 655.176 | N29: 9.5 | O29: =SUM(C29:N29) -> 0
B30: 2027 | C30: 1088.333 | D30: 2092.4001 | E30: 2910.1523 | F30: 2004.0124 | G30: 901.152 | H30: 215.305 | I30: 167.5 | J30: 51.06 | K30: 2986.8719 | L30: 2955.9469 | M30: 546.936 | N30: 3.5 | O30: =SUM(C30:N30) -> 0
B32: Unplanned (kbd)
B33: Year | C33: Jan | D33: Feb | E33: Mar | F33: Apr | G33: May | H33: Jun | I33: Jul | J33: Aug | K33: Sep | L33: Oct | M33: Nov | N33: Dec | O33: Total
B34: 2018 | C34: 852.6345 | D34: 1453.9124 | E34: 893.0537 | F34: 981.5375 | G34: 858.2673 | H34: 626.549 | I34: 1245.1376 | J34: 1072.9289 | K34: 1216.8304 | L34: 998.991 | M34: 679.7406 | N34: 489.008 | O34: =SUM(C34:N34) -> 0
B35: 2019 | C35: 1617.9368 | D35: 2865.9575 | E35: 2350.2258 | F35: 2246.306 | G35: 1541.8013 | H35: 1242.576 | I35: 1082.7676 | J35: 636.3903 | K35: 1504.4449 | L35: 1572.9723 | M35: 1098.645 | N35: 575.3808 | O35: =SUM(C35:N35) -> 0
B36: 2020 | C36: 1232.0382 | D36: 1892.5551 | E36: 3124.2728 | F36: 13100.465 | G36: 13302.605 | H36: 13008.865 | I36: 12854.361 | J36: 13570.994 | K36: 14728.085 | L36: 13735.716 | M36: 12124.414 | N36: 12105.874 | O36: =SUM(C36:N36) -> 0
B37: 2021 | C37: 11996.413 | D37: 17022.144 | E37: 11357.684 | F37: 5399.945 | G37: 2294.947 | H37: 2256.6982 | I37: 1720.6524 | J37: 2236.4022 | K37: 5009.9912 | L37: 3932.9572 | M37: 2535.736 | N37: 1807.8542 | O37: =SUM(C37:N37) -> 0
B38: 2022 | C38: 2136.4074 | D38: 2560.138 | E38: 1897.7965 | F38: 2126.5569 | G38: 1915.8068 | H38: 1365.4118 | I38: 1338.2962 | J38: 1346.9824 | K38: 1198.2113 | L38: 1803.6182 | M38: 1657.1564 | N38: 3282.1273 | O38: =SUM(C38:N38) -> 0
B39: 2023 | C39: 3159.4181 | D39: 2679.4067 | E39: 3076.538 | F39: 2468.7029 | G39: 1748.7276 | H39: 1921.4961 | I39: 1475.1268 | J39: 1444.011 | K39: 1531.522 | L39: 1988.7435 | M39: 1350.9239 | N39: 847.5423 | O39: =SUM(C39:N39) -> 0
B40: 2024 | C40: 2433.6238 | D40: 5025.1422 | E40: 2051.1556 | F40: 1881.5364 | G40: 940.6905 | H40: 1023.714 | I40: 1472.8685 | J40: 1211.9996 | K40: 1844.9944 | L40: 1940.158 | M40: 1047.007 | N40: 709.6768 | O40: =SUM(C40:N40) -> 0
B41: 2025 | C41: 1400.9949 | D41: 2023.3805 | E41: 2228.4465 | F41: 2621.2351 | G41: 1753.1826 | H41: 1169.5851 | I41: 939.4538 | J41: 979.7175 | K41: 1487.0255 | L41: 2468.751 | M41: 1324.048 | N41: 861.733 | O41: =SUM(C41:N41) -> 0
B42: 2026 | C42: 786.9865 | D42: 1792.968 | E42: 1118.4157 | F42: 2043.992 | G42: 1202.4129 | H42: 979.7867 | I42: 141.934 | J42: 47 | K42: 47 | L42: 47 | M42: 42.3 | N42: 0 | O42: =SUM(C42:N42) -> 0

Sheet PADD Charts
B2: PADD Planned & Unplanned Offline (kbd)
B3: Columns = 2026 plan + unplanned (stacked). Lines = prior-year total offline; green = 2027 plan.
B6: PADD 1 - 2026 stack vs 2023-2025 totals & 2027 plan
B7: Series | C7: Jan | D7: Feb | E7: Mar | F7: Apr | G7: May | H7: Jun | I7: Jul | J7: Aug | K7: Sep | L7: Oct | M7: Nov | N7: Dec
B8: 2026 Planned | C8: 3.22 | D8: 12.04 | E8: 12.48 | F8: 3.78 | G8: 0 | H8: 0 | I8: 0 | J8: 0 | K8: 71.8939 | L8: 82.5856 | M8: 0 | N8: 0
B9: 2026 Unplanned | C9: 29.58 | D9: 25.1 | E9: 38.548 | F9: 2.2 | G9: 21.2 | H9: 224.3867 | I9: 0.704 | J9: 0 | K9: 0 | L9: 0 | M9: 0 | N9: 0
B10: 2025 Total | C10: 240.51 | D10: 486.744 | E10: 667.28 | F10: 363.0836 | G10: 265.68 | H10: 191.7042 | I10: 175.9952 | J10: 4.58 | K10: 7.8 | L10: 10.24 | M10: 2.04 | N10: 0
B11: 2024 Total | C11: 99.0698 | D11: 62.445 | E11: 236.6964 | F11: 214.8537 | G11: 23.4 | H11: 1.82 | I11: 75.05 | J11: 10.9 | K11: 87.2639 | L11: 154.0685 | M11: 159.3301 | N11: 197.87
B12: 2023 Total | C12: 126.05 | D12: 440 | E12: 473.92 | F12: 110.08 | G12: 46.16 | H12: 316.8375 | I12: 283.35 | J12: 2.6 | K12: 391.5052 | L12: 695.69 | M12: 256.507 | N12: 30.79
B13: 2027 Planned | C13: 0 | D13: 0 | E13: 236.8488 | F13: 108.2632 | G13: 0 | H13: 0 | I13: 0 | J13: 0 | K13: 38.7069 | L13: 5.5959 | M13: 0 | N13: 0
B28: PADD 2 - 2026 stack vs 2023-2025 totals & 2027 plan
B29: Series | C29: Jan | D29: Feb | E29: Mar | F29: Apr | G29: May | H29: Jun | I29: Jul | J29: Aug | K29: Sep | L29: Oct | M29: Nov | N29: Dec
B30: 2026 Planned | C30: 0 | D30: 152.32 | E30: 1116.623 | F30: 1226.99 | G30: 454.127 | H30: 0 | I30: 8 | J30: 0 | K30: 572.94 | L30: 705.146 | M30: 397.5 | N30: 0
B31: 2026 Unplanned | C31: 161.3505 | D31: 568.1735 | E31: 119.4167 | F31: 287.843 | G31: 375.833 | H31: 163.075 | I31: 13.715 | J31: 0 | K31: 0 | L31: 0 | M31: 0 | N31: 0
B32: 2025 Total | C32: 194.6489 | D32: 601.5409 | E32: 1263.025 | F32: 2161.4255 | G32: 919.8906 | H32: 326.2495 | I32: 260.566 | J32: 603.6235 | K32: 773.2645 | L32: 1204.6989 | M32: 328.8481 | N32: 129.87
B33: 2024 Total | C33: 82.622 | D33: 1893.1044 | E33: 1347.1691 | F33: 1456.5636 | G33: 670.5625 | H33: 364.397 | I33: 802.508 | J33: 516.3492 | K33: 1029.2768 | L33: 1512.466 | M33: 525.778 | N33: 41.1286
B34: 2023 Total | C34: 1256.5976 | D34: 1088.065 | E34: 1877.395 | F34: 2007.8074 | G34: 1042.2436 | H34: 511.95 | I34: 453.487 | J34: 182.999 | K34: 1481.1244 | L34: 1816.5088 | M34: 326.1729 | N34: 60.5386
B35: 2027 Planned | C35: 0 | D35: 192.48 | E35: 614.741 | F35: 961.07 | G35: 473.25 | H35: 0 | I35: 0 | J35: 0 | K35: 1168.516 | L35: 583.63 | M35: 1.8 | N35: 0
B50: PADD 3 - 2026 stack vs 2023-2025 totals & 2027 plan
B51: Series | C51: Jan | D51: Feb | E51: Mar | F51: Apr | G51: May | H51: Jun | I51: Jul | J51: Aug | K51: Sep | L51: Oct | M51: Nov | N51: Dec
B52: 2026 Planned | C52: 879.5774 | D52: 1498.1345 | E52: 645.745 | F52: 229.32 | G52: 221.335 | H52: 55.65 | I52: 115.992 | J52: 156.58 | K52: 416.941 | L52: 587.8024 | M52: 121.48 | N52: 0
B53: 2026 Unplanned | C53: 275.676 | D53: 807.2025 | E53: 652.611 | F53: 1045.263 | G53: 531.2235 | H53: 582.155 | I53: 122.685 | J53: 47 | K53: 47 | L53: 47 | M53: 42.3 | N53: 0
B54: 2025 Total | C54: 2513.4756 | D54: 2916.5111 | E54: 1164.668 | F54: 951.206 | G54: 451.324 | H54: 382.749 | I54: 296.0898 | J54: 608.524 | K54: 2193.196 | L54: 3093.4153 | M54: 1683.7699 | N54: 172.694
B55: 2024 Total | C55: 3897.7506 | D55: 5540.9283 | E55: 2248.1637 | F55: 2012.658 | G55: 1141.365 | H55: 1180.7915 | I55: 1019.787 | J55: 1019.9182 | K55: 1784.1745 | L55: 2036.786 | M55: 1212.9515 | N55: 324.6714
B56: 2023 Total | C56: 3219.0812 | D56: 3622.339 | E56: 3305.26 | F56: 2929.6089 | G56: 2020.7778 | H56: 1367.2069 | I56: 772.8094 | J56: 1367.907 | K56: 1980.1739 | L56: 3552.627 | M56: 1809.522 | N56: 541.6272
B57: 2027 Planned | C57: 692.313 | D57: 1256.1221 | E57: 1565.6915 | F57: 664.0222 | G57: 134.4 | H57: 210.95 | I57: 164 | J57: 47.56 | K57: 1545.905 | L57: 1819.237 | M57: 446.133 | N57: 0
B72: PADD 4 - 2026 stack vs 2023-2025 totals & 2027 plan
B73: Series | C73: Jan | D73: Feb | E73: Mar | F73: Apr | G73: May | H73: Jun | I73: Jul | J73: Aug | K73: Sep | L73: Oct | M73: Nov | N73: Dec
B74: 2026 Planned | C74: 0 | D74: 7.79 | E74: 173.293 | F74: 263.53 | G74: 52.988 | H74: 0 | I74: 0 | J74: 0 | K74: 0 | L74: 19.62 | M74: 0 | N74: 0
B75: 2026 Unplanned | C75: 0 | D75: 27.512 | E75: 20.374 | F75: 34.525 | G75: 75.6664 | H75: 10.17 | I75: 4.83 | J75: 0 | K75: 0 | L75: 0 | M75: 0 | N75: 0
B76: 2025 Total | C76: 63.1796 | D76: 36.9436 | E76: 72.1625 | F76: 127.706 | G76: 75.15 | H76: 8.223 | I76: 92.112 | J76: 4.78 | K76: 6.365 | L76: 54.195 | M76: 16.895 | N76: 14.089
B77: 2024 Total | C77: 71.7204 | D77: 226.08 | E77: 244.3878 | F77: 138.769 | G77: 31.459 | H77: 17.778 | I77: 23.131 | J77: 38.4844 | K77: 131.881 | L77: 58.955 | M77: 6.975 | N77: 44.4628
B78: 2023 Total | C78: 493.348 | D78: 408.143 | E78: 357.3731 | F78: 344.0876 | G78: 228.289 | H78: 53.3175 | I78: 40.651 | J78: 76.8 | K78: 0 | L78: 2.726 | M78: 18.951 | N78: 111.2157
B79: 2027 Planned | C79: 0 | D79: 139.68 | E79: 251.725 | F79: 257.098 | G79: 242.162 | H79: 0.855 | I79: 0 | J79: 0 | K79: 42.994 | L79: 34.444 | M79: 4.753 | N79: 0
B94: PADD 5 - 2026 stack vs 2023-2025 totals & 2027 plan
B95: Series | C95: Jan | D95: Feb | E95: Mar | F95: Apr | G95: May | H95: Jun | I95: Jul | J95: Aug | K95: Sep | L95: Oct | M95: Nov | N95: Dec
B96: 2026 Planned | C96: 179.8849 | D96: 275.9716 | E96: 85.6249 | F96: 214.89 | G96: 272.8808 | H96: 123.38 | I96: 109.58 | J96: 47.53 | K96: 110.06 | L96: 198.14 | M96: 136.196 | N96: 9.5
B97: 2026 Unplanned | C97: 320.38 | D97: 364.98 | E97: 287.466 | F97: 674.161 | G97: 198.49 | H97: 0 | I97: 0 | J97: 0 | K97: 0 | L97: 0 | M97: 0 | N97: 0
B98: 2025 Total | C98: 509.283 | D98: 985.422 | E98: 1263.928 | F98: 1698.66 | G98: 942.048 | H98: 631.49 | I98: 370.407 | J98: 387.615 | K98: 563.551 | L98: 1485.9288 | M98: 1026.309 | N98: 626.7
B99: 2024 Total | C99: 533.68 | D99: 1069.4633 | E99: 618.688 | F99: 709.707 | G99: 615.076 | H99: 544.169 | I99: 65.272 | J99: 112.765 | K99: 533.729 | L99: 647.695 | M99: 325.03 | N99: 171.0665
...

Sheet PADD Detail
B2: PADD Detail Matrices
B3: Capacity offline (kbd) by PADD x year, with Total US.
B6: Total Offline (kbd)
B7: PADD | C7: 2018 | D7: 2019 | E7: 2020 | F7: 2021 | G7: 2022 | H7: 2023 | I7: 2024 | J7: 2025 | K7: 2026 | L7: 2027
B8: PADD 1 | C8: 2893.3769 | D8: 3939.7629 | E8: 9251.7517 | F8: 3805.4693 | G8: 1555.1216 | H8: 3173.4897 | I8: 1322.7674 | J8: 2415.657 | K8: 527.7182 | L8: 389.4148
B9: PADD 2 | C9: 8081.7244 | D9: 10058.303 | E9: 29889.079 | F9: 15977.23 | G9: 10595.26 | H9: 12104.889 | I9: 10241.925 | J9: 8767.6514 | K9: 6323.0527 | L9: 3995.487
B10: PADD 3 | C10: 14797.233 | D10: 22644.488 | E10: 80030.667 | F10: 55571.706 | G10: 26369.134 | H10: 26488.94 | I10: 23419.946 | J10: 16427.623 | K10: 9128.6733 | L10: 8546.3338
B11: PADD 4 | C11: 1578.74 | D11: 573.6105 | E11: 3098.1596 | F11: 2489.7791 | G11: 1648.2037 | H11: 2134.9019 | I11: 1034.0834 | J11: 571.8007 | K11: 690.2984 | L11: 973.711
B12: PADD 5 | C12: 4684.4105 | D12: 5441.4348 | E12: 27982.325 | F12: 14331.243 | G12: 6891.4998 | H12: 5930.1835 | I12: 5946.3408 | J12: 10491.342 | K12: 3609.1152 | L12: 2018.223
B13: Total US | C13: =SUM(C8:C12) -> 0 | D13: =SUM(D8:D12) -> 0 | E13: =SUM(E8:E12) -> 0 | F13: =SUM(F8:F12) -> 0 | G13: =SUM(G8:G12) -> 0 | H13: =SUM(H8:H12) -> 0 | I13: =SUM(I8:I12) -> 0 | J13: =SUM(J8:J12) -> 0 | ... L13: =SUM(L8:L12) -> 0
B15: Unplanned (kbd)
B16: PADD | C16: 2018 | D16: 2019 | E16: 2020 | F16: 2021 | G16: 2022 | H16: 2023 | I16: 2024 | J16: 2025 | K16: 2026
B17: PADD 1 | C17: 686.5772 | D17: 1134.9774 | E17: 6639.4917 | F17: 3499.3643 | G17: 838.49 | H17: 879.2185 | I17: 758.0088 | J17: 1524.7432 | K17: 341.7187
B18: PADD 2 | C18: 2968.9009 | D18: 4280.2866 | E18: 27603.145 | F18: 11298.457 | G18: 6764.0168 | H18: 6640.3387 | I18: 5602.5239 | J18: 2837.6686 | K18: 1689.4067
B19: PADD 3 | C19: 6130.7373 | D19: 9871.7996 | E19: 66183.298 | F19: 40953.226 | G19: 11315.874 | H19: 11829.262 | I19: 11810.349 | J19: 6051.7432 | K19: 4200.116
B20: PADD 4 | C20: 397.564 | D20: 40.1365 | E20: 2735.7326 | F20: 1627.5056 | G20: 693.9537 | H20: 1470.7124 | I20: 401.7754 | J20: 381.1887 | K20: 173.0774
B21: PADD 5 | C21: 1184.8115 | D21: 3008.2042 | E21: 21618.578 | F21: 9056.1411 | G21: 3016.1748 | H21: 2872.6275 | I21: 3009.9095 | J21: 8462.2098 | K21: 1845.477
B22: Total US | C22: =SUM(C17:C21) -> 0 | D22: =SUM(D17:D21) -> 0 | E22: =SUM(E17:E21) -> 0 | F22: =SUM(F17:F21) -> 0 | G22: =SUM(G17:G21) -> 0 | H22: =SUM(H17:H21) -> 0 | I22: =SUM(I17:I21) -> 0 | J22: =SUM(J17:J21) -> 0 | K22: =SUM(K17:K21) -> 0
B24: Planned (kbd)
B25: PADD | C25: 2018 | D25: 2019 | E25: 2020 | F25: 2021 | G25: 2022 | H25: 2023 | I25: 2024 | J25: 2025 | K25: 2026 | L25: 2027
B26: PADD 1 | C26: 2206.7997 | D26: 2804.7855 | E26: 2612.26 | F26: 306.105 | G26: 716.6316 | H26: 2294.2712 | I26: 564.7586 | J26: 890.9138 | K26: 185.9995 | L26: 389.4148
B27: PADD 2 | C27: 5112.8235 | D27: 5778.016 | E27: 2285.9335 | F27: 4678.7734 | G27: 3831.2436 | H27: 5464.5506 | I27: 4639.4013 | J27: 5929.9828 | K27: 4633.646 | L27: 3995.487
B28: PADD 3 | C28: 8666.4955 | D28: 12772.689 | E28: 13847.369 | F28: 14618.48 | G28: 15053.261 | H28: 14659.678 | I28: 11609.596 | J28: 10375.879 | K28: 4928.5573 | L28: 8546.3338
B29: PADD 4 | C29: 1181.176 | D29: 533.474 | E29: 362.427 | F29: 862.2735 | G29: 954.25 | H29: 664.1895 | I29: 632.308 | J29: 190.612 | K29: 517.221 | L29: 973.711
B30: PADD 5 | C30: 3499.599 | D30: 2433.2306 | E30: 6363.747 | F30: 5275.1015 | G30: 3875.325 | H30: 3057.556 | I30: 2936.4313 | J30: 2029.132 | K30: 1763.6382 | L30: 2018.223
B31: Total US | C31: =SUM(C26:C30) -> 0 | D31: =SUM(D26:D30) -> 0 | E31: =SUM(E26:E30) -> 0 | F31: =SUM(F26:F30) -> 0 | G31: =SUM(G26:G30) -> 0 | H31: =SUM(H26:H30) -> 0 | I31: =SUM(I26:I30) -> 0 | J31: =SUM(J26:J30) -> 0 | ... L31: =SUM(L26:L30) -> 0

Sheet Units
B2: Unit-Category Detail
B3: Capacity offline (kbd) by unit category x year, sorted by total.
B6: Capacity Offline by Unit Category (kbd)
B7: Unit Category | C7: 2020 | D7: 2021 | E7: 2022 | F7: 2023 | G7: 2024 | H7: 2025 | I7: 2026 | J7: 2027 | K7: Total
B8: Atmos Distillation | C8: 46512.477 | D8: 29609.011 | E8: 15320.719 | F8: 15276.094 | G8: 12254.372 | H8: 12952.945 | I8: 6971.548 | J8: 7055.79 | K8: =SUM(C8:J8) -> 0
B9: Hydrotreating | C9: 37292.067 | D9: 20210.729 | E9: 10460.02 | F9: 11712.446 | G9: 9401.5057 | H9: 9012.3152 | I9: 4200.8856 | J9: 3139.902 | K9: =SUM(C9:J9) -> 0
B10: Fluid Cat Cracking | C10: 19361.928 | D10: 12179.629 | E10: 5724.9635 | F10: 6157.5325 | G10: 5032.6462 | H10: 4329.9434 | I10: 2623.742 | J10: 2064.5315 | K10: =SUM(C10:J10) -> 0
B11: Vacuum Distillation | C11: 16430.789 | D11: 11786.467 | E11: 5635.4065 | F11: 5961.924 | G11: 4902.8027 | H11: 4566.9633 | I11: 2609.1064 | J11: 1233.4527 | K11: =SUM(C11:J11) -> 0
B12: Reforming | C12: 10878.182 | D12: 7104.1057 | E12: 3739.9282 | F12: 4018.1045 | G12: 4223.5419 | H12: 2350.0454 | I12: 1283.642 | J12: 641.897 | K12: =SUM(C12:J12) -> 0
B13: Coking | C13: 7296.2186 | D13: 4865.5582 | E13: 2622.3905 | F13: 3278.1496 | G13: 3357.0548 | H13: 2299.9069 | I13: 1035.859 | J13: 732.121 | K13: =SUM(C13:J13) -> 0
B14: Hydrocracking | C14: 6316.6157 | D14: 3873.6708 | E14: 2035.4437 | F14: 2200.4856 | G14: 2057.798 | H14: 1959.67 | I14: 852.657 | J14: 461.533 | K14: =SUM(C14:J14) -> 0
B15: Alkylation | C15: 3199.133 | D15: 1990.6946 | E15: 895.996 | F15: 838.9985 | G15: 557.7479 | H15: 608.203 | I15: 361.0614 | J15: 392.8175 | K15: =SUM(C15:J15) -> 0
B16: Isomerization | C16: 1053.9846 | D16: 616.8486 | E16: 143.3713 | F16: 214.9927 | G16: 121.3164 | H16: 256.8642 | I16: 135.589 | J16: 120.326 | K16: =SUM(C16:J16) -> 0
B17: Other | C17: 687.6974 | D17: 386.4898 | E17: 74.939 | F17: 29.658 | G17: 32.758 | H17: 116.53 | I17: 178.0694 | J17: 42.017 | K17: =SUM(C17:J17) -> 0
B18: Resid_Hydrocracking | C18: 426.923 | D18: 175.328 | E18: 178.8 | F18: 73.33 | G18: 0 | H18: 171.2 | I18: 0 | J18: 0 | K18: =SUM(C18:J18) -> 0
B19: Asphalt | C19: 346.8787 | D19: 257.4847 | E19: 222.4997 | F19: 62.6817 | G19: 1.305 | H19: 34.017 | I19: 22.006 | J19: 31.5819 | K19: =SUM(C19:J19) -> 0
... B24: Gas Processing | C24: 0 | D24: 0 | E24: 0 | F24: 0 | G24: 0 | H24: 0 | I24: 0 | J24: 0 | K24: =SUM(C24:J24) -> 0

Sheet Refinery Detail
B2: Refinery & Operator Detail
B3: Top sites and operators by capacity offline (kbd), all years.
B6: Top 15 Refineries by Capacity Offline (kbd)
B7: Refinery | C7: PADD | D7: Operator | E7: Total | F7: Planned | G7: Unplanned | H7: Events
B8: Alliance Refinery | C8: PADD 3 | D8: Phillips 66 | E8: 33211.309 | F8: 27916.436 | G8: 5294.8736 | H8: 290
B9: Galveston Bay Refinery (GBR) | C9: PADD 3 | D9: Marathon Petroleum Corporation | E9: 23493.479 | F9: 10058.128 | G9: 13435.351 | H9: 347
B10: Lake Charles Refinery (CITGO) | C10: PADD 3 | D10: Citgo Petroleum Corporation | E10: 23153.016 | F10: 4733.22 | G10: 18419.796 | H10: 469
B11: Port Arthur Refinery (Motiva) | C11: PADD 3 | D11: Motiva Enterprises Llc | E11: 21904.044 | F11: 7435.601 | G11: 14468.443 | H11: 418
B12: Whiting Refinery | C12: PADD 2 | D12: Bp Products North America Incorporated | E12: 19129.417 | F12: 6915.0546 | G12: 12214.362 | H12: 300
B13: Port Arthur Refinery (Valero) | C13: PADD 3 | D13: Valero Refining Company | E13: 17686.618 | F13: 5065.906 | G13: 12620.712 | H13: 426
B14: Garyville Refinery | C14: PADD 3 | D14: Marathon Petroleum Corporation | E14: 16687.426 | F14: 6703.617 | G14: 9983.8094 | H14: 272
B15: Baytown Refinery | C15: PADD 3 | D15: Exxonmobil Corporation | E15: 16208.932 | F15: 5510.3108 | G15: 10698.621 | H15: 223
B16: Beaumont Refinery | C16: PADD 3 | D16: Exxonmobil Corporation | E16: 14425.321 | F16: 5948.188 | G16: 8477.1328 | H16: 344
B17: Wood River Refinery | C17: PADD 2 | D17: Phillips 66 | E17: 13588.918 | F17: 5885.3065 | G17: 7703.612 | H17: 245
B18: Baton Rouge Refinery | C18: PADD 3 | D18: Exxonmobil Corporation | E18: 13501.072 | F18: 5202.416 | G18: 8298.656 | H18: 308
B19: El Segundo Refinery | C19: PADD 5 | D19: Chevron Corporation | E19: 13331.476 | F19: 5559.812 | G19: 7771.6643 | H19: 283
... B22: Pascagoula Refinery | C22: PADD 3 | D22: Chevron Corporation | E22: 12949.105 | F22: 3578.835 | G22: 9370.2698 | H22: 174
B25: Top 10 Operators x Year (kbd)
B26: Operator | C26: 2020 | D26: 2021 | E26: 2022 | F26: 2023 | G26: 2024 | H26: 2025 | I26: 2026 | J26: 2027
B27: Phillips 66 | C27: 25306.558 | D27: 12988.022 | E27: 12493.472 | F27: 9882.4347 | G27: 2336.4516 | H27: 4027.3002 | I27: 1248.434 | J27: 2053.585
B28: Marathon Petroleum Corporation | C28: 21532.961 | D28: 12421.02 | E28: 5841.9835 | F28: 6593.8331 | G28: 5747.685 | H28: 4923.1125 | I28: 3853.8274 | J28: 1793.13
B29: Valero Refining Company | C29: 17593.755 | D29: 10006.166 | E29: 4098.6005 | F29: 2827.94 | G29: 6261.7678 | H29: 3734.0984 | I29: 3739.0864 | J29: 1682.079
B30: Exxonmobil Corporation | C30: 11989.876 | D30: 7574.6457 | E30: 2697.4988 | F30: 2558.05 | G30: 4189.969 | H30: 1119.6385 | I30: 1552.585 | J30: 2377.5475
B31: Chevron Corporation | C31: 11627.275 | D31: 6070.6939 | E31: 3667.3525 | F31: 2333.752 | G31: 5218.568 | H31: 2314.2958 | I31: 1292.358 | J31: 983.2125
B32: Citgo Petroleum Corporation | C32: 11065.116 | D32: 5354.3886 | E32: 2724.9488 | F32: 2472.6616 | G32: 1948.0044 | H32: 1645.2768 | I32: 873.65 | J32: 698.79
B33: Bp Products North America Incorporated | C33: 3368.9389 | D33: 2042.5059 | E33: 1582.1466 | F33: 1549.4876 | G33: 3661.295 | H33: 1499.9392 | I33: 777.4049 | J33: 404.451
B34: Cenovus Energy Incorporated | C34: 3352.229 | D34: 2838.179 | E34: 4369.18 | F34: 4453.986 | G34: 579.623 | H34: 519.62 | I34: 636.19 | J34: 0
B35: Shell Oil Products Us | C35: 5949.0325 | D35: 11029.687 | E35: 225.0584 | F35: 955.804 | G35: 182.7824 | H35: 477.809 | I35: 10.32 | J35: 629.95
B36: Motiva Enterprises Llc | C36: 1831.612 | D36: 1154.749 | E36: 978.0164 | F36: 689.794 | G36: 1408.758 | H36: 732.77 | I36: 14.8 | J36: 1095.84
B39: Unplanned Events: Capacity vs Monthly Intensity (2023-2025)
B40: Duration (days) | C40: Capacity (kbd)
B41: 29 | C41: 255
B42: 31 | C42: 251
B43: 24 | C43: 234.89
B44: 29 | C44: 220
B45: 22 | C45: 162.74
B46: 31 | C46: 161
B47: 29 | C47: 160
B48: 17 | C48: 155.65
B49: 30 | C49: 155
...

Sheet Scenario 2027
B2: 2027 Unplanned Scenario (Live Model)
B3: Edit the yellow inputs - the forecast, chart, PADD split and the Sensitivity sheet all recompute.
B6: Scenario Inputs
B7: Baseline window | C7: 2022-2025
B8: Production growth % | C8: 0
B9: Unplanned rate multiplier | C9: 1
B10: One-off event (kbd) | C10: 0
B11: Stress month | C11: Sep
B13: Lookup - Avg Unplanned Offline (kbd/month) by Baseline Window
B14: Window | C14: Jan | D14: Feb | E14: Mar | F14: Apr | G14: May | H14: Jun | I14: Jul | J14: Aug | K14: Sep | L14: Oct | M14: Nov | N14: Dec
B15: 2022-2025 | C15: 2282.611 | D15: 3072.0168 | E15: 2313.4842 | F15: 2274.5078 | G15: 1589.6019 | H15: 1370.0518 | I15: 1306.4363 | J15: 1245.6776 | K15: 1515.4383 | L15: 2050.3177 | M15: 1344.7838 | N15: 1425.2698
B16: 2023-2025 | C16: 2331.3456 | D16: 3242.6431 | E16: 2452.0467 | F16: 2323.8248 | G16: 1480.8669 | H16: 1371.5984 | I16: 1295.8164 | J16: 1211.9094 | K16: 1621.1806 | L16: 2132.5508 | M16: 1240.6596 | N16: 806.31737
B17: 2018-19 & 22-25 | C17: 1933.5026 | D17: 2767.9895 | E17: 2082.8693 | F17: 2054.3125 | G17: 1459.746 | H17: 1224.8887 | I17: 1258.9417 | J17: 1115.3383 | K17: 1463.8381 | L17: 1795.539 | M17: 1192.9201 | N17: 1127.578
B18: All ex-2020/21 | C18: 1643.7977 | D18: 2083.2144 | E18: 1614.5233 | F18: 1584.2278 | G18: 1154.0935 | H18: 997.74664 | I18: 999.65198 | J18: 1210.4533 | K18: 1988.7039 | L18: 1586.1721 | M18: 1044.3685 | N18: 916.2711
B20: 2027 Unplanned Forecast Cascade (live)
C21: Jan | D21: Feb | E21: Mar | F21: Apr | G21: May | H21: Jun | I21: Jul | J21: Aug | K21: Sep | L21: Oct | M21: Nov | N21: Dec
B22: Baseline (window) | C22: =INDEX($C$15:$N$18,MATCH($C$7,$B$15:$B$18,0),1) -> 0 | D22: =INDEX($C$15:$N$18,MATCH($C$7,$B$15:$B$18,0),2) -> 0 | E22: =INDEX($C$15:$N$18,MATCH($C$7,$B$15:$B$18,0),3) -> 0 | F22: =INDEX($C$15:$N$18,MATCH($C$7,$B$15:$B$18,0),4) -> 0 | G22: =INDEX($C$15:$N$18,MATCH($C$7,$B$15:$B$18,0),5) -> 0 | H22: =INDEX($C$15:$N$18,MATCH($C$7,$B$15:$B$18,0),6) -> 0 | I22: =INDEX($C$15:$N$18,MATCH($C$7,$B$15:$B$18,0),7) -> 0 | J22: =INDEX($C$15:$N$18,MATCH($C$7,$B$15:$B$18,0),8) -> 0 | K22: =INDEX($C$15:$N$18,MATCH($C$7,$B$15:$B$18,0),9) -> 0 | L22: =INDEX($C$15:$N$18,MATCH($C$7,$B$15:$B$18,0),10) -> 0 | M22: =INDEX($C$15:$N$18,MATCH($C$7,$B$15:$B$18,0),11) -> 0 | N22: =INDEX($C$15:$N$18,MATCH($C$7,$B$15:$B$18,0),12) -> 0
B23: Forecast unplanned | C23: =C22*(1+$C$8)*$C$9+IF($C$11=C21,$C$10,0) -> 0 | D23: =D22*(1+$C$8)*$C$9+IF($C$11=D21,$C$10,0) -> 0 | E23: =E22*(1+$C$8)*$C$9+IF($C$11=E21,$C$10,0) -> 0 | F23: =F22*(1+$C$8)*$C$9+IF($C$11=F21,$C$10,0) -> 0 | G23: =G22*(1+$C$8)*$C$9+IF($C$11=G21,$C$10,0) -> 0 | H23: =H22*(1+$C$8)*$C$9+IF($C$11=H21,$C$10,0) -> 0 | I23: =I22*(1+$C$8)*$C$9+IF($C$11=I21,$C$10,0) -> 0 | J23: =J22*(1+$C$8)*$C$9+IF($C$11=J21,$C$10,0) -> 0 | ... N23: =N22*(1+$C$8)*$C$9+IF($C$11=N21,$C$10,0) -> 0
B25: Scenario Outputs
B26: Baseline annual (pre-shock) | C26: =SUM(C22:N22) -> 0
B27: 2027 Unplanned forecast | C27: =SUM(C23:N23) -> 0
B28: 2027 Planned (booked) | C28: 15923.17
B29: 2027 Implied total offline | C29: =$C$27+$C$28 -> 0
B31: Forecast vs Actuals (chart data)
B32: Series | C32: Jan | D32: Feb | E32: Mar | F32: Apr | G32: May | H32: Jun | I32: Jul | J32: Aug | K32: Sep | L32: Oct | M32: Nov | N32: Dec
B33: 2027 Scenario (unplanned) | C33: =C23 -> 0 | D33: =D23 -> 0 | E33: =E23 -> 0 | F33: =F23 -> 0 | G33: =G23 -> 0 | H33: =H23 -> 0 | I33: =I23 -> 0 | J33: =J23 -> 0 | ... N33: =N23 -> 0
B34: 2027 Planned | C34: 1088.333 | D34: 2092.4001 | E34: 2910.1523 | F34: 2004.0124 | G34: 901.152 | H34: 215.305 | I34: 167.5 | J34: 51.06 | K34: 2986.8719 | L34: 2955.9469 | M34: 546.936 | N34: 3.5
B35: 2025 Unplanned (actual) | C35: 1400.9949 | D35: 2023.3805 | E35: 2228.4465 | F35: 2621.2351 | G35: 1753.1826 | H35: 1169.5851 | I35: 939.4538 | J35: 979.7175 | K35: 1487.0255 | L35: 2468.751 | M35: 1324.048 | N35: 861.733
B36: 2024 Unplanned (actual) | C36: 2433.6238 | D36: 5025.1422 | E36: 2051.1556 | F36: 1881.5364 | G36: 940.6905 | H36: 1023.714 | I36: 1472.8685 | J36: 1211.9996 | K36: 1844.9944 | L36: 1940.158 | M36: 1047.007 | N36: 709.6768
B55: 2027 Scenario - PADD Allocation (by historical unplanned share)
B56: PADD | C56: Share | D56: Scenario kbd
B57: PADD 1 | C57: 0.04589748 | D57: =$C$27*C57 -> 0
B58: PADD 2 | C58: 0.25062357 | D58: =$C$27*C58 -> 0
B59: PADD 3 | C59: 0.47047794 | D59: =$C$27*C59 -> 0
B60: PADD 4 | C60: 0.033818306 | D60: =$C$27*C60 -> 0
B61: PADD 5 | C61: 0.1991827 | D61: =$C$27*C61 -> 0

Sheet Sensitivity
B2: Sensitivity & Risk
B3: Two-way heatmap recomputes from the Scenario baseline window. Tornado ranks the drivers.
B6: 2027 Unplanned (kbd): Growth (rows) x Multiplier (cols)
B7: Growth \ Mult | C7: 0.7 | D7: 0.85 | E7: 1 | F7: 1.15 | G7: 1.3 | H7: 1.5
B8: -0.1 | C8: ='Scenario 2027'!$C$26*(1+$B8)*C$7 -> 0 | D8: ='Scenario 2027'!$C$26*(1+$B8)*D$7 -> 0 | E8: ='Scenario 2027'!$C$26*(1+$B8)*E$7 -> 0 | F8: ='Scenario 2027'!$C$26*(1+$B8)*F$7 -> 0 | G8: ='Scenario 2027'!$C$26*(1+$B8)*G$7 -> 0 | H8: ='Scenario 2027'!$C$26*(1+$B8)*H$7 -> 0
B9: -0.05 | C9: ='Scenario 2027'!$C$26*(1+$B9)*C$7 -> 0 | D9: ='Scenario 2027'!$C$26*(1+$B9)*D$7 -> 0 | E9: ='Scenario 2027'!$C$26*(1+$B9)*E$7 -> 0 | F9: ='Scenario 2027'!$C$26*(1+$B9)*F$7 -> 0 | G9: ='Scenario 2027'!$C$26*(1+$B9)*G$7 -> 0 | H9: ='Scenario 2027'!$C$26*(1+$B9)*H$7 -> 0
B10: 0 | C10: ='Scenario 2027'!$C$26*(1+$B10)*C$7 -> 0 | D10: ='Scenario 2027'!$C$26*(1+$B10)*D$7 -> 0 | E10: ='Scenario 2027'!$C$26*(1+$B10)*E$7 -> 0 | F10: ='Scenario 2027'!$C$26*(1+$B10)*F$7 -> 0 | G10: ='Scenario 2027'!$C$26*(1+$B10)*G$7 -> 0 | H10: ='Scenario 2027'!$C$26*(1+$B10)*H$7 -> 0
B11: 0.05 | C11: ='Scenario 2027'!$C$26*(1+$B11)*C$7 -> 0 | D11: ='Scenario 2027'!$C$26*(1+$B11)*D$7 -> 0 | E11: ='Scenario 2027'!$C$26*(1+$B11)*E$7 -> 0 | F11: ='Scenario 2027'!$C$26*(1+$B11)*F$7 -> 0 | G11: ='Scenario 2027'!$C$26*(1+$B11)*G$7 -> 0 | H11: ='Scenario 2027'!$C$26*(1+$B11)*H$7 -> 0
B12: 0.1 | C12: ='Scenario 2027'!$C$26*(1+$B12)*C$7 -> 0 | D12: ='Scenario 2027'!$C$26*(1+$B12)*D$7 -> 0 | E12: ='Scenario 2027'!$C$26*(1+$B12)*E$7 -> 0 | F12: ='Scenario 2027'!$C$26*(1+$B12)*F$7 -> 0 | G12: ='Scenario 2027'!$C$26*(1+$B12)*G$7 -> 0 | H12: ='Scenario 2027'!$C$26*(1+$B12)*H$7 -> 0
B13: 0.15 | C13: ='Scenario 2027'!$C$26*(1+$B13)*C$7 -> 0 | D13: ='Scenario 2027'!$C$26*(1+$B13)*D$7 -> 0 | E13: ='Scenario 2027'!$C$26*(1+$B13)*E$7 -> 0 | F13: ='Scenario 2027'!$C$26*(1+$B13)*F$7 -> 0 | G13: ='Scenario 2027'!$C$26*(1+$B13)*G$7 -> 0 | H13: ='Scenario 2027'!$C$26*(1+$B13)*H$7 -> 0
B14: Base case (0% / 1.0x) outlined; colors scale green→red across the grid.
B17: Tornado - 2027 Unplanned Sensitivity by Driver (kbd)
B18: Driver | C18: Low | D18: Base | E18: High | F18: Δ Low | G18: Δ High
B19: Unplanned rate multiplier (0.7x / 1.3x) | C19: 15253.138 | D19: 21790.197 | E19: 28327.256 | F19: =C19-D19 -> 0 | G19: =E19-D19 -> 0
B20: Baseline window swing (+/-15%) | C20: 18521.668 | D20: 21790.197 | E20: 25058.727 | F20: =C20-D20 -> 0 | G20: =E20-D20 -> 0
B21: Production growth (-10% / +10%) | C21: 19611.177 | D21: 21790.197 | E21: 23969.217 | F21: =C21-D21 -> 0 | G21: =E21-D21 -> 0
B22: One-off event (+300 kbd) | C22: 21790.197 | D22: 21790.197 | E22: 22090.197 | F22: =C22-D22 -> 0 | G22: =E22-D22 -> 0

Sheet Mogas Overlay
B2: Mogas-Equivalent Overlay (Secondary)
B3: Gasoline-equivalent = capacity x unit yield factor. Secondary view; capacity is never discarded.
B6: Yield Map: Unit Bucket → Mogas Factor
B7: Bucket | C7: Factor | D7: Unit categories
B8: CDU | C8: 0.175 | D8: Atmos Distillation, Vacuum Distillation
B9: FCC | C9: 0.65 | D9: Fluid Cat Cracking
B10: Ref | C10: 0.85 | D10: Reforming
B11: HDC | C11: 0.05 | D11: Hydrocracking, Resid_Hydrocracking
B12: Coker | C12: 0.2 | D12: Coking, Therm Cracking, Visbreaking, Therm Cracking/Visbreaking
B13: Other | C13: 0 | D13: Alkylation, Aromatics, Asphalt, Btx, Gas Processing, Hydrotreating, Isomerization, Mtbe, Other
B16: Mogas-Equivalent Offline by Year (kbd)
B17: Year | C17: Planned | D17: Unplanned | E17: Total
B18: 2016 | C18: 4238.8768 | D18: 2843.4442 | E18: =C18+D18 -> 0
B19: 2017 | C19: 4222.0921 | D19: 4400.7562 | E19: =C19+D19 -> 0
B20: 2018 | C20: 4733.9224 | D20: 2804.2228 | E20: =C20+D20 -> 0
B21: 2019 | C21: 5354.9321 | D21: 4765.7607 | E21: =C21+D21 -> 0
B22: 2020 | C22: 6404.1065 | D22: 28239.093 | E22: =C22+D22 -> 0
B23: 2021 | C23: 6499.1063 | D23: 15875.913 | E23: =C23+D23 -> 0
B24: 2022 | C24: 5682.3477 | D24: 5520.3298 | E24: =C24+D24 -> 0
B25: 2023 | C25: 5999.8846 | D25: 5903.8741 | E25: =C25+D25 -> 0
B26: 2024 | C26: 4916.3718 | D26: 5721.6652 | E26: =C26+D26 -> 0
B27: 2025 | C27: 4228.2804 | D27: 4216.2303 | E27: =C27+D27 -> 0
B28: 2026 | C28: 2585.9665 | D28: 2136.9807 | E28: =C28+D28 -> 0
B29: 2027 | C29: 3507.6762 | D29: 0 | E29: =C29+D29 -> 0

Sheet Notes
B2: Data Notes & Methodology
B5: Source | C5: Snowflake export, sheet Query1. 46,456 rows, 2010-2038.
B6: Primary metric | C6: CAP_OFFLINE_ADJUSTED_KBD - offline capacity, thousand bbl/day, all units.
B7: Event count | C7: 19,934 distinct OUTAGE_IDs; rows are unit-month slices.
B8: Outage type | C8: Binary {PLANNED, UNPLANNED}; UNKNOWN folded into UNPLANNED (desk rule).
B9: PADD | C9: Parsed from PAD_DIST Roman numerals (100% resolved); STATE map is fallback.
B10: Partial years | C10: 2026 & 2027 are incomplete/special - grey italic, never final.
B11: 2027 guardrail | C11: 2027 is planned-only; unplanned-2027 is a scenario. Non-planned comparisons vs 2027 show n/a.
B12: Duration caveat | C12: TOTAL_OUTAGE_DAYS is monthly-allocated intensity (caps ~31), not full event length.
B13: Outliers | C13: 2020-2021 (COVID / Winter Storm Uri) excluded from forecast baselines by default.
B14: Scenario method | C14: Baseline(window) x (1+growth) x multiplier + one-off(stress month). All cells are live formulas off the yellow inputs.
B15: Sensitivity method | C15: Heatmap = anchor x (1+growth) x multiplier across a grid (recalcs from the scenario window). Tornado ranks driver swings.
B16: Mogas method | C16: Mogas-eq = capacity x bucket yield (CDU .175, FCC .65, Ref .85, HDC .05, Coker .20, else 0). Additive overlay; capacity never discarded.
B17: Refresh | C17: Set INPUT_PATH (or pass a path arg) and re-run build_workbook.py. Idempotent.
B19: Color Key (financial-model convention)
B20: Blue font | C20: Hard-coded input the user changes
B21: Black font | C21: Formula / calculation
B22: Green font | C22: Cross-sheet link
B23: Yellow fill | C23: Key assumption cell
