Workbook
Name conn_p1: Scenarios!$B$29
Name conn_p2: Scenarios!$B$30
Name conn_p3: Scenarios!$B$31
Name conn_p4: Scenarios!$B$32
Name conn_p5: Scenarios!$B$33
Name mult_act: Forecast!$B$27
Name mult_avg: Forecast!$B$26
Name mult_cons: Forecast!$B$25
Name naph_yield: HVN!$D$23
Name ref_intake: HVN!$D$24

Sheet What's Changed
A1: What's Changed: rolling MoM & WoW (as of Jun 29, 2026)
A2: Month-over-month is live off Data -- the balance that prices. Week-over-week compares your weekly pulls (source is monthly, so the rolling log grows one row per build).
A4: Month-over-month (live off Data -- this is the balance that prices)
A5: As-of month (edit year / month) | B5: 2026 | C5: 6
A6: Prior month | B6: =IF(C5=1,B5-1,B5) -> 2026 | C6: =IF(C5=1,12,C5-1) -> 5
A8: Metric | B8: This month | C8: Prior month | D8: Δ | E8: Δ%
A9: Total offline | B9: =SUMIFS(Data!$K:$K,Data!$A:$A,$B$5,Data!$B:$B,$C$5) -> 1349.6757 | C9: =SUMIFS(Data!$K:$K,Data!$A:$A,$B$6,Data!$B:$B,$C$6) -> 2203.7437 | D9: =B9-C9 -> -854.068 | E9: =IFERROR(D9/C9,"") -> -0.38755323
A10: Planned | B10: =SUMIFS(Data!$K:$K,Data!$A:$A,$B$5,Data!$B:$B,$C$5,Data!$J:$J,"PLANNED") -> 182.45 | C10: =SUMIFS(Data!$K:$K,Data!$A:$A,$B$6,Data!$B:$B,$C$6,Data!$J:$J,"PLANNED") -> 1001.3308 | D10: =B10-C10 -> -818.8808 | E10: =IFERROR(D10/C10,"") -> -0.81779248
A11: Unplanned | B11: =SUMIFS(Data!$K:$K,Data!$A:$A,$B$5,Data!$B:$B,$C$5,Data!$J:$J,"UNPLANNED") -> 1167.2257 | C11: =SUMIFS(Data!$K:$K,Data!$A:$A,$B$6,Data!$B:$B,$C$6,Data!$J:$J,"UNPLANNED") -> 1202.4129 | D11: =B11-C11 -> -35.1872 | E11: =IFERROR(D11/C11,"") -> -0.029263824
A12: CDU | B12: =SUMIFS(Data!$K:$K,Data!$A:$A,$B$5,Data!$B:$B,$C$5,Data!$G:$G,"CDU") -> 435.03 | C12: =SUMIFS(Data!$K:$K,Data!$A:$A,$B$6,Data!$B:$B,$C$6,Data!$G:$G,"CDU") -> 841.202 | D12: =B12-C12 -> -406.172 | E12: =IFERROR(D12/C12,"") -> -0.48284716
A13: FCC | B13: =SUMIFS(Data!$K:$K,Data!$A:$A,$B$5,Data!$B:$B,$C$5,Data!$G:$G,"FCC") -> 147.405 | C13: =SUMIFS(Data!$K:$K,Data!$A:$A,$B$6,Data!$B:$B,$C$6,Data!$G:$G,"FCC") -> 360.0815 | D13: =B13-C13 -> -212.6765 | E13: =IFERROR(D13/C13,"") -> -0.59063434
A14: Hydrocracker | B14: =SUMIFS(Data!$K:$K,Data!$A:$A,$B$5,Data!$B:$B,$C$5,Data!$G:$G,"Hydrocracker") -> 21.38 | C14: =SUMIFS(Data!$K:$K,Data!$A:$A,$B$6,Data!$B:$B,$C$6,Data!$G:$G,"Hydrocracker") -> 92.77 | D14: =B14-C14 -> -71.39 | E14: =IFERROR(D14/C14,"") -> -0.76953757
A15: Reformer | B15: =SUMIFS(Data!$K:$K,Data!$A:$A,$B$5,Data!$B:$B,$C$5,Data!$G:$G,"Reformer") -> 130.51 | C15: =SUMIFS(Data!$K:$K,Data!$A:$A,$B$6,Data!$B:$B,$C$6,Data!$G:$G,"Reformer") -> 157.769 | D15: =B15-C15 -> -27.259 | E15: =IFERROR(D15/C15,"") -> -0.17277792
A17: Rolling: trailing 6 months (live)
A18: Month | B18: Total | C18: Planned | D18: Unplanned
A19: Jan 2026 | B19: =SUMIFS(Data!$K:$K,Data!$A:$A,2026,Data!$B:$B,1) -> 1849.6688 | C19: =SUMIFS(Data!$K:$K,Data!$A:$A,2026,Data!$B:$B,1,Data!$J:$J,"PLANNED") -> 1062.6823 | D19: =SUMIFS(Data!$K:$K,Data!$A:$A,2026,Data!$B:$B,1,Data!$J:$J,"UNPLANNED") -> 786.9865
A20: Feb 2026 | B20: =SUMIFS(Data!$K:$K,Data!$A:$A,2026,Data!$B:$B,2) -> 3739.2241 | C20: =SUMIFS(Data!$K:$K,Data!$A:$A,2026,Data!$B:$B,2,Data!$J:$J,"PLANNED") -> 1946.2561 | D20: =SUMIFS(Data!$K:$K,Data!$A:$A,2026,Data!$B:$B,2,Data!$J:$J,"UNPLANNED") -> 1792.968
A21: Mar 2026 | B21: =SUMIFS(Data!$K:$K,Data!$A:$A,2026,Data!$B:$B,3) -> 3152.1816 | C21: =SUMIFS(Data!$K:$K,Data!$A:$A,2026,Data!$B:$B,3,Data!$J:$J,"PLANNED") -> 2033.7659 | D21: =SUMIFS(Data!$K:$K,Data!$A:$A,2026,Data!$B:$B,3,Data!$J:$J,"UNPLANNED") -> 1118.4157
A22: Apr 2026 | B22: =SUMIFS(Data!$K:$K,Data!$A:$A,2026,Data!$B:$B,4) -> 3982.502 | C22: =SUMIFS(Data!$K:$K,Data!$A:$A,2026,Data!$B:$B,4,Data!$J:$J,"PLANNED") -> 1938.51 | D22: =SUMIFS(Data!$K:$K,Data!$A:$A,2026,Data!$B:$B,4,Data!$J:$J,"UNPLANNED") -> 2043.992
A23: May 2026 | B23: =SUMIFS(Data!$K:$K,Data!$A:$A,2026,Data!$B:$B,5) -> 2203.7437 | C23: =SUMIFS(Data!$K:$K,Data!$A:$A,2026,Data!$B:$B,5,Data!$J:$J,"PLANNED") -> 1001.3308 | D23: =SUMIFS(Data!$K:$K,Data!$A:$A,2026,Data!$B:$B,5,Data!$J:$J,"UNPLANNED") -> 1202.4129
A24: Jun 2026 | B24: =SUMIFS(Data!$K:$K,Data!$A:$A,2026,Data!$B:$B,6) -> 1349.6757 | C24: =SUMIFS(Data!$K:$K,Data!$A:$A,2026,Data!$B:$B,6,Data!$J:$J,"PLANNED") -> 182.45 | D24: =SUMIFS(Data!$K:$K,Data!$A:$A,2026,Data!$B:$B,6,Data!$J:$J,"UNPLANNED") -> 1167.2257
A26: Week-over-week: your weekly pulls (rolling; one row per build)
A27: Pull date | B27: Jun 2026 | C27: Δ vs prior pull | D27: 2026-07 next mo
A28: 2026-06-27 | B28: 1349.7 | D28: 1075
A29: 2026-06-29 | B29: 1349.7 | C29: 0 | D29: 1075
A30: Each build appends today's snapshot (current + next 6 months' offline) to data/whatschanged_log.csv. Run it weekly after refreshing the Snowflake and the Δ shows what the vendor added/pulled since last week. Δ on the current month is the contract-relevant move.
A32: New this month (Jun 2026) -- not down the prior month
A33: Plant | B33: Unit | C33: PADD | D33: kbd
A34: Corpus Christi Refinery | B34: ATMOS DISTILLATION | C34: PADD 3 | D34: 104
A35: Trainer Refinery | B35: ATMOS DISTILLATION | C35: PADD 1 | D35: 52
A36: Texas City Refinery | B36: HYDROTREATING | C36: PADD 3 | D36: 51.7
A37: Trainer Refinery | B37: ATMOS DISTILLATION | C37: PADD 1 | D37: 48.9
A38: Par East Refinery | B38: ATMOS DISTILLATION | C38: PADD 5 | D38: 45
A39: Port Arthur Refinery (To | B39: ATMOS DISTILLATION | C39: PADD 3 | D39: 40.5
A41: Back online this month -- down the prior month, not now
A42: Plant | B42: Unit | C42: PADD | D42: kbd
A43: Robinson Refinery | B43: ATMOS DISTILLATION | C43: PADD 2 | D43: 180.7
A44: Baytown Refinery | B44: ATMOS DISTILLATION | C44: PADD 3 | D44: 113.4
A45: El Segundo Refinery | B45: HYDROTREATING | C45: PADD 5 | D45: 58.8
A46: Kenai Refinery | B46: ATMOS DISTILLATION | C46: PADD 5 | D46: 53.3
...

Sheet Per-Unit
A1: Per-Unit Concurrent Capacity Offline (kbd, day-weighted) = SUMIFS over Data
A2: Each focus unit on its own, by month and year. Never summed across units.
A4: Crude (CDU)
A5: Year | B5: Jan | C5: Feb | D5: Mar | E5: Apr | F5: May | G5: Jun | H5: Jul | I5: Aug | J5: Sep | K5: Oct | L5: Nov | M5: Dec
A6: 2023 | B6: =SUMIFS(Data!$K:$K,Data!$A:$A,2023,Data!$B:$B,1,Data!$G:$G,"CDU") -> 1739.545 | C6: =SUMIFS(Data!$K:$K,Data!$A:$A,2023,Data!$B:$B,2,Data!$G:$G,"CDU") -> 2180.255 | D6: =SUMIFS(Data!$K:$K,Data!$A:$A,2023,Data!$B:$B,3,Data!$G:$G,"CDU") -> 2060.202 | E6: =SUMIFS(Data!$K:$K,Data!$A:$A,2023,Data!$B:$B,4,Data!$G:$G,"CDU") -> 1806.215 | F6: =SUMIFS(Data!$K:$K,Data!$A:$A,2023,Data!$B:$B,5,Data!$G:$G,"CDU") -> 1061.1038 | G6: =SUMIFS(Data!$K:$K,Data!$A:$A,2023,Data!$B:$B,6,Data!$G:$G,"CDU") -> 794.9545 | H6: =SUMIFS(Data!$K:$K,Data!$A:$A,2023,Data!$B:$B,7,Data!$G:$G,"CDU") -> 510.65 | I6: =SUMIFS(Data!$K:$K,Data!$A:$A,2023,Data!$B:$B,8,Data!$G:$G,"CDU") -> 510.13 | J6: =SUMIFS(Data!$K:$K,Data!$A:$A,2023,Data!$B:$B,9,Data!$G:$G,"CDU") -> 1099.23 | K6: =SUMIFS(Data!$K:$K,Data!$A:$A,2023,Data!$B:$B,10,Data!$G:$G,"CDU") -> 2033.6085 | L6: =SUMIFS(Data!$K:$K,Data!$A:$A,2023,Data!$B:$B,11,Data!$G:$G,"CDU") -> 881.06 | M6: =SUMIFS(Data!$K:$K,Data!$A:$A,2023,Data!$B:$B,12,Data!$G:$G,"CDU") -> 256.08
A7: 2024 | B7: =SUMIFS(Data!$K:$K,Data!$A:$A,2024,Data!$B:$B,1,Data!$G:$G,"CDU") -> 1313.892 | C7: =SUMIFS(Data!$K:$K,Data!$A:$A,2024,Data!$B:$B,2,Data!$G:$G,"CDU") -> 2142.5348 | D7: =SUMIFS(Data!$K:$K,Data!$A:$A,2024,Data!$B:$B,3,Data!$G:$G,"CDU") -> 1268.1126 | E7: =SUMIFS(Data!$K:$K,Data!$A:$A,2024,Data!$B:$B,4,Data!$G:$G,"CDU") -> 1440.7505 | F7: =SUMIFS(Data!$K:$K,Data!$A:$A,2024,Data!$B:$B,5,Data!$G:$G,"CDU") -> 501.391 | G7: =SUMIFS(Data!$K:$K,Data!$A:$A,2024,Data!$B:$B,6,Data!$G:$G,"CDU") -> 455.03 | H7: =SUMIFS(Data!$K:$K,Data!$A:$A,2024,Data!$B:$B,7,Data!$G:$G,"CDU") -> 646.83 | I7: =SUMIFS(Data!$K:$K,Data!$A:$A,2024,Data!$B:$B,8,Data!$G:$G,"CDU") -> 550.098 | J7: =SUMIFS(Data!$K:$K,Data!$A:$A,2024,Data!$B:$B,9,Data!$G:$G,"CDU") -> 1090.8784 | K7: =SUMIFS(Data!$K:$K,Data!$A:$A,2024,Data!$B:$B,10,Data!$G:$G,"CDU") -> 1122.32 | L7: =SUMIFS(Data!$K:$K,Data!$A:$A,2024,Data!$B:$B,11,Data!$G:$G,"CDU") -> 715.6 | M7: =SUMIFS(Data!$K:$K,Data!$A:$A,2024,Data!$B:$B,12,Data!$G:$G,"CDU") -> 288.8526
A8: 2025 | B8: =SUMIFS(Data!$K:$K,Data!$A:$A,2025,Data!$B:$B,1,Data!$G:$G,"CDU") -> 1256.145 | C8: =SUMIFS(Data!$K:$K,Data!$A:$A,2025,Data!$B:$B,2,Data!$G:$G,"CDU") -> 1649.407 | D8: =SUMIFS(Data!$K:$K,Data!$A:$A,2025,Data!$B:$B,3,Data!$G:$G,"CDU") -> 1632.123 | E8: =SUMIFS(Data!$K:$K,Data!$A:$A,2025,Data!$B:$B,4,Data!$G:$G,"CDU") -> 1850.1686 | F8: =SUMIFS(Data!$K:$K,Data!$A:$A,2025,Data!$B:$B,5,Data!$G:$G,"CDU") -> 956.3466 | G8: =SUMIFS(Data!$K:$K,Data!$A:$A,2025,Data!$B:$B,6,Data!$G:$G,"CDU") -> 488.1771 | H8: =SUMIFS(Data!$K:$K,Data!$A:$A,2025,Data!$B:$B,7,Data!$G:$G,"CDU") -> 349.903 | I8: =SUMIFS(Data!$K:$K,Data!$A:$A,2025,Data!$B:$B,8,Data!$G:$G,"CDU") -> 393.8658 | J8: =SUMIFS(Data!$K:$K,Data!$A:$A,2025,Data!$B:$B,9,Data!$G:$G,"CDU") -> 1152.71 | K8: =SUMIFS(Data!$K:$K,Data!$A:$A,2025,Data!$B:$B,10,Data!$G:$G,"CDU") -> 1864.885 | L8: =SUMIFS(Data!$K:$K,Data!$A:$A,2025,Data!$B:$B,11,Data!$G:$G,"CDU") -> 989.6356 | M8: =SUMIFS(Data!$K:$K,Data!$A:$A,2025,Data!$B:$B,12,Data!$G:$G,"CDU") -> 313.306
A9: 2026 | B9: =SUMIFS(Data!$K:$K,Data!$A:$A,2026,Data!$B:$B,1,Data!$G:$G,"CDU") -> 531.3 | C9: =SUMIFS(Data!$K:$K,Data!$A:$A,2026,Data!$B:$B,2,Data!$G:$G,"CDU") -> 1246.845 | D9: =SUMIFS(Data!$K:$K,Data!$A:$A,2026,Data!$B:$B,3,Data!$G:$G,"CDU") -> 968.521 | E9: =SUMIFS(Data!$K:$K,Data!$A:$A,2026,Data!$B:$B,4,Data!$G:$G,"CDU") -> 1411.605 | F9: =SUMIFS(Data!$K:$K,Data!$A:$A,2026,Data!$B:$B,5,Data!$G:$G,"CDU") -> 841.202 | G9: =SUMIFS(Data!$K:$K,Data!$A:$A,2026,Data!$B:$B,6,Data!$G:$G,"CDU") -> 435.03 | H9: =SUMIFS(Data!$K:$K,Data!$A:$A,2026,Data!$B:$B,7,Data!$G:$G,"CDU") -> 378.602 | I9: =SUMIFS(Data!$K:$K,Data!$A:$A,2026,Data!$B:$B,8,Data!$G:$G,"CDU") -> 126 | J9: =SUMIFS(Data!$K:$K,Data!$A:$A,2026,Data!$B:$B,9,Data!$G:$G,"CDU") -> 448.14 | K9: =SUMIFS(Data!$K:$K,Data!$A:$A,2026,Data!$B:$B,10,Data!$G:$G,"CDU") -> 661.633 | L9: =SUMIFS(Data!$K:$K,Data!$A:$A,2026,Data!$B:$B,11,Data!$G:$G,"CDU") -> 214.3 | M9: =SUMIFS(Data!$K:$K,Data!$A:$A,2026,Data!$B:$B,12,Data!$G:$G,"CDU") -> 0
A10: 2027 | B10: =SUMIFS(Data!$K:$K,Data!$A:$A,2027,Data!$B:$B,1,Data!$G:$G,"CDU") -> 365.125 | C10: =SUMIFS(Data!$K:$K,Data!$A:$A,2027,Data!$B:$B,2,Data!$G:$G,"CDU") -> 683.258 | D10: =SUMIFS(Data!$K:$K,Data!$A:$A,2027,Data!$B:$B,3,Data!$G:$G,"CDU") -> 1062.14 | E10: =SUMIFS(Data!$K:$K,Data!$A:$A,2027,Data!$B:$B,4,Data!$G:$G,"CDU") -> 663.255 | F10: =SUMIFS(Data!$K:$K,Data!$A:$A,2027,Data!$B:$B,5,Data!$G:$G,"CDU") -> 320.192 | G10: =SUMIFS(Data!$K:$K,Data!$A:$A,2027,Data!$B:$B,6,Data!$G:$G,"CDU") -> 96 | H10: =SUMIFS(Data!$K:$K,Data!$A:$A,2027,Data!$B:$B,7,Data!$G:$G,"CDU") -> 96 | I10: =SUMIFS(Data!$K:$K,Data!$A:$A,2027,Data!$B:$B,8,Data!$G:$G,"CDU") -> 27.84 | J10: =SUMIFS(Data!$K:$K,Data!$A:$A,2027,Data!$B:$B,9,Data!$G:$G,"CDU") -> 976.735 | K10: =SUMIFS(Data!$K:$K,Data!$A:$A,2027,Data!$B:$B,10,Data!$G:$G,"CDU") -> 1307.315 | L10: =SUMIFS(Data!$K:$K,Data!$A:$A,2027,Data!$B:$B,11,Data!$G:$G,"CDU") -> 283.9 | M10: =SUMIFS(Data!$K:$K,Data!$A:$A,2027,Data!$B:$B,12,Data!$G:$G,"CDU") -> 0
A13: FCC (cat cracker)
A14: Year | B14: Jan | C14: Feb | D14: Mar | E14: Apr | F14: May | G14: Jun | H14: Jul | I14: Aug | J14: Sep | K14: Oct | L14: Nov | M14: Dec
A15: 2023 | B15: =SUMIFS(Data!$K:$K,Data!$A:$A,2023,Data!$B:$B,1,Data!$G:$G,"FCC") -> 810.943 | C15: =SUMIFS(Data!$K:$K,Data!$A:$A,2023,Data!$B:$B,2,Data!$G:$G,"FCC") -> 1025.05 | D15: =SUMIFS(Data!$K:$K,Data!$A:$A,2023,Data!$B:$B,3,Data!$G:$G,"FCC") -> 880.265 | E15: =SUMIFS(Data!$K:$K,Data!$A:$A,2023,Data!$B:$B,4,Data!$G:$G,"FCC") -> 615.626 | F15: =SUMIFS(Data!$K:$K,Data!$A:$A,2023,Data!$B:$B,5,Data!$G:$G,"FCC") -> 530.395 | G15: =SUMIFS(Data!$K:$K,Data!$A:$A,2023,Data!$B:$B,6,Data!$G:$G,"FCC") -> 406.9475 | H15: =SUMIFS(Data!$K:$K,Data!$A:$A,2023,Data!$B:$B,7,Data!$G:$G,"FCC") -> 232.66 | I15: =SUMIFS(Data!$K:$K,Data!$A:$A,2023,Data!$B:$B,8,Data!$G:$G,"FCC") -> 161.055 | J15: =SUMIFS(Data!$K:$K,Data!$A:$A,2023,Data!$B:$B,9,Data!$G:$G,"FCC") -> 407.94 | K15: =SUMIFS(Data!$K:$K,Data!$A:$A,2023,Data!$B:$B,10,Data!$G:$G,"FCC") -> 590.53 | L15: =SUMIFS(Data!$K:$K,Data!$A:$A,2023,Data!$B:$B,11,Data!$G:$G,"FCC") -> 347.605 | M15: =SUMIFS(Data!$K:$K,Data!$A:$A,2023,Data!$B:$B,12,Data!$G:$G,"FCC") -> 152.404
A16: 2024 | B16: =SUMIFS(Data!$K:$K,Data!$A:$A,2024,Data!$B:$B,1,Data!$G:$G,"FCC") -> 313.199 | C16: =SUMIFS(Data!$K:$K,Data!$A:$A,2024,Data!$B:$B,2,Data!$G:$G,"FCC") -> 1054.9718 | D16: =SUMIFS(Data!$K:$K,Data!$A:$A,2024,Data!$B:$B,3,Data!$G:$G,"FCC") -> 579.138 | E16: =SUMIFS(Data!$K:$K,Data!$A:$A,2024,Data!$B:$B,4,Data!$G:$G,"FCC") -> 489.937 | F16: =SUMIFS(Data!$K:$K,Data!$A:$A,2024,Data!$B:$B,5,Data!$G:$G,"FCC") -> 277.135 | G16: =SUMIFS(Data!$K:$K,Data!$A:$A,2024,Data!$B:$B,6,Data!$G:$G,"FCC") -> 334.165 | H16: =SUMIFS(Data!$K:$K,Data!$A:$A,2024,Data!$B:$B,7,Data!$G:$G,"FCC") -> 356.206 | I16: =SUMIFS(Data!$K:$K,Data!$A:$A,2024,Data!$B:$B,8,Data!$G:$G,"FCC") -> 309.4394 | J16: =SUMIFS(Data!$K:$K,Data!$A:$A,2024,Data!$B:$B,9,Data!$G:$G,"FCC") -> 652.189 | K16: =SUMIFS(Data!$K:$K,Data!$A:$A,2024,Data!$B:$B,10,Data!$G:$G,"FCC") -> 453.501 | L16: =SUMIFS(Data!$K:$K,Data!$A:$A,2024,Data!$B:$B,11,Data!$G:$G,"FCC") -> 153.011 | M16: =SUMIFS(Data!$K:$K,Data!$A:$A,2024,Data!$B:$B,12,Data!$G:$G,"FCC") -> 59.754
A17: 2025 | B17: =SUMIFS(Data!$K:$K,Data!$A:$A,2025,Data!$B:$B,1,Data!$G:$G,"FCC") -> 297.316 | C17: =SUMIFS(Data!$K:$K,Data!$A:$A,2025,Data!$B:$B,2,Data!$G:$G,"FCC") -> 403.831 | D17: =SUMIFS(Data!$K:$K,Data!$A:$A,2025,Data!$B:$B,3,Data!$G:$G,"FCC") -> 472.933 | E17: =SUMIFS(Data!$K:$K,Data!$A:$A,2025,Data!$B:$B,4,Data!$G:$G,"FCC") -> 576.225 | F17: =SUMIFS(Data!$K:$K,Data!$A:$A,2025,Data!$B:$B,5,Data!$G:$G,"FCC") -> 393.455 | G17: =SUMIFS(Data!$K:$K,Data!$A:$A,2025,Data!$B:$B,6,Data!$G:$G,"FCC") -> 215.541 | H17: =SUMIFS(Data!$K:$K,Data!$A:$A,2025,Data!$B:$B,7,Data!$G:$G,"FCC") -> 183.557 | I17: =SUMIFS(Data!$K:$K,Data!$A:$A,2025,Data!$B:$B,8,Data!$G:$G,"FCC") -> 235.215 | J17: =SUMIFS(Data!$K:$K,Data!$A:$A,2025,Data!$B:$B,9,Data!$G:$G,"FCC") -> 364.325 | K17: =SUMIFS(Data!$K:$K,Data!$A:$A,2025,Data!$B:$B,10,Data!$G:$G,"FCC") -> 702.5715 | L17: =SUMIFS(Data!$K:$K,Data!$A:$A,2025,Data!$B:$B,11,Data!$G:$G,"FCC") -> 409.0129 | M17: =SUMIFS(Data!$K:$K,Data!$A:$A,2025,Data!$B:$B,12,Data!$G:$G,"FCC") -> 75.961
A18: 2026 | B18: =SUMIFS(Data!$K:$K,Data!$A:$A,2026,Data!$B:$B,1,Data!$G:$G,"FCC") -> 299.98 | C18: =SUMIFS(Data!$K:$K,Data!$A:$A,2026,Data!$B:$B,2,Data!$G:$G,"FCC") -> 559.7625 | D18: =SUMIFS(Data!$K:$K,Data!$A:$A,2026,Data!$B:$B,3,Data!$G:$G,"FCC") -> 331.375 | E18: =SUMIFS(Data!$K:$K,Data!$A:$A,2026,Data!$B:$B,4,Data!$G:$G,"FCC") -> 558.008 | F18: =SUMIFS(Data!$K:$K,Data!$A:$A,2026,Data!$B:$B,5,Data!$G:$G,"FCC") -> 360.0815 | G18: =SUMIFS(Data!$K:$K,Data!$A:$A,2026,Data!$B:$B,6,Data!$G:$G,"FCC") -> 147.405 | H18: =SUMIFS(Data!$K:$K,Data!$A:$A,2026,Data!$B:$B,7,Data!$G:$G,"FCC") -> 69.8 | I18: =SUMIFS(Data!$K:$K,Data!$A:$A,2026,Data!$B:$B,8,Data!$G:$G,"FCC") -> 30.6 | J18: =SUMIFS(Data!$K:$K,Data!$A:$A,2026,Data!$B:$B,9,Data!$G:$G,"FCC") -> 68.93 | K18: =SUMIFS(Data!$K:$K,Data!$A:$A,2026,Data!$B:$B,10,Data!$G:$G,"FCC") -> 189.01 | L18: =SUMIFS(Data!$K:$K,Data!$A:$A,2026,Data!$B:$B,11,Data!$G:$G,"FCC") -> 127.225 | M18: =SUMIFS(Data!$K:$K,Data!$A:$A,2026,Data!$B:$B,12,Data!$G:$G,"FCC") -> 4.8
A19: 2027 | B19: =SUMIFS(Data!$K:$K,Data!$A:$A,2027,Data!$B:$B,1,Data!$G:$G,"FCC") -> 250.98 | C19: =SUMIFS(Data!$K:$K,Data!$A:$A,2027,Data!$B:$B,2,Data!$G:$G,"FCC") -> 450.5215 | D19: =SUMIFS(Data!$K:$K,Data!$A:$A,2027,Data!$B:$B,3,Data!$G:$G,"FCC") -> 447.892 | E19: =SUMIFS(Data!$K:$K,Data!$A:$A,2027,Data!$B:$B,4,Data!$G:$G,"FCC") -> 150.455 | F19: =SUMIFS(Data!$K:$K,Data!$A:$A,2027,Data!$B:$B,5,Data!$G:$G,"FCC") -> 23.3 | G19: =SUMIFS(Data!$K:$K,Data!$A:$A,2027,Data!$B:$B,6,Data!$G:$G,"FCC") -> 68.255 | H19: =SUMIFS(Data!$K:$K,Data!$A:$A,2027,Data!$B:$B,7,Data!$G:$G,"FCC") -> 68 | I19: =SUMIFS(Data!$K:$K,Data!$A:$A,2027,Data!$B:$B,8,Data!$G:$G,"FCC") -> 19.72 | J19: =SUMIFS(Data!$K:$K,Data!$A:$A,2027,Data!$B:$B,9,Data!$G:$G,"FCC") -> 176.274 | K19: =SUMIFS(Data!$K:$K,Data!$A:$A,2027,Data!$B:$B,10,Data!$G:$G,"FCC") -> 189.624 | L19: =SUMIFS(Data!$K:$K,Data!$A:$A,2027,Data!$B:$B,11,Data!$G:$G,"FCC") -> 54.87 | M19: =SUMIFS(Data!$K:$K,Data!$A:$A,2027,Data!$B:$B,12,Data!$G:$G,"FCC") -> 0
A22: Hydrocracker
A23: Year | B23: Jan | C23: Feb | D23: Mar | E23: Apr | F23: May | G23: Jun | H23: Jul | I23: Aug | J23: Sep | K23: Oct | L23: Nov | M23: Dec
A24: 2023 | B24: =SUMIFS(Data!$K:$K,Data!$A:$A,2023,Data!$B:$B,1,Data!$G:$G,"Hydrocracker") -> 281.7 | C24: =SUMIFS(Data!$K:$K,Data!$A:$A,2023,Data!$B:$B,2,Data!$G:$G,"Hydrocracker") -> 420.495 | D24: =SUMIFS(Data!$K:$K,Data!$A:$A,2023,Data!$B:$B,3,Data!$G:$G,"Hydrocracker") -> 492.643 | E24: =SUMIFS(Data!$K:$K,Data!$A:$A,2023,Data!$B:$B,4,Data!$G:$G,"Hydrocracker") -> 424.371 | F24: =SUMIFS(Data!$K:$K,Data!$A:$A,2023,Data!$B:$B,5,Data!$G:$G,"Hydrocracker") -> 158.444 | G24: =SUMIFS(Data!$K:$K,Data!$A:$A,2023,Data!$B:$B,6,Data!$G:$G,"Hydrocracker") -> 11.7462 | H24: =SUMIFS(Data!$K:$K,Data!$A:$A,2023,Data!$B:$B,7,Data!$G:$G,"Hydrocracker") -> 40.6884 | I24: =SUMIFS(Data!$K:$K,Data!$A:$A,2023,Data!$B:$B,8,Data!$G:$G,"Hydrocracker") -> 64.313 | J24: =SUMIFS(Data!$K:$K,Data!$A:$A,2023,Data!$B:$B,9,Data!$G:$G,"Hydrocracker") -> 85.565 | K24: =SUMIFS(Data!$K:$K,Data!$A:$A,2023,Data!$B:$B,10,Data!$G:$G,"Hydrocracker") -> 169.43 | L24: =SUMIFS(Data!$K:$K,Data!$A:$A,2023,Data!$B:$B,11,Data!$G:$G,"Hydrocracker") -> 66.22 | M24: =SUMIFS(Data!$K:$K,Data!$A:$A,2023,Data!$B:$B,12,Data!$G:$G,"Hydrocracker") -> 60.28
A25: 2024 | B25: =SUMIFS(Data!$K:$K,Data!$A:$A,2024,Data!$B:$B,1,Data!$G:$G,"Hydrocracker") -> 248.172 | C25: =SUMIFS(Data!$K:$K,Data!$A:$A,2024,Data!$B:$B,2,Data!$G:$G,"Hydrocracker") -> 429.613 | D25: =SUMIFS(Data!$K:$K,Data!$A:$A,2024,Data!$B:$B,3,Data!$G:$G,"Hydrocracker") -> 305.265 | E25: =SUMIFS(Data!$K:$K,Data!$A:$A,2024,Data!$B:$B,4,Data!$G:$G,"Hydrocracker") -> 142.443 | F25: =SUMIFS(Data!$K:$K,Data!$A:$A,2024,Data!$B:$B,5,Data!$G:$G,"Hydrocracker") -> 153.69 | G25: =SUMIFS(Data!$K:$K,Data!$A:$A,2024,Data!$B:$B,6,Data!$G:$G,"Hydrocracker") -> 81.81 | H25: =SUMIFS(Data!$K:$K,Data!$A:$A,2024,Data!$B:$B,7,Data!$G:$G,"Hydrocracker") -> 44.115 | I25: =SUMIFS(Data!$K:$K,Data!$A:$A,2024,Data!$B:$B,8,Data!$G:$G,"Hydrocracker") -> 39.24 | J25: =SUMIFS(Data!$K:$K,Data!$A:$A,2024,Data!$B:$B,9,Data!$G:$G,"Hydrocracker") -> 212.99 | K25: =SUMIFS(Data!$K:$K,Data!$A:$A,2024,Data!$B:$B,10,Data!$G:$G,"Hydrocracker") -> 245.08 | L25: =SUMIFS(Data!$K:$K,Data!$A:$A,2024,Data!$B:$B,11,Data!$G:$G,"Hydrocracker") -> 91.11 | M25: =SUMIFS(Data!$K:$K,Data!$A:$A,2024,Data!$B:$B,12,Data!$G:$G,"Hydrocracker") -> 64.27
A26: 2025 | B26: =SUMIFS(Data!$K:$K,Data!$A:$A,2025,Data!$B:$B,1,Data!$G:$G,"Hydrocracker") -> 158.245 | C26: =SUMIFS(Data!$K:$K,Data!$A:$A,2025,Data!$B:$B,2,Data!$G:$G,"Hydrocracker") -> 255.94 | D26: =SUMIFS(Data!$K:$K,Data!$A:$A,2025,Data!$B:$B,3,Data!$G:$G,"Hydrocracker") -> 219.599 | E26: =SUMIFS(Data!$K:$K,Data!$A:$A,2025,Data!$B:$B,4,Data!$G:$G,"Hydrocracker") -> 244.39 | F26: =SUMIFS(Data!$K:$K,Data!$A:$A,2025,Data!$B:$B,5,Data!$G:$G,"Hydrocracker") -> 128.7 | G26: =SUMIFS(Data!$K:$K,Data!$A:$A,2025,Data!$B:$B,6,Data!$G:$G,"Hydrocracker") -> 149.126 | H26: =SUMIFS(Data!$K:$K,Data!$A:$A,2025,Data!$B:$B,7,Data!$G:$G,"Hydrocracker") -> 155.395 | I26: =SUMIFS(Data!$K:$K,Data!$A:$A,2025,Data!$B:$B,8,Data!$G:$G,"Hydrocracker") -> 201.5 | J26: =SUMIFS(Data!$K:$K,Data!$A:$A,2025,Data!$B:$B,9,Data!$G:$G,"Hydrocracker") -> 144.05 | K26: =SUMIFS(Data!$K:$K,Data!$A:$A,2025,Data!$B:$B,10,Data!$G:$G,"Hydrocracker") -> 242.68 | L26: =SUMIFS(Data!$K:$K,Data!$A:$A,2025,Data!$B:$B,11,Data!$G:$G,"Hydrocracker") -> 146.955 | M26: =SUMIFS(Data!$K:$K,Data!$A:$A,2025,Data!$B:$B,12,Data!$G:$G,"Hydrocracker") -> 84.29
A27: 2026 | B27: =SUMIFS(Data!$K:$K,Data!$A:$A,2026,Data!$B:$B,1,Data!$G:$G,"Hydrocracker") -> 50.92 | C27: =SUMIFS(Data!$K:$K,Data!$A:$A,2026,Data!$B:$B,2,Data!$G:$G,"Hydrocracker") -> 68.32 | D27: =SUMIFS(Data!$K:$K,Data!$A:$A,2026,Data!$B:$B,3,Data!$G:$G,"Hydrocracker") -> 145.776 | E27: =SUMIFS(Data!$K:$K,Data!$A:$A,2026,Data!$B:$B,4,Data!$G:$G,"Hydrocracker") -> 172.765 | F27: =SUMIFS(Data!$K:$K,Data!$A:$A,2026,Data!$B:$B,5,Data!$G:$G,"Hydrocracker") -> 92.77 | G27: =SUMIFS(Data!$K:$K,Data!$A:$A,2026,Data!$B:$B,6,Data!$G:$G,"Hydrocracker") -> 21.38 | H27: =SUMIFS(Data!$K:$K,Data!$A:$A,2026,Data!$B:$B,7,Data!$G:$G,"Hydrocracker") -> 30.24 | I27: =SUMIFS(Data!$K:$K,Data!$A:$A,2026,Data!$B:$B,8,Data!$G:$G,"Hydrocracker") -> 69.66 | J27: =SUMIFS(Data!$K:$K,Data!$A:$A,2026,Data!$B:$B,9,Data!$G:$G,"Hydrocracker") -> 149.15 | K27: =SUMIFS(Data!$K:$K,Data!$A:$A,2026,Data!$B:$B,10,Data!$G:$G,"Hydrocracker") -> 73.98 | L27: =SUMIFS(Data!$K:$K,Data!$A:$A,2026,Data!$B:$B,11,Data!$G:$G,"Hydrocracker") -> 17.296 | M27: =SUMIFS(Data!$K:$K,Data!$A:$A,2026,Data!$B:$B,12,Data!$G:$G,"Hydrocracker") -> 0
A28: 2027 | B28: =SUMIFS(Data!$K:$K,Data!$A:$A,2027,Data!$B:$B,1,Data!$G:$G,"Hydrocracker") -> 121.41 | C28: =SUMIFS(Data!$K:$K,Data!$A:$A,2027,Data!$B:$B,2,Data!$G:$G,"Hydrocracker") -> 141.67 | D28: =SUMIFS(Data!$K:$K,Data!$A:$A,2027,Data!$B:$B,3,Data!$G:$G,"Hydrocracker") -> 75.53 | E28: =SUMIFS(Data!$K:$K,Data!$A:$A,2027,Data!$B:$B,4,Data!$G:$G,"Hydrocracker") -> 39.15 | F28: =SUMIFS(Data!$K:$K,Data!$A:$A,2027,Data!$B:$B,5,Data!$G:$G,"Hydrocracker") -> 0 | G28: =SUMIFS(Data!$K:$K,Data!$A:$A,2027,Data!$B:$B,6,Data!$G:$G,"Hydrocracker") -> 0 | H28: =SUMIFS(Data!$K:$K,Data!$A:$A,2027,Data!$B:$B,7,Data!$G:$G,"Hydrocracker") -> 0 | I28: =SUMIFS(Data!$K:$K,Data!$A:$A,2027,Data!$B:$B,8,Data!$G:$G,"Hydrocracker") -> 0 | J28: =SUMIFS(Data!$K:$K,Data!$A:$A,2027,Data!$B:$B,9,Data!$G:$G,"Hydrocracker") -> 104.88 | K28: =SUMIFS(Data!$K:$K,Data!$A:$A,2027,Data!$B:$B,10,Data!$G:$G,"Hydrocracker") -> 63.94 | L28: =SUMIFS(Data!$K:$K,Data!$A:$A,2027,Data!$B:$B,11,Data!$G:$G,"Hydrocracker") -> 17.653 | M28: =SUMIFS(Data!$K:$K,Data!$A:$A,2027,Data!$B:$B,12,Data!$G:$G,"Hydrocracker") -> 0
A31: Reformer
A32: Year | B32: Jan | C32: Feb | D32: Mar | E32: Apr | F32: May | G32: Jun | H32: Jul | I32: Aug | J32: Sep | K32: Oct | L32: Nov | M32: Dec
A33: 2023 | B33: =SUMIFS(Data!$K:$K,Data!$A:$A,2023,Data!$B:$B,1,Data!$G:$G,"Reformer") -> 432.859 | C33: =SUMIFS(Data!$K:$K,Data!$A:$A,2023,Data!$B:$B,2,Data!$G:$G,"Reformer") -> 453.94 | D33: =SUMIFS(Data!$K:$K,Data!$A:$A,2023,Data!$B:$B,3,Data!$G:$G,"Reformer") -> 486.416 | E33: =SUMIFS(Data!$K:$K,Data!$A:$A,2023,Data!$B:$B,4,Data!$G:$G,"Reformer") -> 495.342 | F33: =SUMIFS(Data!$K:$K,Data!$A:$A,2023,Data!$B:$B,5,Data!$G:$G,"Reformer") -> 360.457 | G33: =SUMIFS(Data!$K:$K,Data!$A:$A,2023,Data!$B:$B,6,Data!$G:$G,"Reformer") -> 198.97 | H33: =SUMIFS(Data!$K:$K,Data!$A:$A,2023,Data!$B:$B,7,Data!$G:$G,"Reformer") -> 147.233 | I33: =SUMIFS(Data!$K:$K,Data!$A:$A,2023,Data!$B:$B,8,Data!$G:$G,"Reformer") -> 238.18 | J33: =SUMIFS(Data!$K:$K,Data!$A:$A,2023,Data!$B:$B,9,Data!$G:$G,"Reformer") -> 236.457 | K33: =SUMIFS(Data!$K:$K,Data!$A:$A,2023,Data!$B:$B,10,Data!$G:$G,"Reformer") -> 529.1175 | L33: =SUMIFS(Data!$K:$K,Data!$A:$A,2023,Data!$B:$B,11,Data!$G:$G,"Reformer") -> 371.958 | M33: =SUMIFS(Data!$K:$K,Data!$A:$A,2023,Data!$B:$B,12,Data!$G:$G,"Reformer") -> 67.175
A34: 2024 | B34: =SUMIFS(Data!$K:$K,Data!$A:$A,2024,Data!$B:$B,1,Data!$G:$G,"Reformer") -> 436.8612 | C34: =SUMIFS(Data!$K:$K,Data!$A:$A,2024,Data!$B:$B,2,Data!$G:$G,"Reformer") -> 843.04 | D34: =SUMIFS(Data!$K:$K,Data!$A:$A,2024,Data!$B:$B,3,Data!$G:$G,"Reformer") -> 439.2958 | E34: =SUMIFS(Data!$K:$K,Data!$A:$A,2024,Data!$B:$B,4,Data!$G:$G,"Reformer") -> 470.9954 | F34: =SUMIFS(Data!$K:$K,Data!$A:$A,2024,Data!$B:$B,5,Data!$G:$G,"Reformer") -> 285.8775 | G34: =SUMIFS(Data!$K:$K,Data!$A:$A,2024,Data!$B:$B,6,Data!$G:$G,"Reformer") -> 303.314 | H34: =SUMIFS(Data!$K:$K,Data!$A:$A,2024,Data!$B:$B,7,Data!$G:$G,"Reformer") -> 129.5725 | I34: =SUMIFS(Data!$K:$K,Data!$A:$A,2024,Data!$B:$B,8,Data!$G:$G,"Reformer") -> 149.935 | J34: =SUMIFS(Data!$K:$K,Data!$A:$A,2024,Data!$B:$B,9,Data!$G:$G,"Reformer") -> 319.02 | K34: =SUMIFS(Data!$K:$K,Data!$A:$A,2024,Data!$B:$B,10,Data!$G:$G,"Reformer") -> 587.828 | L34: =SUMIFS(Data!$K:$K,Data!$A:$A,2024,Data!$B:$B,11,Data!$G:$G,"Reformer") -> 228.1725 | M34: =SUMIFS(Data!$K:$K,Data!$A:$A,2024,Data!$B:$B,12,Data!$G:$G,"Reformer") -> 29.63
A35: 2025 | B35: =SUMIFS(Data!$K:$K,Data!$A:$A,2025,Data!$B:$B,1,Data!$G:$G,"Reformer") -> 160.3135 | C35: =SUMIFS(Data!$K:$K,Data!$A:$A,2025,Data!$B:$B,2,Data!$G:$G,"Reformer") -> 251.5285 | D35: =SUMIFS(Data!$K:$K,Data!$A:$A,2025,Data!$B:$B,3,Data!$G:$G,"Reformer") -> 301.84 | E35: =SUMIFS(Data!$K:$K,Data!$A:$A,2025,Data!$B:$B,4,Data!$G:$G,"Reformer") -> 443.2805 | F35: =SUMIFS(Data!$K:$K,Data!$A:$A,2025,Data!$B:$B,5,Data!$G:$G,"Reformer") -> 213.1394 | G35: =SUMIFS(Data!$K:$K,Data!$A:$A,2025,Data!$B:$B,6,Data!$G:$G,"Reformer") -> 90.0075 | H35: =SUMIFS(Data!$K:$K,Data!$A:$A,2025,Data!$B:$B,7,Data!$G:$G,"Reformer") -> 37.819 | I35: =SUMIFS(Data!$K:$K,Data!$A:$A,2025,Data!$B:$B,8,Data!$G:$G,"Reformer") -> 87.9 | J35: =SUMIFS(Data!$K:$K,Data!$A:$A,2025,Data!$B:$B,9,Data!$G:$G,"Reformer") -> 131.7565 | K35: =SUMIFS(Data!$K:$K,Data!$A:$A,2025,Data!$B:$B,10,Data!$G:$G,"Reformer") -> 379.416 | L35: =SUMIFS(Data!$K:$K,Data!$A:$A,2025,Data!$B:$B,11,Data!$G:$G,"Reformer") -> 227.8095 | M35: =SUMIFS(Data!$K:$K,Data!$A:$A,2025,Data!$B:$B,12,Data!$G:$G,"Reformer") -> 25.235
A36: 2026 | B36: =SUMIFS(Data!$K:$K,Data!$A:$A,2026,Data!$B:$B,1,Data!$G:$G,"Reformer") -> 95.4175 | C36: =SUMIFS(Data!$K:$K,Data!$A:$A,2026,Data!$B:$B,2,Data!$G:$G,"Reformer") -> 210.5685 | D36: =SUMIFS(Data!$K:$K,Data!$A:$A,2026,Data!$B:$B,3,Data!$G:$G,"Reformer") -> 159.17 | E36: =SUMIFS(Data!$K:$K,Data!$A:$A,2026,Data!$B:$B,4,Data!$G:$G,"Reformer") -> 154.283 | F36: =SUMIFS(Data!$K:$K,Data!$A:$A,2026,Data!$B:$B,5,Data!$G:$G,"Reformer") -> 157.769 | G36: =SUMIFS(Data!$K:$K,Data!$A:$A,2026,Data!$B:$B,6,Data!$G:$G,"Reformer") -> 130.51 | H36: =SUMIFS(Data!$K:$K,Data!$A:$A,2026,Data!$B:$B,7,Data!$G:$G,"Reformer") -> 98.204 | I36: =SUMIFS(Data!$K:$K,Data!$A:$A,2026,Data!$B:$B,8,Data!$G:$G,"Reformer") -> 44.905 | J36: =SUMIFS(Data!$K:$K,Data!$A:$A,2026,Data!$B:$B,9,Data!$G:$G,"Reformer") -> 137.55 | K36: =SUMIFS(Data!$K:$K,Data!$A:$A,2026,Data!$B:$B,10,Data!$G:$G,"Reformer") -> 166.385 | L36: =SUMIFS(Data!$K:$K,Data!$A:$A,2026,Data!$B:$B,11,Data!$G:$G,"Reformer") -> 68.1 | M36: =SUMIFS(Data!$K:$K,Data!$A:$A,2026,Data!$B:$B,12,Data!$G:$G,"Reformer") -> 0
A37: 2027 | B37: =SUMIFS(Data!$K:$K,Data!$A:$A,2027,Data!$B:$B,1,Data!$G:$G,"Reformer") -> 29.125 | C37: =SUMIFS(Data!$K:$K,Data!$A:$A,2027,Data!$B:$B,2,Data!$G:$G,"Reformer") -> 68.78 | D37: =SUMIFS(Data!$K:$K,Data!$A:$A,2027,Data!$B:$B,3,Data!$G:$G,"Reformer") -> 184.889 | E37: =SUMIFS(Data!$K:$K,Data!$A:$A,2027,Data!$B:$B,4,Data!$G:$G,"Reformer") -> 141.475 | F37: =SUMIFS(Data!$K:$K,Data!$A:$A,2027,Data!$B:$B,5,Data!$G:$G,"Reformer") -> 45.428 | G37: =SUMIFS(Data!$K:$K,Data!$A:$A,2027,Data!$B:$B,6,Data!$G:$G,"Reformer") -> 0.3 | H37: =SUMIFS(Data!$K:$K,Data!$A:$A,2027,Data!$B:$B,7,Data!$G:$G,"Reformer") -> 0 | I37: =SUMIFS(Data!$K:$K,Data!$A:$A,2027,Data!$B:$B,8,Data!$G:$G,"Reformer") -> 0 | J37: =SUMIFS(Data!$K:$K,Data!$A:$A,2027,Data!$B:$B,9,Data!$G:$G,"Reformer") -> 112.05 | K37: =SUMIFS(Data!$K:$K,Data!$A:$A,2027,Data!$B:$B,10,Data!$G:$G,"Reformer") -> 109.945 | L37: =SUMIFS(Data!$K:$K,Data!$A:$A,2027,Data!$B:$B,11,Data!$G:$G,"Reformer") -> 20.105 | M37: =SUMIFS(Data!$K:$K,Data!$A:$A,2027,Data!$B:$B,12,Data!$G:$G,"Reformer") -> 0
A40: Busiest-month concurrent offline (=MAX of the unit's months)
A41: Year | B41: Crude (CDU) | C41: FCC (cat cracker) | D41: Hydrocracker | E41: Reformer
A42: 2023 | B42: =MAX(B6:M6) -> 2180.255 | C42: =MAX(B15:M15) -> 1025.05 | D42: =MAX(B24:M24) -> 492.643 | E42: =MAX(B33:M33) -> 529.1175
A43: 2024 | B43: =MAX(B7:M7) -> 2142.5348 | C43: =MAX(B16:M16) -> 1054.9718 | D43: =MAX(B25:M25) -> 429.613 | E43: =MAX(B34:M34) -> 843.04
A44: 2025 | B44: =MAX(B8:M8) -> 1864.885 | C44: =MAX(B17:M17) -> 702.5715 | D44: =MAX(B26:M26) -> 255.94 | E44: =MAX(B35:M35) -> 443.2805
A45: 2026 | B45: =MAX(B9:M9) -> 1411.605 | C45: =MAX(B18:M18) -> 559.7625 | D45: =MAX(B27:M27) -> 172.765 | E45: =MAX(B36:M36) -> 210.5685
A46: 2027 | B46: =MAX(B10:M10) -> 1307.315 | C46: =MAX(B19:M19) -> 450.5215 | D46: =MAX(B28:M28) -> 141.67 | E46: =MAX(B37:M37) -> 184.889

Sheet Biggest
A1: Biggest 2027 Outages by Unit (nameplate kbd, from Data)
A2: Individual units, never added. PADD shows where the tonnage sits.
A4: Refinery | B4: Unit | C4: Class | D4: PADD | E4: kbd | F4: Window | G4: Type | H4: Status
A5: Joliet | B5: Crude | C5: CDU | D5: PADD 2 | E5: 250 | F5: Apr-May | G5: Planned | H5: confirmed
A6: Cherry Point | B6: Crude | C6: CDU | D6: PADD 5 | E6: 250 | F6: Mar | G6: Planned | H6: confirmed
A7: Norco | B7: DU-5 (Distilling Unit) (Sweet) | C7: CDU | D7: PADD 3 | E7: 240 | F7: Oct-Nov | G7: Planned | H7: indicative (H2)
A8: Richmond | B8: Crude | C8: CDU | D8: PADD 5 | E8: 240 | F8: Oct | G8: Planned | H8: indicative (H2)
A9: Lemont | B9: Crude Distillation 111 | C9: CDU | D9: PADD 2 | E9: 175 | F9: Apr-May | G9: Planned | H9: confirmed
A10: Martinez (PBF) | B10: DH Crude | C10: CDU | D10: PADD 5 | E10: 155 | F10: Jan-Mar | G10: Planned | H10: confirmed
A11: Garyville | B11: Crude 10 B-Train Sour/Sweet | C11: CDU | D11: PADD 3 | E11: 145 | F11: Sep-Nov | G11: Planned | H11: indicative (H2)
A12: Garyville | B12: Crude 10 A-Train/Sour | C12: CDU | D12: PADD 3 | E12: 145 | F12: Sep-Nov | G12: Planned | H12: indicative (H2)
A13: Garyville | B13: Crude 210 | C13: CDU | D13: PADD 3 | E13: 138 | F13: Jan-Feb | G13: Planned | H13: confirmed
A14: Baytown | B14: FCCU 3 (Fuels East) | C14: FCC | D14: PADD 3 | E14: 125 | F14: Feb-Apr | G14: Planned | H14: confirmed
A15: Beaumont | B15: FCCU | C15: FCC | D15: PADD 3 | E15: 120 | F15: Jan-Feb | G15: Planned | H15: confirmed
A16: Memphis | B16: Crude East | C16: CDU | D16: PADD 2 | E16: 110 | F16: Sep-Oct | G16: Planned | H16: indicative (H2)
... A34: Sweeny | B34: Heavy Oil Cracker 27-1 | C34: FCC | D34: PADD 3 | E34: 78 | F34: Jan-Mar | G34: Planned | H34: confirmed

Sheet H1 by Unit
A1: H1 (Jan-Jun) Planned Offline per Unit & Month = SUMIFS (type=Planned)
A2: Like-for-like cross-year read; 2027 is confirmed through H1. H1 avg = AVERAGE of the row.
A4: Crude (CDU)
A5: Year | B5: Jan | C5: Feb | D5: Mar | E5: Apr | F5: May | G5: Jun
A6: 2025 | B6: =SUMIFS(Data!$K:$K,Data!$A:$A,2025,Data!$B:$B,1,Data!$G:$G,"CDU",Data!$J:$J,"PLANNED") -> 757.195 | C6: =SUMIFS(Data!$K:$K,Data!$A:$A,2025,Data!$B:$B,2,Data!$G:$G,"CDU",Data!$J:$J,"PLANNED") -> 1058.991 | D6: =SUMIFS(Data!$K:$K,Data!$A:$A,2025,Data!$B:$B,3,Data!$G:$G,"CDU",Data!$J:$J,"PLANNED") -> 935.345 | E6: =SUMIFS(Data!$K:$K,Data!$A:$A,2025,Data!$B:$B,4,Data!$G:$G,"CDU",Data!$J:$J,"PLANNED") -> 1072.7975 | F6: =SUMIFS(Data!$K:$K,Data!$A:$A,2025,Data!$B:$B,5,Data!$G:$G,"CDU",Data!$J:$J,"PLANNED") -> 286.61 | G6: =SUMIFS(Data!$K:$K,Data!$A:$A,2025,Data!$B:$B,6,Data!$G:$G,"CDU",Data!$J:$J,"PLANNED") -> 118.65
A7: 2026 | B7: =SUMIFS(Data!$K:$K,Data!$A:$A,2026,Data!$B:$B,1,Data!$G:$G,"CDU",Data!$J:$J,"PLANNED") -> 284.73 | C7: =SUMIFS(Data!$K:$K,Data!$A:$A,2026,Data!$B:$B,2,Data!$G:$G,"CDU",Data!$J:$J,"PLANNED") -> 699.13 | D7: =SUMIFS(Data!$K:$K,Data!$A:$A,2026,Data!$B:$B,3,Data!$G:$G,"CDU",Data!$J:$J,"PLANNED") -> 638.401 | E7: =SUMIFS(Data!$K:$K,Data!$A:$A,2026,Data!$B:$B,4,Data!$G:$G,"CDU",Data!$J:$J,"PLANNED") -> 720.29 | F7: =SUMIFS(Data!$K:$K,Data!$A:$A,2026,Data!$B:$B,5,Data!$G:$G,"CDU",Data!$J:$J,"PLANNED") -> 516.362 | G7: =SUMIFS(Data!$K:$K,Data!$A:$A,2026,Data!$B:$B,6,Data!$G:$G,"CDU",Data!$J:$J,"PLANNED") -> 126.65
A8: 2027 | B8: =SUMIFS(Data!$K:$K,Data!$A:$A,2027,Data!$B:$B,1,Data!$G:$G,"CDU",Data!$J:$J,"PLANNED") -> 365.125 | C8: =SUMIFS(Data!$K:$K,Data!$A:$A,2027,Data!$B:$B,2,Data!$G:$G,"CDU",Data!$J:$J,"PLANNED") -> 683.258 | D8: =SUMIFS(Data!$K:$K,Data!$A:$A,2027,Data!$B:$B,3,Data!$G:$G,"CDU",Data!$J:$J,"PLANNED") -> 1062.14 | E8: =SUMIFS(Data!$K:$K,Data!$A:$A,2027,Data!$B:$B,4,Data!$G:$G,"CDU",Data!$J:$J,"PLANNED") -> 663.255 | F8: =SUMIFS(Data!$K:$K,Data!$A:$A,2027,Data!$B:$B,5,Data!$G:$G,"CDU",Data!$J:$J,"PLANNED") -> 320.192 | G8: =SUMIFS(Data!$K:$K,Data!$A:$A,2027,Data!$B:$B,6,Data!$G:$G,"CDU",Data!$J:$J,"PLANNED") -> 96
A11: FCC (cat cracker)
A12: Year | B12: Jan | C12: Feb | D12: Mar | E12: Apr | F12: May | G12: Jun
A13: 2025 | B13: =SUMIFS(Data!$K:$K,Data!$A:$A,2025,Data!$B:$B,1,Data!$G:$G,"FCC",Data!$J:$J,"PLANNED") -> 150.66 | C13: =SUMIFS(Data!$K:$K,Data!$A:$A,2025,Data!$B:$B,2,Data!$G:$G,"FCC",Data!$J:$J,"PLANNED") -> 209.57 | D13: =SUMIFS(Data!$K:$K,Data!$A:$A,2025,Data!$B:$B,3,Data!$G:$G,"FCC",Data!$J:$J,"PLANNED") -> 240.735 | E13: =SUMIFS(Data!$K:$K,Data!$A:$A,2025,Data!$B:$B,4,Data!$G:$G,"FCC",Data!$J:$J,"PLANNED") -> 331.825 | F13: =SUMIFS(Data!$K:$K,Data!$A:$A,2025,Data!$B:$B,5,Data!$G:$G,"FCC",Data!$J:$J,"PLANNED") -> 171.93 | G13: =SUMIFS(Data!$K:$K,Data!$A:$A,2025,Data!$B:$B,6,Data!$G:$G,"FCC",Data!$J:$J,"PLANNED") -> 20.97
A14: 2026 | B14: =SUMIFS(Data!$K:$K,Data!$A:$A,2026,Data!$B:$B,1,Data!$G:$G,"FCC",Data!$J:$J,"PLANNED") -> 168.25 | C14: =SUMIFS(Data!$K:$K,Data!$A:$A,2026,Data!$B:$B,2,Data!$G:$G,"FCC",Data!$J:$J,"PLANNED") -> 303.52 | D14: =SUMIFS(Data!$K:$K,Data!$A:$A,2026,Data!$B:$B,3,Data!$G:$G,"FCC",Data!$J:$J,"PLANNED") -> 199.243 | E14: =SUMIFS(Data!$K:$K,Data!$A:$A,2026,Data!$B:$B,4,Data!$G:$G,"FCC",Data!$J:$J,"PLANNED") -> 135.45 | F14: =SUMIFS(Data!$K:$K,Data!$A:$A,2026,Data!$B:$B,5,Data!$G:$G,"FCC",Data!$J:$J,"PLANNED") -> 32.069 | G14: =SUMIFS(Data!$K:$K,Data!$A:$A,2026,Data!$B:$B,6,Data!$G:$G,"FCC",Data!$J:$J,"PLANNED") -> 0
A15: 2027 | B15: =SUMIFS(Data!$K:$K,Data!$A:$A,2027,Data!$B:$B,1,Data!$G:$G,"FCC",Data!$J:$J,"PLANNED") -> 250.98 | C15: =SUMIFS(Data!$K:$K,Data!$A:$A,2027,Data!$B:$B,2,Data!$G:$G,"FCC",Data!$J:$J,"PLANNED") -> 450.5215 | D15: =SUMIFS(Data!$K:$K,Data!$A:$A,2027,Data!$B:$B,3,Data!$G:$G,"FCC",Data!$J:$J,"PLANNED") -> 447.892 | E15: =SUMIFS(Data!$K:$K,Data!$A:$A,2027,Data!$B:$B,4,Data!$G:$G,"FCC",Data!$J:$J,"PLANNED") -> 150.455 | F15: =SUMIFS(Data!$K:$K,Data!$A:$A,2027,Data!$B:$B,5,Data!$G:$G,"FCC",Data!$J:$J,"PLANNED") -> 23.3 | G15: =SUMIFS(Data!$K:$K,Data!$A:$A,2027,Data!$B:$B,6,Data!$G:$G,"FCC",Data!$J:$J,"PLANNED") -> 68.255
A18: Hydrocracker
A19: Year | B19: Jan | C19: Feb | D19: Mar | E19: Apr | F19: May | G19: Jun
A20: 2025 | B20: =SUMIFS(Data!$K:$K,Data!$A:$A,2025,Data!$B:$B,1,Data!$G:$G,"Hydrocracker",Data!$J:$J,"PLANNED") -> 84.48 | C20: =SUMIFS(Data!$K:$K,Data!$A:$A,2025,Data!$B:$B,2,Data!$G:$G,"Hydrocracker",Data!$J:$J,"PLANNED") -> 64.74 | D20: =SUMIFS(Data!$K:$K,Data!$A:$A,2025,Data!$B:$B,3,Data!$G:$G,"Hydrocracker",Data!$J:$J,"PLANNED") -> 9.669 | E20: =SUMIFS(Data!$K:$K,Data!$A:$A,2025,Data!$B:$B,4,Data!$G:$G,"Hydrocracker",Data!$J:$J,"PLANNED") -> 64.31 | F20: =SUMIFS(Data!$K:$K,Data!$A:$A,2025,Data!$B:$B,5,Data!$G:$G,"Hydrocracker",Data!$J:$J,"PLANNED") -> 45.6 | G20: =SUMIFS(Data!$K:$K,Data!$A:$A,2025,Data!$B:$B,6,Data!$G:$G,"Hydrocracker",Data!$J:$J,"PLANNED") -> 20.811
A21: 2026 | B21: =SUMIFS(Data!$K:$K,Data!$A:$A,2026,Data!$B:$B,1,Data!$G:$G,"Hydrocracker",Data!$J:$J,"PLANNED") -> 44.38 | C21: =SUMIFS(Data!$K:$K,Data!$A:$A,2026,Data!$B:$B,2,Data!$G:$G,"Hydrocracker",Data!$J:$J,"PLANNED") -> 49.32 | D21: =SUMIFS(Data!$K:$K,Data!$A:$A,2026,Data!$B:$B,3,Data!$G:$G,"Hydrocracker",Data!$J:$J,"PLANNED") -> 81.245 | E21: =SUMIFS(Data!$K:$K,Data!$A:$A,2026,Data!$B:$B,4,Data!$G:$G,"Hydrocracker",Data!$J:$J,"PLANNED") -> 106.25 | F21: =SUMIFS(Data!$K:$K,Data!$A:$A,2026,Data!$B:$B,5,Data!$G:$G,"Hydrocracker",Data!$J:$J,"PLANNED") -> 59.05 | G21: =SUMIFS(Data!$K:$K,Data!$A:$A,2026,Data!$B:$B,6,Data!$G:$G,"Hydrocracker",Data!$J:$J,"PLANNED") -> 6.5
A22: 2027 | B22: =SUMIFS(Data!$K:$K,Data!$A:$A,2027,Data!$B:$B,1,Data!$G:$G,"Hydrocracker",Data!$J:$J,"PLANNED") -> 121.41 | C22: =SUMIFS(Data!$K:$K,Data!$A:$A,2027,Data!$B:$B,2,Data!$G:$G,"Hydrocracker",Data!$J:$J,"PLANNED") -> 141.67 | D22: =SUMIFS(Data!$K:$K,Data!$A:$A,2027,Data!$B:$B,3,Data!$G:$G,"Hydrocracker",Data!$J:$J,"PLANNED") -> 75.53 | E22: =SUMIFS(Data!$K:$K,Data!$A:$A,2027,Data!$B:$B,4,Data!$G:$G,"Hydrocracker",Data!$J:$J,"PLANNED") -> 39.15 | F22: =SUMIFS(Data!$K:$K,Data!$A:$A,2027,Data!$B:$B,5,Data!$G:$G,"Hydrocracker",Data!$J:$J,"PLANNED") -> 0 | G22: =SUMIFS(Data!$K:$K,Data!$A:$A,2027,Data!$B:$B,6,Data!$G:$G,"Hydrocracker",Data!$J:$J,"PLANNED") -> 0
A25: Reformer
A26: Year | B26: Jan | C26: Feb | D26: Mar | E26: Apr | F26: May | G26: Jun
A27: 2025 | B27: =SUMIFS(Data!$K:$K,Data!$A:$A,2025,Data!$B:$B,1,Data!$G:$G,"Reformer",Data!$J:$J,"PLANNED") -> 78.466 | C27: =SUMIFS(Data!$K:$K,Data!$A:$A,2025,Data!$B:$B,2,Data!$G:$G,"Reformer",Data!$J:$J,"PLANNED") -> 145.75 | D27: =SUMIFS(Data!$K:$K,Data!$A:$A,2025,Data!$B:$B,3,Data!$G:$G,"Reformer",Data!$J:$J,"PLANNED") -> 160.432 | E27: =SUMIFS(Data!$K:$K,Data!$A:$A,2025,Data!$B:$B,4,Data!$G:$G,"Reformer",Data!$J:$J,"PLANNED") -> 202.358 | F27: =SUMIFS(Data!$K:$K,Data!$A:$A,2025,Data!$B:$B,5,Data!$G:$G,"Reformer",Data!$J:$J,"PLANNED") -> 113.691 | G27: =SUMIFS(Data!$K:$K,Data!$A:$A,2025,Data!$B:$B,6,Data!$G:$G,"Reformer",Data!$J:$J,"PLANNED") -> 43.806
A28: 2026 | B28: =SUMIFS(Data!$K:$K,Data!$A:$A,2026,Data!$B:$B,1,Data!$G:$G,"Reformer",Data!$J:$J,"PLANNED") -> 44.665 | C28: =SUMIFS(Data!$K:$K,Data!$A:$A,2026,Data!$B:$B,2,Data!$G:$G,"Reformer",Data!$J:$J,"PLANNED") -> 60.616 | D28: =SUMIFS(Data!$K:$K,Data!$A:$A,2026,Data!$B:$B,3,Data!$G:$G,"Reformer",Data!$J:$J,"PLANNED") -> 85.93 | E28: =SUMIFS(Data!$K:$K,Data!$A:$A,2026,Data!$B:$B,4,Data!$G:$G,"Reformer",Data!$J:$J,"PLANNED") -> 92.18 | F28: =SUMIFS(Data!$K:$K,Data!$A:$A,2026,Data!$B:$B,5,Data!$G:$G,"Reformer",Data!$J:$J,"PLANNED") -> 51.27 | G28: =SUMIFS(Data!$K:$K,Data!$A:$A,2026,Data!$B:$B,6,Data!$G:$G,"Reformer",Data!$J:$J,"PLANNED") -> 6.5
A29: 2027 | B29: =SUMIFS(Data!$K:$K,Data!$A:$A,2027,Data!$B:$B,1,Data!$G:$G,"Reformer",Data!$J:$J,"PLANNED") -> 29.125 | C29: =SUMIFS(Data!$K:$K,Data!$A:$A,2027,Data!$B:$B,2,Data!$G:$G,"Reformer",Data!$J:$J,"PLANNED") -> 68.78 | D29: =SUMIFS(Data!$K:$K,Data!$A:$A,2027,Data!$B:$B,3,Data!$G:$G,"Reformer",Data!$J:$J,"PLANNED") -> 184.889 | E29: =SUMIFS(Data!$K:$K,Data!$A:$A,2027,Data!$B:$B,4,Data!$G:$G,"Reformer",Data!$J:$J,"PLANNED") -> 141.475 | F29: =SUMIFS(Data!$K:$K,Data!$A:$A,2027,Data!$B:$B,5,Data!$G:$G,"Reformer",Data!$J:$J,"PLANNED") -> 45.428 | G29: =SUMIFS(Data!$K:$K,Data!$A:$A,2027,Data!$B:$B,6,Data!$G:$G,"Reformer",Data!$J:$J,"PLANNED") -> 0.3
A32: H1 average offline (=AVERAGE Jan:Jun)
A33: Unit | B33: 2025 | C33: 2026 | D33: 2027
A34: Crude (CDU) | B34: =AVERAGE(B6:G6) -> 704.93142 | C34: =AVERAGE(B7:G7) -> 497.59383 | D34: =AVERAGE(B8:G8) -> 531.66167
A35: FCC (cat cracker) | B35: =AVERAGE(B13:G13) -> 187.615 | C35: =AVERAGE(B14:G14) -> 139.75533 | D35: =AVERAGE(B15:G15) -> 231.90058
A36: Hydrocracker | B36: =AVERAGE(B20:G20) -> 48.268333 | C36: =AVERAGE(B21:G21) -> 57.790833 | D36: =AVERAGE(B22:G22) -> 62.96
A37: Reformer | B37: =AVERAGE(B27:G27) -> 124.08383 | C37: =AVERAGE(B28:G28) -> 56.860167 | D37: =AVERAGE(B29:G29) -> 78.332833

Sheet PADD by Unit
A1: Outages by PADD by Unit: full history with MoM% and YoY% = SUMIFS over Data
A2: CDU and FCC offline by PADD and month, 2023-2027: level, month-over-month % and year-over-year %.
A4: Unit | B4: PADD | C4: Year | D4: Mon | E4: Period | F4: kbd | G4: MoM % | H4: YoY %
A5: CDU | B5: P1 | C5: 2023 | D5: 1 | E5: Jan 23 | F5: =SUMIFS(Data!$K:$K,Data!$A:$A,2023,Data!$B:$B,1,Data!$G:$G,"CDU",Data!$F:$F,"PADD 1") -> 63.26
A6: CDU | B6: P1 | C6: 2023 | D6: 2 | E6: Feb 23 | F6: =SUMIFS(Data!$K:$K,Data!$A:$A,2023,Data!$B:$B,2,Data!$G:$G,"CDU",Data!$F:$F,"PADD 1") -> 129 | G6: =IFERROR(F6/F5-1,"") -> 1.0392033
A7: CDU | B7: P1 | C7: 2023 | D7: 3 | E7: Mar 23 | F7: =SUMIFS(Data!$K:$K,Data!$A:$A,2023,Data!$B:$B,3,Data!$G:$G,"CDU",Data!$F:$F,"PADD 1") -> 189.71 | G7: =IFERROR(F7/F6-1,"") -> 0.47062016
A8: CDU | B8: P1 | C8: 2023 | D8: 4 | E8: Apr 23 | F8: =SUMIFS(Data!$K:$K,Data!$A:$A,2023,Data!$B:$B,4,Data!$G:$G,"CDU",Data!$F:$F,"PADD 1") -> 22.31 | G8: =IFERROR(F8/F7-1,"") -> -0.88239945
A9: CDU | B9: P1 | C9: 2023 | D9: 5 | E9: May 23 | F9: =SUMIFS(Data!$K:$K,Data!$A:$A,2023,Data!$B:$B,5,Data!$G:$G,"CDU",Data!$F:$F,"PADD 1") -> 0 | G9: =IFERROR(F9/F8-1,"") -> -1
A10: CDU | B10: P1 | C10: 2023 | D10: 6 | E10: Jun 23 | F10: =SUMIFS(Data!$K:$K,Data!$A:$A,2023,Data!$B:$B,6,Data!$G:$G,"CDU",Data!$F:$F,"PADD 1") -> 99.5225 | G10: =IFERROR(F10/F9-1,"")
A11: CDU | B11: P1 | C11: 2023 | D11: 7 | E11: Jul 23 | F11: =SUMIFS(Data!$K:$K,Data!$A:$A,2023,Data!$B:$B,7,Data!$G:$G,"CDU",Data!$F:$F,"PADD 1") -> 87.89 | G11: =IFERROR(F11/F10-1,"") -> -0.11688312
A12: CDU | B12: P1 | C12: 2023 | D12: 8 | E12: Aug 23 | F12: =SUMIFS(Data!$K:$K,Data!$A:$A,2023,Data!$B:$B,8,Data!$G:$G,"CDU",Data!$F:$F,"PADD 1") -> 0 | G12: =IFERROR(F12/F11-1,"") -> -1
A13: CDU | B13: P1 | C13: 2023 | D13: 9 | E13: Sep 23 | F13: =SUMIFS(Data!$K:$K,Data!$A:$A,2023,Data!$B:$B,9,Data!$G:$G,"CDU",Data!$F:$F,"PADD 1") -> 100.725 | G13: =IFERROR(F13/F12-1,"")
A14: CDU | B14: P1 | C14: 2023 | D14: 10 | E14: Oct 23 | F14: =SUMIFS(Data!$K:$K,Data!$A:$A,2023,Data!$B:$B,10,Data!$G:$G,"CDU",Data!$F:$F,"PADD 1") -> 185 | G14: =IFERROR(F14/F13-1,"") -> 0.83668404
A15: CDU | B15: P1 | C15: 2023 | D15: 11 | E15: Nov 23 | F15: =SUMIFS(Data!$K:$K,Data!$A:$A,2023,Data!$B:$B,11,Data!$G:$G,"CDU",Data!$F:$F,"PADD 1") -> 55.5 | G15: =IFERROR(F15/F14-1,"") -> -0.7
A16: CDU | B16: P1 | C16: 2023 | D16: 12 | E16: Dec 23 | F16: =SUMIFS(Data!$K:$K,Data!$A:$A,2023,Data!$B:$B,12,Data!$G:$G,"CDU",Data!$F:$F,"PADD 1") -> 25.85 | G16: =IFERROR(F16/F15-1,"") -> -0.53423423
A17: CDU | B17: P1 | C17: 2024 | D17: 1 | E17: Jan 24 | F17: =SUMIFS(Data!$K:$K,Data!$A:$A,2024,Data!$B:$B,1,Data!$G:$G,"CDU",Data!$F:$F,"PADD 1") -> 39.56 | G17: =IFERROR(F17/F16-1,"") -> 0.5303675 | H17: =IFERROR(F17/F5-1,"") -> -0.37464433
A18: CDU | B18: P1 | C18: 2024 | D18: 2 | E18: Feb 24 | F18: =SUMIFS(Data!$K:$K,Data!$A:$A,2024,Data!$B:$B,2,Data!$G:$G,"CDU",Data!$F:$F,"PADD 1") -> 0 | G18: =IFERROR(F18/F17-1,"") -> -1 | H18: =IFERROR(F18/F6-1,"") -> -1
A19: CDU | B19: P1 | C19: 2024 | D19: 3 | E19: Mar 24 | F19: =SUMIFS(Data!$K:$K,Data!$A:$A,2024,Data!$B:$B,3,Data!$G:$G,"CDU",Data!$F:$F,"PADD 1") -> 60.55 | G19: =IFERROR(F19/F18-1,"") | H19: =IFERROR(F19/F7-1,"") -> -0.68082863
A20: CDU | B20: P1 | C20: 2024 | D20: 4 | E20: Apr 24 | F20: =SUMIFS(Data!$K:$K,Data!$A:$A,2024,Data!$B:$B,4,Data!$G:$G,"CDU",Data!$F:$F,"PADD 1") -> 47.775 | G20: =IFERROR(F20/F19-1,"") -> -0.21098266 | H20: =IFERROR(F20/F8-1,"") -> 1.1414164
A21: CDU | B21: P1 | C21: 2024 | D21: 5 | E21: May 24 | F21: =SUMIFS(Data!$K:$K,Data!$A:$A,2024,Data!$B:$B,5,Data!$G:$G,"CDU",Data!$F:$F,"PADD 1") -> 0 | G21: =IFERROR(F21/F20-1,"") -> -1 | H21: =IFERROR(F21/F9-1,"")
A22: CDU | B22: P1 | C22: 2024 | D22: 6 | E22: Jun 24 | F22: =SUMIFS(Data!$K:$K,Data!$A:$A,2024,Data!$B:$B,6,Data!$G:$G,"CDU",Data!$F:$F,"PADD 1") -> 0 | G22: =IFERROR(F22/F21-1,"") | H22: =IFERROR(F22/F10-1,"") -> -1
A23: CDU | B23: P1 | C23: 2024 | D23: 7 | E23: Jul 24 | F23: =SUMIFS(Data!$K:$K,Data!$A:$A,2024,Data!$B:$B,7,Data!$G:$G,"CDU",Data!$F:$F,"PADD 1") -> 11.25 | G23: =IFERROR(F23/F22-1,"") | H23: =IFERROR(F23/F11-1,"") -> -0.87199909
A24: CDU | B24: P1 | C24: 2024 | D24: 8 | E24: Aug 24 | F24: =SUMIFS(Data!$K:$K,Data!$A:$A,2024,Data!$B:$B,8,Data!$G:$G,"CDU",Data!$F:$F,"PADD 1") -> 0 | G24: =IFERROR(F24/F23-1,"") -> -1 | H24: =IFERROR(F24/F12-1,"")
A25: CDU | B25: P1 | C25: 2024 | D25: 9 | E25: Sep 24 | F25: =SUMIFS(Data!$K:$K,Data!$A:$A,2024,Data!$B:$B,9,Data!$G:$G,"CDU",Data!$F:$F,"PADD 1") -> 0 | G25: =IFERROR(F25/F24-1,"") | H25: =IFERROR(F25/F13-1,"") -> -1
A26: CDU | B26: P1 | C26: 2024 | D26: 10 | E26: Oct 24 | F26: =SUMIFS(Data!$K:$K,Data!$A:$A,2024,Data!$B:$B,10,Data!$G:$G,"CDU",Data!$F:$F,"PADD 1") -> 73.08 | G26: =IFERROR(F26/F25-1,"") | H26: =IFERROR(F26/F14-1,"") -> -0.60497297
A27: CDU | B27: P1 | C27: 2024 | D27: 11 | E27: Nov 24 | F27: =SUMIFS(Data!$K:$K,Data!$A:$A,2024,Data!$B:$B,11,Data!$G:$G,"CDU",Data!$F:$F,"PADD 1") -> 116.9 | G27: =IFERROR(F27/F26-1,"") -> 0.59961686 | H27: =IFERROR(F27/F15-1,"") -> 1.1063063
A28: CDU | B28: P1 | C28: 2024 | D28: 12 | E28: Dec 24 | F28: =SUMIFS(Data!$K:$K,Data!$A:$A,2024,Data!$B:$B,12,Data!$G:$G,"CDU",Data!$F:$F,"PADD 1") -> 159.85 | G28: =IFERROR(F28/F27-1,"") -> 0.36740804 | H28: =IFERROR(F28/F16-1,"") -> 5.1837524
A29: CDU | B29: P1 | C29: 2025 | D29: 1 | E29: Jan 25 | F29: =SUMIFS(Data!$K:$K,Data!$A:$A,2025,Data!$B:$B,1,Data!$G:$G,"CDU",Data!$F:$F,"PADD 1") -> 170.12 | G29: =IFERROR(F29/F28-1,"") -> 0.064247732 | H29: =IFERROR(F29/F17-1,"") -> 3.3003033
A30: CDU | B30: P1 | C30: 2025 | D30: 2 | E30: Feb 25 | F30: =SUMIFS(Data!$K:$K,Data!$A:$A,2025,Data!$B:$B,2,Data!$G:$G,"CDU",Data!$F:$F,"PADD 1") -> 306.59 | G30: =IFERROR(F30/F29-1,"") -> 0.80219845 | H30: =IFERROR(F30/F18-1,"")
A31: CDU | B31: P1 | C31: 2025 | D31: 3 | E31: Mar 25 | F31: =SUMIFS(Data!$K:$K,Data!$A:$A,2025,Data!$B:$B,3,Data!$G:$G,"CDU",Data!$F:$F,"PADD 1") -> 426.19 | G31: =IFERROR(F31/F30-1,"") -> 0.39009752 | H31: =IFERROR(F31/F19-1,"") -> 6.0386457
A32: CDU | B32: P1 | C32: 2025 | D32: 4 | E32: Apr 25 | F32: =SUMIFS(Data!$K:$K,Data!$A:$A,2025,Data!$B:$B,4,Data!$G:$G,"CDU",Data!$F:$F,"PADD 1") -> 128.3961 | G32: =IFERROR(F32/F31-1,"") -> -0.69873507 | H32: =IFERROR(F32/F20-1,"") -> 1.6875165
A33: CDU | B33: P1 | C33: 2025 | D33: 5 | E33: May 25 | F33: =SUMIFS(Data!$K:$K,Data!$A:$A,2025,Data!$B:$B,5,Data!$G:$G,"CDU",Data!$F:$F,"PADD 1") -> 87.63 | G33: =IFERROR(F33/F32-1,"") -> -0.31750263 | H33: =IFERROR(F33/F21-1,"")
A34: CDU | B34: P1 | C34: 2025 | D34: 6 | E34: Jun 25 | F34: =SUMIFS(Data!$K:$K,Data!$A:$A,2025,Data!$B:$B,6,Data!$G:$G,"CDU",Data!$F:$F,"PADD 1") -> 70.0371 | G34: =IFERROR(F34/F33-1,"") -> -0.20076344 | H34: =IFERROR(F34/F22-1,"")
A35: CDU | B35: P1 | C35: 2025 | D35: 7 | E35: Jul 25 | F35: =SUMIFS(Data!$K:$K,Data!$A:$A,2025,Data!$B:$B,7,Data!$G:$G,"CDU",Data!$F:$F,"PADD 1") -> 78.435 | G35: =IFERROR(F35/F34-1,"") -> 0.11990645 | H35: =IFERROR(F35/F23-1,"") -> 5.972
A36: CDU | B36: P1 | C36: 2025 | D36: 8 | E36: Aug 25 | F36: =SUMIFS(Data!$K:$K,Data!$A:$A,2025,Data!$B:$B,8,Data!$G:$G,"CDU",Data!$F:$F,"PADD 1") -> 0 | G36: =IFERROR(F36/F35-1,"") -> -1 | H36: =IFERROR(F36/F24-1,"")
A37: CDU | B37: P1 | C37: 2025 | D37: 9 | E37: Sep 25 | F37: =SUMIFS(Data!$K:$K,Data!$A:$A,2025,Data!$B:$B,9,Data!$G:$G,"CDU",Data!$F:$F,"PADD 1") -> 0 | G37: =IFERROR(F37/F36-1,"") | H37: =IFERROR(F37/F25-1,"")
A38: CDU | B38: P1 | C38: 2025 | D38: 10 | E38: Oct 25 | F38: =SUMIFS(Data!$K:$K,Data!$A:$A,2025,Data!$B:$B,10,Data!$G:$G,"CDU",Data!$F:$F,"PADD 1") -> 0 | G38: =IFERROR(F38/F37-1,"") | H38: =IFERROR(F38/F26-1,"") -> -1
A39: CDU | B39: P1 | C39: 2025 | D39: 11 | E39: Nov 25 | F39: =SUMIFS(Data!$K:$K,Data!$A:$A,2025,Data!$B:$B,11,Data!$G:$G,"CDU",Data!$F:$F,"PADD 1") -> 0 | G39: =IFERROR(F39/F38-1,"") | H39: =IFERROR(F39/F27-1,"") -> -1
A40: CDU | B40: P1 | C40: 2025 | D40: 12 | E40: Dec 25 | F40: =SUMIFS(Data!$K:$K,Data!$A:$A,2025,Data!$B:$B,12,Data!$G:$G,"CDU",Data!$F:$F,"PADD 1") -> 0 | G40: =IFERROR(F40/F39-1,"") | H40: =IFERROR(F40/F28-1,"") -> -1
A41: CDU | B41: P1 | C41: 2026 | D41: 1 | E41: Jan 26 | F41: =SUMIFS(Data!$K:$K,Data!$A:$A,2026,Data!$B:$B,1,Data!$G:$G,"CDU",Data!$F:$F,"PADD 1") -> 17.6 | G41: =IFERROR(F41/F40-1,"") | H41: =IFERROR(F41/F29-1,"") -> -0.89654362
...

Sheet ExxonMobil
A1: ExxonMobil 2027 Focus-Unit Turnarounds, per Unit (kbd)
A2: Cross-checked against ExxonMobil's corporate turnaround plan.
A4: Refinery | B4: Unit | C4: Class | D4: PADD | E4: kbd | F4: Window | G4: Type | H4: Vs corporate plan
A5: Joliet | B5: Crude | C5: CDU | D5: PADD 2 | E5: 250 | F5: Apr-May | G5: Planned | H5: matches corporate plan
A6: Baytown | B6: FCCU 3 (Fuels East) | C6: FCC | D6: PADD 3 | E6: 125 | F6: Feb-Apr | G6: Planned | H6: matches corporate plan
A7: Beaumont | B7: FCCU | C7: FCC | D7: PADD 3 | E7: 120 | F7: Jan-Feb | G7: Planned | H7: matches corporate plan
A8: Baton Rouge | B8: PSLA 9 (Pipestill) | C8: CDU | D8: PADD 3 | E8: 110 | F8: Sep-Oct | G8: Planned | H8: matches corporate plan
A9: Beaumont | B9: Hydrocracker | C9: Hydrocracker | D9: PADD 3 | E9: 65 | F9: Jan-Feb | G9: Planned | H9: matches corporate plan
A10: Joliet | B10: Reformer CCR | C10: Reformer | D10: PADD 2 | E10: 52 | F10: Apr-May | G10: Planned | H10: matches corporate plan

Sheet HVN
A1: HVN (Heavy Virgin Naphtha) Balance: CDU Supply vs Reformer Demand (kbd) = live model
A2: Reformer-feed naphtha. CDU/reformer offline pulled from Data; supply, demand and net recompute off the gold yield cells below. All PADDs, then PADD 3 (Gulf) only.
A4: Month | B4: CDU offline | C4: HVN supply removed | D4: Reformer offline | E4: HVN demand removed | F4: Net balance
A5: Jan | B5: =SUMIFS(Data!$K:$K,Data!$A:$A,2027,Data!$B:$B,1,Data!$G:$G,"CDU") -> 365.125 | C5: =B5*naph_yield -> 127.79375 | D5: =SUMIFS(Data!$K:$K,Data!$A:$A,2027,Data!$B:$B,1,Data!$G:$G,"Reformer") -> 29.125 | E5: =D5*ref_intake -> 29.125 | F5: =E5-C5 -> -98.66875 | G5: =-C5 -> -127.79375
A6: Feb | B6: =SUMIFS(Data!$K:$K,Data!$A:$A,2027,Data!$B:$B,2,Data!$G:$G,"CDU") -> 683.258 | C6: =B6*naph_yield -> 239.1403 | D6: =SUMIFS(Data!$K:$K,Data!$A:$A,2027,Data!$B:$B,2,Data!$G:$G,"Reformer") -> 68.78 | E6: =D6*ref_intake -> 68.78 | F6: =E6-C6 -> -170.3603 | G6: =-C6 -> -239.1403
A7: Mar | B7: =SUMIFS(Data!$K:$K,Data!$A:$A,2027,Data!$B:$B,3,Data!$G:$G,"CDU") -> 1062.14 | C7: =B7*naph_yield -> 371.749 | D7: =SUMIFS(Data!$K:$K,Data!$A:$A,2027,Data!$B:$B,3,Data!$G:$G,"Reformer") -> 184.889 | E7: =D7*ref_intake -> 184.889 | F7: =E7-C7 -> -186.86 | G7: =-C7 -> -371.749
A8: Apr | B8: =SUMIFS(Data!$K:$K,Data!$A:$A,2027,Data!$B:$B,4,Data!$G:$G,"CDU") -> 663.255 | C8: =B8*naph_yield -> 232.13925 | D8: =SUMIFS(Data!$K:$K,Data!$A:$A,2027,Data!$B:$B,4,Data!$G:$G,"Reformer") -> 141.475 | E8: =D8*ref_intake -> 141.475 | F8: =E8-C8 -> -90.66425 | G8: =-C8 -> -232.13925
A9: May | B9: =SUMIFS(Data!$K:$K,Data!$A:$A,2027,Data!$B:$B,5,Data!$G:$G,"CDU") -> 320.192 | C9: =B9*naph_yield -> 112.0672 | D9: =SUMIFS(Data!$K:$K,Data!$A:$A,2027,Data!$B:$B,5,Data!$G:$G,"Reformer") -> 45.428 | E9: =D9*ref_intake -> 45.428 | F9: =E9-C9 -> -66.6392 | G9: =-C9 -> -112.0672
A10: Jun | B10: =SUMIFS(Data!$K:$K,Data!$A:$A,2027,Data!$B:$B,6,Data!$G:$G,"CDU") -> 96 | C10: =B10*naph_yield -> 33.6 | D10: =SUMIFS(Data!$K:$K,Data!$A:$A,2027,Data!$B:$B,6,Data!$G:$G,"Reformer") -> 0.3 | E10: =D10*ref_intake -> 0.3 | F10: =E10-C10 -> -33.3 | G10: =-C10 -> -33.6
A11: Jul | B11: =SUMIFS(Data!$K:$K,Data!$A:$A,2027,Data!$B:$B,7,Data!$G:$G,"CDU") -> 96 | C11: =B11*naph_yield -> 33.6 | D11: =SUMIFS(Data!$K:$K,Data!$A:$A,2027,Data!$B:$B,7,Data!$G:$G,"Reformer") -> 0 | E11: =D11*ref_intake -> 0 | F11: =E11-C11 -> -33.6 | G11: =-C11 -> -33.6
A12: Aug | B12: =SUMIFS(Data!$K:$K,Data!$A:$A,2027,Data!$B:$B,8,Data!$G:$G,"CDU") -> 27.84 | C12: =B12*naph_yield -> 9.744 | D12: =SUMIFS(Data!$K:$K,Data!$A:$A,2027,Data!$B:$B,8,Data!$G:$G,"Reformer") -> 0 | E12: =D12*ref_intake -> 0 | F12: =E12-C12 -> -9.744 | G12: =-C12 -> -9.744
A13: Sep | B13: =SUMIFS(Data!$K:$K,Data!$A:$A,2027,Data!$B:$B,9,Data!$G:$G,"CDU") -> 976.735 | C13: =B13*naph_yield -> 341.85725 | D13: =SUMIFS(Data!$K:$K,Data!$A:$A,2027,Data!$B:$B,9,Data!$G:$G,"Reformer") -> 112.05 | E13: =D13*ref_intake -> 112.05 | F13: =E13-C13 -> -229.80725 | G13: =-C13 -> -341.85725
A14: Oct | B14: =SUMIFS(Data!$K:$K,Data!$A:$A,2027,Data!$B:$B,10,Data!$G:$G,"CDU") -> 1307.315 | C14: =B14*naph_yield -> 457.56025 | D14: =SUMIFS(Data!$K:$K,Data!$A:$A,2027,Data!$B:$B,10,Data!$G:$G,"Reformer") -> 109.945 | E14: =D14*ref_intake -> 109.945 | F14: =E14-C14 -> -347.61525 | G14: =-C14 -> -457.56025
A15: Nov | B15: =SUMIFS(Data!$K:$K,Data!$A:$A,2027,Data!$B:$B,11,Data!$G:$G,"CDU") -> 283.9 | C15: =B15*naph_yield -> 99.365 | D15: =SUMIFS(Data!$K:$K,Data!$A:$A,2027,Data!$B:$B,11,Data!$G:$G,"Reformer") -> 20.105 | E15: =D15*ref_intake -> 20.105 | F15: =E15-C15 -> -79.26 | G15: =-C15 -> -99.365
A16: Dec | B16: =SUMIFS(Data!$K:$K,Data!$A:$A,2027,Data!$B:$B,12,Data!$G:$G,"CDU") -> 0 | C16: =B16*naph_yield -> 0 | D16: =SUMIFS(Data!$K:$K,Data!$A:$A,2027,Data!$B:$B,12,Data!$G:$G,"Reformer") -> 0 | E16: =D16*ref_intake -> 0 | F16: =E16-C16 -> 0 | G16: =-C16 -> 0
A17: Year | B17: =SUM(B5:B16) -> 5881.76 | C17: =SUM(C5:C16) -> 2058.616 | D17: =SUM(D5:D16) -> 712.097 | E17: =SUM(E5:E16) -> 712.097 | F17: =SUM(F5:F16) -> -1346.519
A19: Net < 0 = deficit (HVN short, bullish reformate); net > 0 = surplus.
A20: 2027 annual net = -1,347 kbd (11 deficit months, 0 surplus).
A22: Live inputs (edit -- supply & demand above recompute)
A23: Naphtha yield (per bbl crude) | D23: 0.35
A24: Reformer naphtha intake (per bbl capacity) | D24: 1
A26: PADD 3 (Gulf) only -- CDU & reformer filtered to PADD 3
A27: Month | B27: CDU offline | C27: HVN supply removed | D27: Reformer offline | E27: HVN demand removed | F27: Net balance
A28: Jan | B28: =SUMIFS(Data!$K:$K,Data!$A:$A,2027,Data!$B:$B,1,Data!$G:$G,"CDU",Data!$F:$F,"PADD 3") -> 210.575 | C28: =B28*naph_yield -> 73.70125 | D28: =SUMIFS(Data!$K:$K,Data!$A:$A,2027,Data!$B:$B,1,Data!$G:$G,"Reformer",Data!$F:$F,"PADD 3") -> 5.8 | E28: =D28*ref_intake -> 5.8 | F28: =E28-C28 -> -67.90125 | G28: =-C28 -> -73.70125
A29: Feb | B29: =SUMIFS(Data!$K:$K,Data!$A:$A,2027,Data!$B:$B,2,Data!$G:$G,"CDU",Data!$F:$F,"PADD 3") -> 355.17 | C29: =B29*naph_yield -> 124.3095 | D29: =SUMIFS(Data!$K:$K,Data!$A:$A,2027,Data!$B:$B,2,Data!$G:$G,"Reformer",Data!$F:$F,"PADD 3") -> 17.36 | E29: =D29*ref_intake -> 17.36 | F29: =E29-C29 -> -106.9495 | G29: =-C29 -> -124.3095
A30: Mar | B30: =SUMIFS(Data!$K:$K,Data!$A:$A,2027,Data!$B:$B,3,Data!$G:$G,"CDU",Data!$F:$F,"PADD 3") -> 468.97 | C30: =B30*naph_yield -> 164.1395 | D30: =SUMIFS(Data!$K:$K,Data!$A:$A,2027,Data!$B:$B,3,Data!$G:$G,"Reformer",Data!$F:$F,"PADD 3") -> 100.37 | E30: =D30*ref_intake -> 100.37 | F30: =E30-C30 -> -63.7695 | G30: =-C30 -> -164.1395
A31: Apr | B31: =SUMIFS(Data!$K:$K,Data!$A:$A,2027,Data!$B:$B,4,Data!$G:$G,"CDU",Data!$F:$F,"PADD 3") -> 178.93 | C31: =B31*naph_yield -> 62.6255 | D31: =SUMIFS(Data!$K:$K,Data!$A:$A,2027,Data!$B:$B,4,Data!$G:$G,"Reformer",Data!$F:$F,"PADD 3") -> 52.91 | E31: =D31*ref_intake -> 52.91 | F31: =E31-C31 -> -9.7155 | G31: =-C31 -> -62.6255
A32: May | B32: =SUMIFS(Data!$K:$K,Data!$A:$A,2027,Data!$B:$B,5,Data!$G:$G,"CDU",Data!$F:$F,"PADD 3") -> 0 | C32: =B32*naph_yield -> 0 | D32: =SUMIFS(Data!$K:$K,Data!$A:$A,2027,Data!$B:$B,5,Data!$G:$G,"Reformer",Data!$F:$F,"PADD 3") -> 0 | E32: =D32*ref_intake -> 0 | F32: =E32-C32 -> 0 | G32: =-C32 -> 0
A33: Jun | B33: =SUMIFS(Data!$K:$K,Data!$A:$A,2027,Data!$B:$B,6,Data!$G:$G,"CDU",Data!$F:$F,"PADD 3") -> 96 | C33: =B33*naph_yield -> 33.6 | D33: =SUMIFS(Data!$K:$K,Data!$A:$A,2027,Data!$B:$B,6,Data!$G:$G,"Reformer",Data!$F:$F,"PADD 3") -> 0 | E33: =D33*ref_intake -> 0 | F33: =E33-C33 -> -33.6 | G33: =-C33 -> -33.6
A34: Jul | B34: =SUMIFS(Data!$K:$K,Data!$A:$A,2027,Data!$B:$B,7,Data!$G:$G,"CDU",Data!$F:$F,"PADD 3") -> 96 | C34: =B34*naph_yield -> 33.6 | D34: =SUMIFS(Data!$K:$K,Data!$A:$A,2027,Data!$B:$B,7,Data!$G:$G,"Reformer",Data!$F:$F,"PADD 3") -> 0 | E34: =D34*ref_intake -> 0 | F34: =E34-C34 -> -33.6 | G34: =-C34 -> -33.6
A35: Aug | B35: =SUMIFS(Data!$K:$K,Data!$A:$A,2027,Data!$B:$B,8,Data!$G:$G,"CDU",Data!$F:$F,"PADD 3") -> 27.84 | C35: =B35*naph_yield -> 9.744 | D35: =SUMIFS(Data!$K:$K,Data!$A:$A,2027,Data!$B:$B,8,Data!$G:$G,"Reformer",Data!$F:$F,"PADD 3") -> 0 | E35: =D35*ref_intake -> 0 | F35: =E35-C35 -> -9.744 | G35: =-C35 -> -9.744
A36: Sep | B36: =SUMIFS(Data!$K:$K,Data!$A:$A,2027,Data!$B:$B,9,Data!$G:$G,"CDU",Data!$F:$F,"PADD 3") -> 583.89 | C36: =B36*naph_yield -> 204.3615 | D36: =SUMIFS(Data!$K:$K,Data!$A:$A,2027,Data!$B:$B,9,Data!$G:$G,"Reformer",Data!$F:$F,"PADD 3") -> 0 | E36: =D36*ref_intake -> 0 | F36: =E36-C36 -> -204.3615 | G36: =-C36 -> -204.3615
A37: Oct | B37: =SUMIFS(Data!$K:$K,Data!$A:$A,2027,Data!$B:$B,10,Data!$G:$G,"CDU",Data!$F:$F,"PADD 3") -> 865.76 | C37: =B37*naph_yield -> 303.016 | D37: =SUMIFS(Data!$K:$K,Data!$A:$A,2027,Data!$B:$B,10,Data!$G:$G,"Reformer",Data!$F:$F,"PADD 3") -> 15.015 | E37: =D37*ref_intake -> 15.015 | F37: =E37-C37 -> -288.001 | G37: =-C37 -> -303.016
A38: Nov | B38: =SUMIFS(Data!$K:$K,Data!$A:$A,2027,Data!$B:$B,11,Data!$G:$G,"CDU",Data!$F:$F,"PADD 3") -> 250.9 | C38: =B38*naph_yield -> 87.815 | D38: =SUMIFS(Data!$K:$K,Data!$A:$A,2027,Data!$B:$B,11,Data!$G:$G,"Reformer",Data!$F:$F,"PADD 3") -> 13.025 | E38: =D38*ref_intake -> 13.025 | F38: =E38-C38 -> -74.79 | G38: =-C38 -> -87.815
A39: Dec | B39: =SUMIFS(Data!$K:$K,Data!$A:$A,2027,Data!$B:$B,12,Data!$G:$G,"CDU",Data!$F:$F,"PADD 3") -> 0 | C39: =B39*naph_yield -> 0 | D39: =SUMIFS(Data!$K:$K,Data!$A:$A,2027,Data!$B:$B,12,Data!$G:$G,"Reformer",Data!$F:$F,"PADD 3") -> 0 | E39: =D39*ref_intake -> 0 | F39: =E39-C39 -> 0 | G39: =-C39 -> 0
A40: Year | B40: =SUM(B28:B39) -> 3134.035 | C40: =SUM(C28:C39) -> 1096.9122 | D40: =SUM(D28:D39) -> 204.48 | E40: =SUM(E28:E39) -> 204.48 | F40: =SUM(F28:F39) -> -892.43225
A42: PADD 3 2027 annual net = -892 kbd (10 deficit months) -- the Gulf share of the HVN deficit.

Sheet Forecast
A1: 2027 Unplanned Scenario (kbd/month) = baseline x multiplier (live)
A2: Headline by month (peak/avg = real levels). Annual Sigma (sum of the 12 monthly concurrent figures) is kept for reference -- a magnitude, not a level; not for slides.
A4: Unplanned scenario (kbd/mo) | B4: Jan | C4: Feb | D4: Mar | E4: Apr | F4: May | G4: Jun | H4: Jul | I4: Aug | J4: Sep | K4: Oct | L4: Nov | M4: Dec | N4: Peak/mo | O4: Avg/mo | P4: Annual Σ
A5: Baseline (2023-2026, completeness-aware) | B5: 1946.2278 | C5: 2880.2243 | D5: 2118.639 | E5: 2253.8666 | F5: 1411.2534 | G5: 1333.7552 | H5: 1173.2245 | I5: 1212.6027 | J5: 1621.1806 | K5: 2132.5508 | L5: 1240.6596 | M5: 806.31737 | N5: =MAX(B5:M5) -> 2880.2243 | O5: =AVERAGE(B5:M5) -> 1677.5418 | P5: =SUM(B5:M5) -> 20130.502
A6: Conservative | B6: =B5*mult_cons -> 1556.9823 | C6: =C5*mult_cons -> 2304.1795 | D6: =D5*mult_cons -> 1694.9112 | E6: =E5*mult_cons -> 1803.0933 | F6: =F5*mult_cons -> 1129.0027 | G6: =G5*mult_cons -> 1067.0042 | H6: =H5*mult_cons -> 938.57962 | I6: =I5*mult_cons -> 970.08216 | ... M6: =M5*mult_cons -> 645.05389 | N6: =MAX(B6:M6) -> 2304.1795 | O6: =AVERAGE(B6:M6) -> 1342.0335 | P6: =SUM(B6:M6) -> 16104.402
A7: Average | B7: =B5*mult_avg -> 1946.2278 | C7: =C5*mult_avg -> 2880.2243 | D7: =D5*mult_avg -> 2118.639 | E7: =E5*mult_avg -> 2253.8666 | F7: =F5*mult_avg -> 1411.2534 | G7: =G5*mult_avg -> 1333.7552 | H7: =H5*mult_avg -> 1173.2245 | I7: =I5*mult_avg -> 1212.6027 | ... M7: =M5*mult_avg -> 806.31737 | N7: =MAX(B7:M7) -> 2880.2243 | O7: =AVERAGE(B7:M7) -> 1677.5418 | P7: =SUM(B7:M7) -> 20130.502
A8: Active | B8: =B5*mult_act -> 2530.0962 | C8: =C5*mult_act -> 3744.2917 | D8: =D5*mult_act -> 2754.2306 | E8: =E5*mult_act -> 2930.0266 | F8: =F5*mult_act -> 1834.6294 | G8: =G5*mult_act -> 1733.8818 | H8: =H5*mult_act -> 1525.1919 | I8: =I5*mult_act -> 1576.3835 | ... M8: =M5*mult_act -> 1048.2126 | N8: =MAX(B8:M8) -> 3744.2917 | O8: =AVERAGE(B8:M8) -> 2180.8044 | P8: =SUM(B8:M8) -> 26169.653
