Workbook

Sheet P2 - 2026 delet
Q2: P2 2025 Planned Offline Mogas Production (KBD)
B3: Sum of Capacity Offline for Area Chart (KBD) | C3: Column Labels | R3: Column Labels
B4: Row Labels | C4: Jan | D4: Feb | E4: Mar | F4: Apr | G4: May | H4: Jun | I4: Sep | J4: Oct | K4: Nov | L4: Dec | M4: Grand Total | Q4: Row Labels | R4: Jan | S4: Feb | T4: Mar | U4: Apr | V4: May | W4: Jun | X4: Jul | Y4: Aug | Z4: Sep | AA4: Oct | AB4: Nov | AC4: Dec | AD4: 1Q25 Total | AE4: Aug-Nov Avg
B5: Chalmette Refining LLC | C5: 220.76 | D5: 77.745714 | L5: 24.768571 | M5: 323.27429
B6: Chalmette Refinery | C6: 220.76 | D6: 77.745714 | L6: 24.768571 | M6: 323.27429
B7: Chevron Corporation | F7: 43.2 | G7: 86.4 | H7: 43.2 | M7: 172.8
B8: Pasadena Refinery | F8: 43.2 | G8: 86.4 | H8: 43.2 | M8: 172.8
B9: CITGO Petroleum Corporation | C9: 19.942857 | D9: 267.2 | E9: 392.14 | F9: 97.8 | I9: 180.51429 | J9: 187.2 | K9: 33.428571 | M9: 1178.2257
B10: Corpus Christi Refinery - West (CITGO) | E10: 83.785714 | F10: 69.214286 | M10: 153
B11: Corpus Christi Refinery-East | E11: 194.38286 | F11: 28.585714 | M11: 222.96857
B12: Lake Charles Refinery (CITGO) | C12: 19.942857 | D12: 267.2 | E12: 113.97143 | I12: 180.51429 | J12: 187.2 | K12: 33.428571 | M12: 802.25714
B13: Deer Park Refining LP | I13: 27.867857 | J13: 156.06 | K13: 11.147143 | M13: 195.075
B14: Deer Park Refinery | I14: 27.867857 | J14: 156.06 | K14: 11.147143 | M14: 195.075
B15: Delek US Holdings | J15: 115.32857 | K15: 76.885714 | M15: 192.21429
B16: Krotz Springs Refinery | J16: 115.32857 | K16: 76.885714 | M16: 192.21429
B17: ExxonMobil Corporation | C17: 433.67857 | D17: 413.73571 | L17: 18.228571 | M17: 865.64286
B18: Baton Rouge Refinery | C18: 255.2 | D18: 45.571429 | L18: 18.228571 | M18: 319
B19: Baytown Refinery | C19: 159.19286 | D19: 117.66429 | M19: 276.85714
B20: Beaumont Refinery | C20: 19.285714 | D20: 250.5 | M20: 269.78571
B21: Flint Hills Resources LLC | C21: 155.81429 | D21: 155.81429 | I21: 91.142857 | J21: 68.357143 | M21: 471.12857 | AF21: Padd 2
B22: Corpus Christi Refinery - East | I22: 91.142857 | J22: 68.357143 | M22: 159.5 | AG22: 2024 | AH22: 2025 | AI22: 2026
B23: Corpus Christi Refinery - West (Flint Hills) | C23: 155.81429 | D23: 155.81429 | M23: 311.62857 | AF23: Jan | AH23: 8.6370968
B24: Marathon Petroleum Corporation | C24: 160.82857 | D24: 49.485714 | M24: 210.31429 | Q24: 2026 | W24: 97.516889 | X24: 84.983871 | Y24: 119.15488 | Z24: 231.42722 | AA24: 165.62493 | AB24: 76.768333 | AC24: 30 | AF24: Feb | AG24: 13.6 | AH24: 36.455357 | AI24: 40.346429
B25: Texas City Refinery (Bay Plant) | C25: 160.82857 | D25: 49.485714 | M25: 210.31429 | Q25: 2025 | W25: 36.5 | X25: 131.6 | Y25: 97 | Z25: 203 | AA25: 280.8 | AB25: 132 | AC25: 2 | AF25: Mar | AG25: 134.09944 | AH25: 280.16213 | AI25: 89.583065
B26: Phillips 66 | D26: 9 | E26: 157.5 | F26: 22.5 | I26: 76.56 | J26: 107.184 | K26: 45.936 | M26: 418.68 | AF26: Apr | AG26: 343.47233 | AH26: 383.5415 | AI26: 82.446667
B27: Lake Charles Refinery (Phillips 66) | I27: 76.56 | J27: 107.184 | K27: 45.936 | M27: 229.68 | AF27: May | AG27: 148.09726 | AH27: 110.88065 | AI27: 12.084677
B28: Sweeny Refinery | D28: 9 | E28: 157.5 | F28: 22.5 | M28: 189 | AF28: Jun | AH28: 45.25
B29: Valero Refining Company | C29: 374.16 | D29: 319.51714 | E29: 51.04 | I29: 19.794286 | J29: 277.12 | K29: 98.971429 | L29: 26.725714 | M29: 1167.3286 | AF29: Jul | AG29: 3.9166667 | AH29: 36.193548
B30: McKee Refinery | I30: 19.794286 | J30: 277.12 | K30: 98.971429 | M30: 395.88571 | AF30: Aug | AG30: 0 | AH30: 42.25
B31: Port Arthur Refinery (Valero) | C31: 170 | D31: 115.35714 | L31: 12.142857 | M31: 297.5 | AF31: Sep | AG31: 212.34333 | AH31: 205.09833 | AI31: 53.958333
B32: Texas City Refinery | C32: 204.16 | D32: 204.16 | E32: 51.04 | L32: 14.582857 | M32: 473.94286 | AF32: Oct | AG32: 347.76452 | AH32: 110.39919 | AI32: 64.75
B33: Vertex Energy | I33: 3.2785714 | J33: 45.9 | K33: 8.1964286 | M33: 57.375 | R33: 347.18258 | S33: 441.12196 | T33: 724.38673 | U33: 672.1815 | V33: 233.31655 | W33: 75.509167 | X33: 52.535484 | Y33: 44.824194 | Z33: 490.20733 | AA33: 605.17758 | AB33: 201.02667 | AC33: 96.526129 | AF33: Nov | AG33: 43.561667 | AH33: 10.768333
B34: Mobile Refinery (Vertex) | I34: 3.2785714 | J34: 45.9 | K34: 8.1964286 | M34: 57.375 | Q34: Mobile Refinery (Vertex) | X34: 0 | Y34: 0
O35: ‘25, 24, '22 & '23 Planned & Unplanned | Q35: 2026 Plan + Unplanned | W35: =W42+W51 -> -3.4104444 | X35: =X42+X51 -> 84.983871 | Y35: =Y42+Y51 -> 101.91133 | Z35: =Z42+Z51 -> 216.295 | AA35: =AA42+AA51 -> 128.79186 | AB35: =AB42+AB51 -> 76.768333 | AC35: =AC42+AC51 -> 30 | AE35: =AVERAGE(W35:AC35) -> 90.76285
Q36: 2025 Outages | X36: 131.6 | Y36: 97 | Z36: 203 | AA36: 280.8 | AB36: 132 | AC36: 2 | AE36: =AVERAGE(W36:AC36) -> 141.06667
Q37: vs 2026 | R37: =(R$35-R36)/R36 -> #DIV/0! | S37: =(S$35-S36)/S36 -> #DIV/0! | T37: =(T$35-T36)/T36 -> #DIV/0! | U37: =(U$35-U36)/U36 -> #DIV/0! | V37: =(V$35-V36)/V36 -> #DIV/0! | W37: =(W$35-W36)/W36 -> #DIV/0! | X37: =(X$35-X36)/X36 -> -0.3542259 | Y37: =(Y$35-Y36)/Y36 -> 0.050632229 | ... AC37: =(AC$35-AC36)/AC36 -> 14 | AE37: =(AE$35-AE36)/AE36 -> -0.35659606
Q38: 2024 Outages | X38: 36.5 | Y38: 131.6 | Z38: 97 | AA38: 203 | AB38: 280.8 | AC38: 132 | AD38: 2 | AE38: =AVERAGE(W38:AC38) -> 146.81667
Q39: vs 2026 | R39: =(R35-R38)/R38 -> #DIV/0! | S39: =(S35-S38)/S38 -> #DIV/0! | T39: =(T35-T38)/T38 -> #DIV/0! | U39: =(U35-U38)/U38 -> #DIV/0! | V39: =(V35-V38)/V38 -> #DIV/0! | W39: =(W$35-W38)/W38 -> #DIV/0! | X39: =(X35-X38)/X38 -> 1.3283252 | Y39: =(Y35-Y38)/Y38 -> -0.22559783 | Z39: =(Z35-Z38)/Z38 -> 1.2298454 | AA39: =(AA35-AA38)/AA38 -> -0.36555733 | AB39: =(AB35-AB38)/AB38 -> -0.7266085 | AC39: =(AC35-AC38)/AC38 -> -0.77272727 | AD39: =(#REF!-AD38)/AD38 -> #REF! | AE39: =(AE35-AE38)/AE38 -> -0.38179464
B40: 2026 | Q40: 2023 Outages | R40: 290.55307 | S40: 234.397 | T40: 282.96883 | U40: 366 | V40: 207.17533 | W40: 86.418667 | X40: 74.094 | Y40: 22.667667 | Z40: 242.75643 | AA40: 308.8098 | AB40: 71.48 | AC40: 15 | AD40: =AVERAGE(R40:AC40) -> 183.52673 | AE40: =AVERAGE(W40:AC40) -> 117.31808
B41: Sum of Gasoline Production Offline (KBD) | C41: Column Labels | Q41: vs 2026 | R41: =(R35-R40)/R40 -> -1 | S41: =(S35-S40)/S40 -> -1 | T41: =(T35-T40)/T40 -> -1 | U41: =(U35-U40)/U40 -> -1 | V41: =(V35-V40)/V40 -> -1 | W41: =(W35-W40)/W40 -> -1.0394642 | X41: =(X35-X40)/X40 -> 0.14697372 | Y41: =(Y35-Y40)/Y40 -> 3.4958896 | ... AC41: =(AC35-AC40)/AC40 -> 1 | AD41: =(#REF!-AD40)/AD40 -> #REF! | AE41: =(AE35-AE40)/AE40 -> -0.22635242
...

Sheet P1 - 2026
B2: 46023 | C2: 46054 | D2: 46082 | E2: 46113 | F2: 46143 | G2: 46174 | H2: 46204 | I2: 46235 | J2: 46266 | K2: 46296 | L2: 46327 | M2: 46357
A3: 2026 Enhanced Golden Record | B3: =IFERROR(VLOOKUP(B2,'[1]PADD 1 Query'!$G:$M,7,FALSE),"") -> 8.853 | C3: =IFERROR(VLOOKUP(C2,'[1]PADD 1 Query'!$G:$M,7,FALSE),"") -> 2.1175 | D3: =IFERROR(VLOOKUP(D2,'[1]PADD 1 Query'!$G:$M,7,FALSE),"") -> 7.4293 | E3: =IFERROR(VLOOKUP(E2,'[1]PADD 1 Query'!$G:$M,7,FALSE),"") -> 1.87 | F3: =IFERROR(VLOOKUP(F2,'[1]PADD 1 Query'!$G:$M,7,FALSE),"") -> 5.395 | G3: =IFERROR(VLOOKUP(G2,'[1]PADD 1 Query'!$G:$M,7,FALSE),"") -> 37.726 | H3: =IFERROR(VLOOKUP(H2,'[1]PADD 1 Query'!$G:$M,7,FALSE),"") -> 0.5984 | I3: =IFERROR(VLOOKUP(I2,'[1]PADD 1 Query'!$G:$M,7,FALSE),"") | ... K3: =IFERROR(VLOOKUP(K2,'[1]PADD 1 Query'!$G:$M,7,FALSE),"") -> 13.09 | L3: =IFERROR(VLOOKUP(L2,'[1]PADD 1 Query'!$G:$M,7,FALSE),0) -> 0 | M3: =IFERROR(VLOOKUP(M2,'[1]PADD 1 Query'!$G:$M,7,FALSE),"")
A4: 46192 | B4: 8.853 | C4: 2.1175 | D4: 7.4293 | E4: 1.87 | F4: 5.395 | G4: 0.6171 | J4: 9.0475 | K4: 13.09 | L4: 0
A5: 2026 Offline Outage file | B5: 0 | C5: 0 | E5: 0 | K5: 7.975 | L5: 27.5 | M5: 12.375
A6: m/m | C6: =B3-C3 -> 6.7355 | D6: =C3-D3 -> -5.3118 | E6: =D3-E3 -> 5.5593 | F6: =E3-F3 -> -3.525 | G6: =F3-G3 -> -32.331 | H6: =G3-H3 -> 37.1276 | I6: =H3-I3 -> #VALUE! | J6: =I3-J3 -> #VALUE! | ... L6: =K3-L3 -> 13.09
A7: changes vs previous | B7: =B4-B3 -> 0 | C7: =C4-C3 -> 0 | D7: =D4-D3 -> 0 | E7: =E4-E3 -> 0 | F7: =F4-F3 -> 0 | G7: =G4-G3 -> -37.1089 | H7: =H4-H3 -> #VALUE! | I7: =I4-I3 -> #VALUE! | ... M7: =M4-M3 -> #VALUE!

Sheet P2 - 2026 
M2: 2025 Offline Mogas Production (KBD)
B3: Sum of Capacity Offline for Area Chart (KBD) | C3: Column Labels | N3: Column Labels
M4: Row Labels | N4: Jan | O4: Feb | P4: Mar | Q4: Apr | R4: May | S4: Jun | T4: Jul | U4: Aug | V4: Sep | W4: Oct | X4: Nov | Y4: Dec | Z4: Total | AA4: 1H26 Avg | AB4: 2H25 Avg
AF15: jan | AG15: feb | AH15: mar | AI15: apr | AJ15: may | AK15: jun | AL15: jul
AE16: 2025 | AF16: -47.430484 | AG16: -99.6125 | AH16: -210.36194 | AI16: -371.07308 | AJ16: -244.73323 | AK16: -45.521333 | AL16: -38.177742
AF17: =-1*AF16 -> 47.430484 | AG17: =-1*AG16 -> 99.6125 | AH17: =-1*AH16 -> 210.36194 | AI17: =-1*AI16 -> 371.07308 | AJ17: =-1*AJ16 -> 244.73323 | AK17: =-1*AK16 -> 45.521333 | AL17: =-1*AL16 -> 38.177742
AE18: 2024 | AF18: -4.483871 | AG18: -280.5819 | AH18: -110.81613 | AI18: -276.655 | AJ18: -126.35806
AF19: =-1*AF18 -> 4.483871 | AG19: =-1*AG18 -> 280.5819 | AH19: =-1*AH18 -> 110.81613 | AI19: =-1*AI18 -> 276.655 | AJ19: =-1*AJ18 -> 126.35806
N25: 46388 | O25: 46419 | P25: 46447 | Q25: 46478 | R25: 46508 | S25: 46539 | T25: 46569 | U25: 46600 | V25: 46631 | W25: 46661 | X25: 46692 | Y25: 46722
M26: 2027 Planned outages | N26: =IFERROR(VLOOKUP(N25,'[1]PADD 2 Planned'!$G:$M,7,FALSE),0) -> 0 | O26: =IFERROR(VLOOKUP(O25,'[1]PADD 2 Planned'!$G:$M,7,FALSE),0) -> 41.276 | P26: =IFERROR(VLOOKUP(P25,'[1]PADD 2 Planned'!$G:$M,7,FALSE),0) -> 88.6255 | Q26: =IFERROR(VLOOKUP(Q25,'[1]PADD 2 Planned'!$G:$M,7,FALSE),0) -> 160.57175 | R26: =IFERROR(VLOOKUP(R25,'[1]PADD 2 Planned'!$G:$M,7,FALSE),0) -> 106.838 | S26: =IFERROR(VLOOKUP(S25,'[1]PADD 2 Planned'!$G:$M,7,FALSE),0) -> 0 | T26: =IFERROR(VLOOKUP(T25,'[1]PADD 2 Planned'!$G:$M,7,FALSE),0) -> 0 | U26: =IFERROR(VLOOKUP(U25,'[1]PADD 2 Planned'!$G:$M,7,FALSE),0) -> 0 | ... Y26: =IFERROR(VLOOKUP(Y25,'[1]PADD 2 Planned'!$G:$M,7,FALSE),0) -> 0
N28: 46023 | O28: 46054 | P28: 46082 | Q28: 46113 | R28: 46143 | S28: 46174 | T28: 46204 | U28: 46235 | V28: 46266 | W28: 46296 | X28: 46327 | Y28: 46357
M29: 2026 Enhanced Golden Record | N29: =IFERROR(VLOOKUP(N28,'[1]PADD 2 Query'!$G:$M,7,FALSE),0) -> 29.842975 | O29: =IFERROR(VLOOKUP(O28,'[1]PADD 2 Query'!$G:$M,7,FALSE),0) -> 148.15513 | P29: =IFERROR(VLOOKUP(P28,'[1]PADD 2 Query'!$G:$M,7,FALSE),0) -> 205.01355 | Q29: =IFERROR(VLOOKUP(Q28,'[1]PADD 2 Query'!$G:$M,7,FALSE),0) -> 234.55925 | R29: =IFERROR(VLOOKUP(R28,'[1]PADD 2 Query'!$G:$M,7,FALSE),0) -> 213.5886 | S29: =IFERROR(VLOOKUP(S28,'[1]PADD 2 Query'!$G:$M,7,FALSE),0) -> 57.72025 | T29: =IFERROR(VLOOKUP(T28,'[1]PADD 2 Query'!$G:$M,7,FALSE),0) -> 1.225 | U29: =IFERROR(VLOOKUP(U28,'[1]PADD 2 Query'!$G:$M,7,FALSE),0) -> 0 | ... Y29: =IFERROR(VLOOKUP(Y28,'[1]PADD 2 Query'!$G:$M,7,FALSE),0) -> 0 | AG29: Padd 2 | AK29: Sum of [Selected_Measure_Yield] | AL29: Column Labels
N30: =N35-N29 -> -0.442975 | O30: =O35-O29 -> -1.764 | P30: =P35-P29 -> -3.885 | Q30: =Q35-Q29 -> -2.71575 | R30: =R35-R29 -> 0 | S30: =S35-S29 -> -5.5973611 | T30: =T42-T29 -> -1.225 | U30: =U42-U29 -> 0 | V30: =V42-V29 -> 5.159 | W30: =W42-W29 -> 1.209 | X30: =X42-X29 -> -10.475 | Y30: =Y42-Y29 -> 0 | AH30: 2024 | AI30: 2025 | AJ30: 2026 | AL30: 2023 | AM30: 2024 | AN30: 2025 | AO30: 2026
M31: Planned | N31: =IFERROR(VLOOKUP(N28,'[1]PADD 2 Planned'!$G:$M,7,FALSE),0) -> 0 | O31: =IFERROR(VLOOKUP(O28,'[1]PADD 2 Planned'!$G:$M,7,FALSE),0) -> 32.673 | P31: =IFERROR(VLOOKUP(P28,'[1]PADD 2 Planned'!$G:$M,7,FALSE),0) -> 182.54075 | Q31: =IFERROR(VLOOKUP(Q28,'[1]PADD 2 Planned'!$G:$M,7,FALSE),0) -> 178.009 | R31: =IFERROR(VLOOKUP(R28,'[1]PADD 2 Planned'!$G:$M,7,FALSE),0) -> 74.821 | S31: =IFERROR(VLOOKUP(S28,'[1]PADD 2 Planned'!$G:$M,7,FALSE),0) -> 0 | T31: =IFERROR(VLOOKUP(T28,'[1]PADD 2 Planned'!$G:$M,7,FALSE),0) -> 0 | U31: =IFERROR(VLOOKUP(U28,'[1]PADD 2 Planned'!$G:$M,7,FALSE),0) -> 0 | ... Y31: =IFERROR(VLOOKUP(Y28,'[1]PADD 2 Planned'!$G:$M,7,FALSE),0) -> 0 | AG31: Jan | AI31: 8.6370968 | AK31: Row Labels
N32: =N29-N31 -> 29.842975 | O32: =O29-O31 -> 115.48213 | P32: =P29-P31 -> 22.4728 | Y32: =Y35-X35 -> -116.58 | AG32: Feb | AH32: 13.6 | AI32: 36.455357 | AJ32: 146.72143 | AK32: Jan | AL32: 187.67 | AM32: 90 | AN32: 29.506323 | AO32: 0
M33: Padd 2 2026 Offline Mogas Production (KBD) | AG33: Mar | AH33: 134.09944 | AI33: 280.16213 | AJ33: 155.92823 | AK33: Feb | AL33: 194.47893 | AM33: 103.36621 | AN33: 64.859 | AO33: 137.81786 | AP33: =AO33-X30 -> 148.29286
N34: Jan | O34: Feb | P34: Mar | Q34: Apr | R34: May | S34: Jun | T34: Jul | U34: Aug | V34: Sep | W34: Oct | X34: Nov | Y34: Dec | AA34: 1H26 Avg | AG34: Apr | AH34: 343.47233 | AI34: 383.5415 | AJ34: 148.97167 | AK34: Mar | AL34: 225.18339 | AM34: 163.40016 | AN34: 190.22871 | AO34: 84.803226 | AP34: =AO34-X31 -> -8.5467742
K35: 26 ‘25, 24, & '23 Planned & Unplanned | M35: 2026 Plan + Unplanned | N35: 29.4 | O35: 146.39112 | P35: 201.12855 | Q35: 231.8435 | R35: 213.5886 | S35: =S42+S54 -> 52.122889 | T35: =T42+T54 -> 52.99966 | U35: =U42+U54 -> 54.230731 | V35: =V42+V54 -> 166.90892 | W35: =W42+W54 -> 233.32115 | X35: =X42+X54 -> 132.48 | Y35: =Y42+Y54 -> 15.9 | Z35: =Z42+Z50 -> 83.594842 | AA35: =AVERAGE(N35:S35) -> 145.74578 | AB35: =AVERAGE(N35:S35) -> 145.74578 | AD35: =AB35-AB36 -> -23.916094 | AG35: May | AH35: 148.09726 | AI35: 110.88065 | AJ35: 23.029839 | AK35: Apr | AL35: 276.396 | AM35: 226.50133 | AN35: 351.62783 | AO35: 56.081667 | AP35: =AO35-X32 -> 56.081667
M36: 2025 Outages | N36: 47.430484 | O36: 99.6125 | P36: 210.36194 | Q36: 371.07308 | R36: 244.73323 | S36: 44.76 | T36: 59.687 | U36: 79.65 | V36: 159.2175 | W36: 313.0997 | X36: 83.47 | Y36: 15.9 | Z36: =AVERAGE(N36:Y36) -> 144.08295 | AA36: =AVERAGE(N36:S36) -> 169.66187 | AB36: =AVERAGE(N36:S36) -> 169.66187 | AG36: Jun | AI36: 45.25 | AK36: May | AL36: 137.33742 | AM36: 113.01387 | AN36: 161.14806 | AO36: 11.453226 | AP36: =AO36-X33 -> 11.453226
B37: El Dorado Refinery (HF Sinclair) | M37: vs 2026 | N37: =(N$35-N36)/N36 -> -0.38014548 | O37: =(O$35-O36)/O36 -> 0.46960597 | P37: =(P$35-P36)/P36 -> -0.043892853 | Q37: =(Q$35-Q36)/Q36 -> -0.37520798 | R37: =(R$35-R36)/R36 -> -0.12725949 | S37: =(S$35-S36)/S36 -> 0.16449707 | T37: =(T$35-T36)/T36 -> -0.11204014 | U37: =(U$35-U36)/U36 -> -0.31913708 | ... Y37: =(Y$35-Y36)/Y36 -> 0 | Z37: =AVERAGE(N37:Y37) -> -0.028576474 | AA37: =AVERAGE(N37:S37) -> -0.048733793 | AB37: =(AB35-AB36)/AB36 -> -0.14096328 | AG37: Jul | AH37: 3.9166667 | AI37: 36.193548 | AK37: Jun | AL37: 90 | AM37: 45.804667 | AN37: 55.68 | AP37: =AO37-X34 -> #VALUE!
B38: Lemont Refinery | M38: 2024 Outages | N38: 90 | O38: 280.5819 | P38: 163 | Q38: 276.655 | R38: 126.35806 | S38: 45 | T38: 131.6 | U38: 97 | V38: 203 | W38: 280.8 | X38: 132 | Y38: 2 | Z38: =AVERAGE(N38:Y38) -> 152.33291 | AA38: =AVERAGE(N38:S38) -> 163.59916 | AB38: =AVERAGE(N38:S38) -> 163.59916 | AG38: Aug | AH38: 0 | AI38: 42.25 | AK38: Jul | AL38: 100.67871 | AM38: 35.771742 | AN38: 33.370968 | AP38: =AO38-X35 -> -132.48
B39: Ponca City Refinery | M39: vs 2026 | N39: =(N35-N38)/N38 -> -0.67333333 | O39: =(O35-O38)/O38 -> -0.47825884 | P39: =(P35-P38)/P38 -> 0.23391748 | Q39: =(Q35-Q38)/Q38 -> -0.16197611 | R39: =(R35-R38)/R38 -> 0.69034403 | S39: =(S35-S38)/S38 -> 0.15828642 | T39: =(T35-T38)/T38 -> -0.59726702 | U39: =(U35-U38)/U38 -> -0.4409203 | ... Y39: =(Y35-Y38)/Y38 -> 6.95 | Z39: =AVERAGE(N39:Y39) -> 0.44479633 | AA39: =AVERAGE(N39:S39) -> -0.038503391 | AB39: =(AB35-AB38)/AB38 -> -0.10912882 | AG39: Sep | AH39: 212.34333 | AI39: 177.59833 | AJ39: 10.791667 | AK39: Aug | AL39: 91.419355 | AM39: 8.7345161 | AN39: 41.38
B40: Robinson Refinery | M40: 2023 Outages | N40: 290.55307 | O40: 234.397 | P40: 282.96883 | Q40: 366 | R40: 207.17533 | S40: 86.418667 | T40: 74.094 | U40: 22.667667 | V40: 242.75643 | W40: 308.8098 | X40: 71.48 | Y40: 15 | Z40: =AVERAGE(N40:Y40) -> 183.52673 | AA40: =AVERAGE(N40:S40) -> 244.58548 | AB40: =AVERAGE(S40:Y40) -> 117.31808 | AG40: Oct | AH40: 347.76452 | AI40: 105.96371 | AJ40: 64.75 | AK40: Sep | AL40: 323.94977 | AM40: 164.105 | AN40: 199.916 | AO40: 53.958333
B41: Toledo Refinery (PBF) | M41: vs 2026 | N41: =(N35-N40)/N40 -> -0.89881366 | O41: =(O35-O40)/O40 -> -0.37545649 | P41: =(P35-P40)/P40 -> -0.28922013 | Q41: =(Q35-Q40)/Q40 -> -0.36654781 | R41: =(R35-R40)/R40 -> 0.030955744 | S41: =(S35-S40)/S40 -> -0.39685613 | T41: =(T35-T40)/T40 -> -0.284697 | U41: =(U35-U40)/U40 -> 1.3924267 | ... Y41: =(Y35-Y40)/Y40 -> 0.06 | Z41: =AVERAGE(N41:Y41) -> -0.069309699 | AA41: =AVERAGE(N41:S41) -> -0.38265641 | AB41: =(AB35-AB40)/AB40 -> 0.242313 | AG41: Nov | AH41: 43.561667 | AI41: 4.2933333 | AJ41: 6.475 | AK41: Oct | AL41: 406.71465 | AM41: 234.14435 | AN41: 131.22097 | AO41: 64.75
K42: 26 ‘25, 24, & '23 Planned ONLY | M42: 2026 Plan | N42: 0 | O42: 53.057 | P42: 194.77225 | Q42: 178.609 | R42: 54.3045 | S42: 0 | T42: 0 | U42: 0 | V42: 145.55325 | W42: 177.76815 | X42: 82.875 | Y42: 0 | Z42: =(N42*(31/90))+(O42*(28/90))+(P42*(31/90)) -> 83.594842 | AA42: =AVERAGE(N42:S42) -> 80.123792 | AB42: =AVERAGE(S42:Y42) -> 58.028057 | AD42: =AB42-AB43 -> -5.3086172 | AG42: Grand Total | AH42: 1246.8552 | AI42: 1231.2257 | AJ42: 556.66783 | AK42: Nov | AL42: 135.98667 | AM42: 62.874167
M43: 2025 Outages | N43: 8.6370968 | O43: 18.35 | P43: 202.00806 | Q43: 278.099 | R43: 122.17258 | S43: 19.7 | T43: 36.193548 | U43: 42.566667 | V43: 127.375 | W43: 184.60484 | X43: 32.916667 | Y43: 0 | Z43: =(N43*(31/90))+(O43*(28/90))+(P43*(31/90)) -> 78.264444 | AA43: =AVERAGE(N43:S43) -> 108.16112 | AB43: =AVERAGE(S43:Y43) -> 63.336674 | AK43: Dec | AL43: 90
M44: vs 2026 | N44: =(N42-N43)/N43 -> -1 | O44: =(O42-O43)/O43 -> 1.8913896 | P44: =(P42-P43)/P43 -> -0.035819434 | Q44: =(Q42-Q43)/Q43 -> -0.3577503 | R44: =(R42-R43)/R43 -> -0.55550992 | S44: =(S42-S43)/S43 -> -1 | T44: =(T$42-T43)/T43 -> -1 | U44: =(U$42-U43)/U43 -> -1 | V44: =(V$42-V43)/V43 -> 0.14271443 | W44: =(W$42-W43)/W43 -> -0.037034179 | X44: =(X$42-X43)/X43 -> 1.5177215 | Y44: =(Y$42-Y43)/Y43 -> #DIV/0! | Z44: =(Z42-Z43)/Z43 -> 0.06810752 | AA44: =AVERAGE(N44:S44) -> -0.17628167 | AB44: =(AB42-AB43)/AB43 -> -0.08381585 | AK44: Grand Total | AL44: 2259.8149 | AM44: 1247.716 | AN44: 1258.9379 | AO44: 290.15598
M45: 2024 Outages | N45: 1e-05 | O45: 13.6 | P45: 135.14944 | Q45: 343.64733 | R45: 148.09726 | S45: 0.01 | T45: 4.0733333 | U45: 6.9193548 | V45: 199.59333 | W45: 280.56452 | X45: 44.496667 | Y45: 0.01 | Z45: =(N45*(31/90))+(O45*(28/90))+(P45*(31/90)) -> 50.782589 | AA45: =AVERAGE(N45:S45) -> 106.75067 | AB45: =AVERAGE(S45:Y45) -> 76.523886
M46: vs 2026 | N46: =(N42-N45)/N45 -> -1 | O46: =(O42-O45)/O45 -> 2.90125 | P46: =(P42-P45)/P45 -> 0.44116209 | Q46: =(Q42-Q45)/Q45 -> -0.48025495 | R46: =(R42-R45)/R45 -> -0.63331867 | S46: =(S42-S45)/S45 -> -1 | T46: =(T42-T45)/T45 -> -1 | U46: =(U42-U45)/U45 -> -1 | ... Z46: =(Z42-Z45)/Z45 -> 0.64613195 | AA46: =AVERAGE(N46:S46) -> 0.038139744 | AB46: =(AB42-AB45)/AB45 -> -0.24170008
M47: 2023 Outages | N47: 100.92567 | O47: 91.353667 | P47: 131.6945 | Q47: 199.056 | R47: 55.635333 | S47: 0.1 | T47: 12.474667 | U47: 0 | V47: 224.61643 | W47: 270.88113 | X47: 31.586667 | Y47: 0.01 | Z47: =(N47*(31/90))+(O47*(28/90))+(P47*(31/90)) -> 108.54586 | AA47: =AVERAGE(N47:S47) -> 96.460861 | AB47: =AVERAGE(S47:Y47) -> 77.095557
M48: vs 2026 | N48: =(N42-N47)/N47 -> -1 | O48: =(O42-O47)/O47 -> -0.41921324 | P48: =(P42-P47)/P47 -> 0.47897027 | Q48: =(Q42-Q47)/Q47 -> -0.10271984 | R48: =(R42-R47)/R47 -> -0.02392065 | S48: =(S42-S47)/S47 -> -1 | T48: =(T42-T47)/T47 -> -1 | U48: =(U42-U47)/U47 -> #DIV/0! | ... Z48: =(Z42-Z47)/Z47 -> -0.22986618 | AA48: =AVERAGE(N48:S48) -> -0.34448058 | AB48: =(AB42-AB47)/AB47 -> -0.24732294
M50: 2025 Unplanned Outages | N50: =N36-N43 -> 38.793387 | O50: =O36-O43 -> 81.2625 | P50: =P36-P43 -> 8.353871 | Q50: =Q36-Q43 -> 92.974083 | R50: =R36-R43 -> 122.56065 | S50: =S36-S43 -> 25.06 | T50: =T36-T43 -> 23.493452 | U50: =U36-U43 -> 37.083333 | ... Y50: =Y36-Y43 -> 15.9 | AA50: =AVERAGE(N50:S50) -> 61.500748 | AB50: =AVERAGE(S50:Y50) -> 44.632497 | AG50: Jan | AH50: Feb | AI50: Mar | AJ50: Apr | AK50: May | AL50: Jun | AM50: Jul | AN50: Aug | AO50: Sep | AP50: Oct | AQ50: Nov | AR50: Dec
M51: 2024 Unplanned Outages | N51: =N38-N45 -> 89.99999 | O51: =O38-O45 -> 266.9819 | P51: =P38-P45 -> 27.850559 | Q51: =Q38-Q45 -> -66.992333 | R51: =R38-R45 -> -21.739194 | S51: =S38-S45 -> 44.99 | T51: =T38-T45 -> 127.52667 | U51: =U38-U45 -> 90.080645 | ... Y51: =Y38-Y45 -> 1.99 | Z51: =Z36-Z43 -> 65.818508 | AA51: =AVERAGE(N51:S51) -> 56.848486 | AB51: =AVERAGE(N51:Y51) -> 54.319476 | AF51: 1 | AJ51: 32.3
M52: 2023 Unplanned Outages | N52: =N40-N47 -> 189.6274 | O52: =O40-O47 -> 143.04333 | P52: =P40-P47 -> 151.27433 | Q52: =Q40-Q47 -> 166.944 | R52: =R40-R47 -> 151.54 | S52: =S40-S47 -> 86.318667 | T52: =T40-T47 -> 61.619333 | U52: =U40-U47 -> 22.667667 | ... Y52: =Y40-Y47 -> 14.99 | Z52: =AVERAGE(N52:Y52) -> 90.332228 | AA52: =AVERAGE(N52:S52) -> 148.12462 | AB52: =AVERAGE(S52:Y52) -> 40.222524 | AF52: 2 | AH52: 146.72143 | AI52: 155.92823 | AJ52: 148.97167 | AK52: 23.029839 | AO52: 10.791667 | AP52: 64.75 | AQ52: 6.475
N53: =AVERAGE(N50:N52) -> 106.14026 | O53: =AVERAGE(O50:O52) -> 163.76258 | P53: =AVERAGE(P50:P52) -> 62.492921 | Q53: =AVERAGE(Q50:Q52) -> 64.308583 | R53: =AVERAGE(R50:R52) -> 84.120484 | S53: =AVERAGE(S50:S52) -> 52.122889 | T53: =AVERAGE(T50:T52) -> 70.879817 | U53: =AVERAGE(U50:U52) -> 49.943882 | ... Y53: =AVERAGE(Y50:Y52) -> 10.96 | Z53: =AVERAGE(N53:Y53) -> 66.449789 | AB53: =AVERAGE(S53:Y53) -> 45.224664 | AF53: 3 | AG53: 246.11532 | AH53: 386.82679 | AI53: 206.43468 | AJ53: 38.385833 | AK53: 9.9395161 | AL53: 2.75 | AM53: 0.91935484 | AN53: 1.1
N54: =N35-N42 -> 29.4 | O54: =O35-O42 -> 93.334125 | P54: =P35-P42 -> 6.3563 | Q54: =Q35-Q42 -> 53.2345 | R54: =R35-R42 -> 159.2841 | S54: =S53 -> 52.122889 | T54: =AVERAGE(T52:T53)*0.8 -> 52.99966 | U54: =AVERAGE(U51:U53) -> 54.230731 | V54: =V53*1.2 -> 21.355667 | W54: =W53 -> 55.553004 | X54: =AVERAGE(X52:X53) -> 49.605 | Y54: =Y50 -> 15.9 | AF54: 4 | AH54: 18.75 | AI54: 75.589839 | AJ54: 64.991027 | AK54: 3.0141935 | AP54: 6.8870968 | AQ54: 15.25 | AR54: 2.9516129
AF55: 5 | AG55: 25.909677 | AH55: 8.3725 | AI55: 11.34 | AJ55: 118.53933 | AK55: 129.53409 | AL55: 117.55667 | AM55: 103.05 | AN55: 103.05 | AO55: 103.05 | AP55: 103.05 | AQ55: 103.05 | AR55: 103.05
M56: 22-23 avg | N56: 110.61187 | O56: 86.7945 | P56: 86.918667 | Q56: 98.4875 | R56: 88.493 | S56: 60
N57: =N56*0.8 -> 88.489493 | O57: =O56*1 -> 86.7945 | P57: =P56*0.8 -> 69.534933 | Q57: =Q56*0.8 -> 78.79 | R57: =R56*0.8 -> 70.7944 | S57: =S56*0.8 -> 48 | AG57: 272.025 | AH57: 560.67071 | AI57: 449.29274 | AJ57: 403.18786 | AK57: 165.51763 | AL57: 120.30667 | AM57: 103.96935 | AN57: 104.15 | AO57: 113.84167 | AP57: 174.6871 | AQ57: 124.775 | AR57: 106.00161
Q59: confirm ho wmuch need to change in apr
...

Sheet P3 - 2026
M2: 2025 Offline Mogas Production (KBD)
B3: Sum of Capacity Offline for Area Chart (KBD) | C3: Column Labels | N3: Column Labels
M4: Row Labels | N4: Jan | O4: Feb | P4: Mar | Q4: Apr | R4: May | S4: Jun | T4: Jul | U4: Aug | V4: Sep | W4: Oct | X4: Nov | Y4: Dec | Z4: 1Q25 Total | AA4: 1H26 Avg | AB4: 2H25 Avg
C6: 46199 | D6: =C6+7 -> 46206 | E6: =D6+7 -> 46213
C7: =120 -> 120 | D7: 120
C8: =C7*7 -> 840 | D8: =D7*7 -> 840
AF15: jan | AG15: feb | AH15: mar | AI15: apr | AJ15: may | AK15: jun
AE16: 20205 | AF16: -487.36074 | AG16: -537.594 | AH16: -386.37598 | AI16: -335.22733 | AJ16: -215.98352 | AK16: -229.89186
AF17: =-1*AF16 -> 487.36074 | AG17: =-1*AG16 -> 537.594 | AH17: =-1*AH16 -> 386.37598 | AI17: =-1*AI16 -> 335.22733 | AJ17: =-1*AJ16 -> 215.98352 | AK17: =-1*AK16 -> 229.89186
AE18: 2024 | AF18: -409.61 | AG18: -453.78805 | AH18: -496.328 | AI18: -262.86707 | AJ18: -189.15242
AF19: =-1*AF18 -> 409.61 | AG19: =-1*AG18 -> 453.78805 | AH19: =-1*AH18 -> 496.328 | AI19: =-1*AI18 -> 262.86707 | AJ19: =-1*AJ18 -> 189.15242
S21: =245*0.1+80*0.65+40*0.85+60*0.1 -> 116.5
S22: =(30-19)/30*120 -> 44 | T22: =(3)/31*120 -> 11.612903
P23: *find the 40&20kbd more offline I have in our offline tool vs outages
M24: 2027 planned and unplanned outages
M25: 2027 Planned Outages withLyondell | N25: =N27+128 -> 346.56788 | O25: =O27+128 -> 467.34663 | P25: =P27+128 -> 529.54 | Q25: =Q27+128 -> 284.27375 | R25: =R27+128 -> 139.28 | S25: =S27+128 -> 189.84 | T25: =T27+128 -> 189 | U25: =U27+128 -> 145.69 | ... Y25: =Y27+128 -> 128
N26: 46388 | O26: 46419 | P26: 46447 | Q26: 46478 | R26: 46508 | S26: 46539 | T26: 46569 | U26: 46600 | V26: 46631 | W26: 46661 | X26: 46692 | Y26: 46722
M27: 2027 plan | N27: =IFERROR(VLOOKUP(N26,'[1]PADD 3 Planned'!$G:$M,7,FALSE),0) -> 218.56788 | O27: =IFERROR(VLOOKUP(O26,'[1]PADD 3 Planned'!$G:$M,7,FALSE),0) -> 339.34663 | P27: =IFERROR(VLOOKUP(P26,'[1]PADD 3 Planned'!$G:$M,7,FALSE),0) -> 401.54 | Q27: =IFERROR(VLOOKUP(Q26,'[1]PADD 3 Planned'!$G:$M,7,FALSE),0) -> 156.27375 | R27: =IFERROR(VLOOKUP(R26,'[1]PADD 3 Planned'!$G:$M,7,FALSE),0) -> 11.28 | S27: =IFERROR(VLOOKUP(S26,'[1]PADD 3 Planned'!$G:$M,7,FALSE),0) -> 61.84 | T27: =IFERROR(VLOOKUP(T26,'[1]PADD 3 Planned'!$G:$M,7,FALSE),0) -> 61 | U27: =IFERROR(VLOOKUP(U26,'[1]PADD 3 Planned'!$G:$M,7,FALSE),0) -> 17.69 | ... Y27: =IFERROR(VLOOKUP(Y26,'[1]PADD 3 Planned'!$G:$M,7,FALSE),0) -> 0
N28: 46023 | O28: 46054 | P28: 46082 | Q28: 46113 | R28: 46143 | S28: 46174 | T28: 46204 | U28: 46235 | V28: 46266 | W28: 46296 | X28: 46327 | Y28: 46357
M29: 2026 Enhanced Golden Record | N29: =IFERROR(VLOOKUP(N28,'[1]PADD 3 Query'!$G:$M,7,FALSE),0) -> 249.794 | O29: =IFERROR(VLOOKUP(O28,'[1]PADD 3 Query'!$G:$M,7,FALSE),0) -> 502.16497 | P29: =IFERROR(VLOOKUP(P28,'[1]PADD 3 Query'!$G:$M,7,FALSE),0) -> 241.85297 | Q29: =IFERROR(VLOOKUP(Q28,'[1]PADD 3 Query'!$G:$M,7,FALSE),0) -> 299.61255 | R29: =IFERROR(VLOOKUP(R28,'[1]PADD 3 Query'!$G:$M,7,FALSE),0) -> 192.98688 | S29: =IFERROR(VLOOKUP(S28,'[1]PADD 3 Query'!$G:$M,7,FALSE),0) -> 106.75225 | T29: =IFERROR(VLOOKUP(T28,'[1]PADD 3 Query'!$G:$M,7,FALSE),0) -> 25.3611 | U29: =IFERROR(VLOOKUP(U28,'[1]PADD 3 Query'!$G:$M,7,FALSE),0) -> 13.1595 | ... Y29: =IFERROR(VLOOKUP(Y28,'[1]PADD 3 Query'!$G:$M,7,FALSE),0) -> 0 | AG29: Sum of Gasoline Production Offline (KBD) | AH29: Column Labels
M30: 2026 Enhanced Golden Record (w. Lyondell) | N30: =N29+N63 -> 377.794 | O30: =O29+O63 -> 630.16497 | P30: =P29+P63 -> 369.85298 | Q30: =Q29+Q63 -> 427.61255 | R30: =R29+R63 -> 320.98688 | S30: =S29+S63 -> 234.75225 | T30: =T29+T63 -> 153.3611 | U30: =U29+U63 -> 141.1595 | ... Y30: =Y29+Y63 -> 128 | AG30: Row Labels | AH30: 2024 | AI30: 2025 | AJ30: 2026 | AK30: Grand Total
N31: =N36-N30 -> 19.1595 | O31: =O36-O30 -> 3.835025 | P31: =P36-P30 -> -9.4005 | Q31: =Q36-Q30 -> -20 | R31: =R36-R30 -> -15.99575 | S31: =S36-S30 -> -11.903139 | T31: =T43-T30 -> -24.296584 | U31: =U43-U30 -> -11.465952 | V31: =V43-V30 -> -20.53125 | W31: =W43-W30 -> -23.4129 | X31: =X43-X30 -> -9.2705 | Y31: =Y43-Y30 -> 0
M32: 2026 planned | N32: =IFERROR(VLOOKUP(N28,'[1]PADD 3 Planned'!$G:$M,7,FALSE),0) -> 185.6145 | O32: =IFERROR(VLOOKUP(O28,'[1]PADD 3 Planned'!$G:$M,7,FALSE),0) -> 329.68285 | P32: =IFERROR(VLOOKUP(P28,'[1]PADD 3 Planned'!$G:$M,7,FALSE),0) -> 117.21297 | Q32: =IFERROR(VLOOKUP(Q28,'[1]PADD 3 Planned'!$G:$M,7,FALSE),0) -> 44.49875 | R32: =IFERROR(VLOOKUP(R28,'[1]PADD 3 Planned'!$G:$M,7,FALSE),0) -> 40.3005 | S32: =IFERROR(VLOOKUP(S28,'[1]PADD 3 Planned'!$G:$M,7,FALSE),0) -> 7.62125 | T32: =IFERROR(VLOOKUP(T28,'[1]PADD 3 Planned'!$G:$M,7,FALSE),0) -> 17.7211 | U32: =IFERROR(VLOOKUP(U28,'[1]PADD 3 Planned'!$G:$M,7,FALSE),0) -> 13.1595 | ... Y32: =IFERROR(VLOOKUP(Y28,'[1]PADD 3 Planned'!$G:$M,7,FALSE),0) -> 0 | AG32: Jan | AH32: 343.11774 | AI32: 288.69032 | AJ32: 246.11532 | AK32: 877.92339
N33: =N36-N37 -> -95.407242 | O33: =O36-O37 -> 31.906 | P33: =P36-P37 -> -153.92351 | Q33: =Q36-Q37 -> -55.614783 | R33: =R36-R37 -> -38.992391 | S33: =S36-S37 -> 0.84911111 | T33: =T36-T37 -> -21.394882 | U33: =U36-U37 -> -79.634386 | ... Y33: =Y36-Y37 -> 48.268889 | AG33: Feb | AH33: 604.0628 | AI33: 293.54107 | AJ33: 386.82679 | AK33: 1284.4307
N34: =Y37-N36 -> -258.9535 | O34: =N36-O36 -> -237.0465 | P34: =O36-P36 -> 273.54753 | Q34: =P36-Q36 -> -47.160075 | R34: =Q36-R36 -> 102.62142 | S34: =R36-S36 -> 82.142014 | T34: =S36-T36 -> -8.7560072 | U34: =T36-U36 -> 3.1205047 | V34: =U36-V36 -> -82.950231 | ... Y34: =X36-Y36 -> 68.756861 | AG34: Mar | AH34: 235.24526 | AI34: 222.98024 | AJ34: 206.43468 | AK34: 664.66018
N35: Jan | O35: Feb | P35: Mar | Q35: Apr | R35: May | S35: Jun | T35: Jul | U35: Aug | V35: Sep | W35: Oct | X35: Nov | Y35: Dec | AG35: Apr | AH35: 78.808333 | AI35: 147.22667 | AJ35: 38.385833 | AK35: 264.42083
K36: 26 ‘25, 24, & '23 Planned & Unplanned | M36: 2026 Plan + Unplanned | N36: 396.9535 | O36: 634 | P36: 360.45247 | Q36: 407.61255 | R36: 304.99113 | S36: =S43+S55 -> 222.84911 | T36: =T43+T55 -> 231.60512 | U36: =U43+U55 -> 228.48461 | V36: =V43+V55 -> 311.43484 | W36: =W43+W55 -> 382.06055 | X36: =X43+X55 -> 255.02575 | Y36: =Y43+Y55 -> 186.26889 | Z36: =Z43+Z51 -> 381.29678 | AA36: =AVERAGE(N36:S36) -> 387.80979 | AB36: =AVERAGE(S36:Y36) -> 259.67555 | AC36: =AVERAGE(N36:R36) -> 420.80193 | AD36: =AC36-AC37 -> -62.406384 | AG36: May | AH36: 22.755 | AI36: 34.555903 | AJ36: 9.9395161 | AK36: 67.250419
M37: 2025 Outages | N37: =N44+N69 -> 492.36074 | O37: =O44+O69 -> 602.094 | P37: =P44+P69 -> 514.37598 | Q37: =Q44+Q69 -> 463.22733 | R37: =R44+R69 -> 343.98352 | S37: 222 | T37: 253 | U37: 308.119 | V37: 401.186 | W37: 763.5 | X37: 420.93 | Y37: 138 | AA37: =AVERAGE(N37:S37) -> 439.6736 | AB37: =AVERAGE(S37:Y37) -> 358.105 | AC37: =AVERAGE(N37:R37) -> 483.20831 | AG37: Jun | AH37: 59.156667 | AI37: 17.933333 | AJ37: 2.75 | AK37: 79.84
M38: vs 2026 | N38: =(N$36-N37)/N37 -> -0.19377508 | O38: =(O$36-O37)/O37 -> 0.052991726 | P38: =(P$36-P37)/P37 -> -0.29924318 | Q38: =(Q$36-Q37)/Q37 -> -0.12005937 | R38: =(R$36-R37)/R37 -> -0.11335541 | S38: =(S$36-S37)/S37 -> 0.0038248248 | T38: =(T$36-T37)/T37 -> -0.08456475 | U38: =(U$36-U37)/U37 -> -0.25845335 | ... Y38: =(Y$36-Y37)/Y37 -> 0.34977456 | AA38: =AVERAGE(N38:S38) -> -0.11160275 | AB38: =(AB36-AB37)/AB37 -> -0.27486197 | AG38: Jul | AH38: 56.459677 | AI38: 1.8580645 | AJ38: 0.91935484 | AK38: 59.237097
M39: 2024 Outages | N39: 409.61 | O39: 453.78805 | P39: 496.328 | Q39: 262.86707 | R39: 189.15242 | S39: 157 | T39: 229 | U39: 200 | V39: 319 | W39: 349 | X39: 267.4 | Y39: 12 | Z39: =AVERAGE(N39:Y39) -> 278.76213 | AA39: =AVERAGE(N39:S39) -> 328.12426 | AB39: =AVERAGE(S39:Y39) -> 219.05714 | AG39: Aug | AH39: 107.7579 | AJ39: 1.1 | AK39: 108.8579
M40: vs 2026 | N40: =(N36-N39)/N39 -> -0.030898904 | O40: =(O36-O39)/O39 -> 0.39712801 | P40: =(P36-P39)/P39 -> -0.27376155 | Q40: =(Q36-Q39)/Q39 -> 0.55064138 | R40: =(R36-R39)/R39 -> 0.61240933 | S40: =(S$36-S39)/S39 -> 0.41942109 | T40: =(T36-T39)/T39 -> 0.011376062 | U40: =(U36-U39)/U39 -> 0.14242307 | V40: =(V36-V39)/V39 -> -0.023715221 | W40: =(W36-W39)/W39 -> 0.09472938 | X40: =(X36-X39)/X39 -> -0.046276178 | Y40: =(Y36-Y39)/Y39 -> 14.522407 | Z40: =(#REF!-Z39)/Z39 -> #REF! | AA40: =AVERAGE(N40:S40) -> 0.27915656 | AB40: =(AB36-AB39)/AB39 -> 0.18542382 | AG40: Sep | AH40: 178.73 | AI40: 195.60533 | AK40: 374.33533
M41: 2023 Outages | N41: 453.4398 | O41: 503.9216 | P41: 462.3153 | Q41: 311.645 | R41: 238.36467 | S41: 246.243 | T41: 142.38567 | U41: 272.15967 | V41: 347.09167 | W41: 570.43267 | X41: 254.687 | Y41: 57.101667 | Z41: =AVERAGE(N41:Y41) -> 321.64898 | AA41: =AVERAGE(N41:S41) -> 369.32156 | AB41: =AVERAGE(S41:Y41) -> 270.01448 | AG41: Oct | AH41: 290.5279 | AI41: 321.95806 | AK41: 612.48597
M42: vs 2026 | N42: =(N36-N41)/N41 -> -0.12457288 | O42: =(O36-O41)/O41 -> 0.25813222 | P42: =(P36-P41)/P41 -> -0.22033194 | Q42: =(Q36-Q41)/Q41 -> 0.30793868 | R42: =(R36-R41)/R41 -> 0.27951483 | S42: =(S36-S41)/S41 -> -0.095003265 | T42: =(T36-T41)/T41 -> 0.62660416 | U42: =(U36-U41)/U41 -> -0.16047585 | ... Y42: =(Y36-Y41)/Y41 -> 2.262057 | Z42: =(#REF!-Z41)/Z41 -> #REF! | AA42: =AVERAGE(N42:S42) -> 0.067612941 | AB42: =(AB36-AB41)/AB41 -> -0.03829025 | AG42: Nov | AH42: 76.9545 | AI42: 40.338333 | AK42: 117.29283
K43: 26 ‘25, 24, & '23 Planned ONLY | M43: 2026 Plan | N43: =N64 -> 328.24145 | O43: =O64 -> 558.51607 | P43: =P64 -> 274.28306 | Q43: =Q64 -> 207 | R43: =R64 -> 193 | S43: =S64 -> 133 | T43: =T64 -> 129.06452 | U43: =U64 -> 129.69355 | V43: 200 | W43: 253 | X43: =X64 -> 155.47075 | Y43: =Y64 -> 128 | Z43: =(N43*(31/90))+(O43*(28/90))+(P43*(31/90)) -> 381.29678 | AA43: =AVERAGE(N43:S43) -> 282.3401 | AB43: =AVERAGE(S43:Y43) -> 161.17554 | AD43: =AB43-AB44 -> -67.660455 | AG43: Grand Total | AH43: 2053.5758 | AI43: 1564.6873 | AJ43: 892.47149 | AK43: 4510.7346
M44: 2025 Outages | N44: =246.335483870968+5 -> 251.33548 | O44: =268.776785714286+64.5 -> 333.27679 | P44: =126.851612903226+128 -> 254.85161 | Q44: =173.528333333+128 -> 301.52833 | R44: =56.6138064516129+128 -> 184.61381 | S44: 145.93333 | T44: 129.85806 | U44: 187.66237 | V44: 324.902 | W44: 437.5629 | X44: 247.93333 | Y44: 128 | Z44: =(N44*(31/90))+(O44*(28/90))+(P44*(31/90)) -> 278.03944 | AA44: =AVERAGE(N44:S44) -> 245.25656 | AB44: =AVERAGE(S44:Y44) -> 228.836
M45: vs 2026 | N45: =(N43-N44)/N44 -> 0.3059893 | O45: =(O43-O44)/O44 -> 0.67583251 | P45: =(P43-P44)/P44 -> 0.076246139 | Q45: =(Q43-Q44)/Q44 -> -0.31349735 | R45: =(R43-R44)/R44 -> 0.045425603 | S45: =(S$43-S44)/S44 -> -0.088624943 | T45: =(T$43-T44)/T44 -> -0.0061108903 | U45: =(U$43-U44)/U44 -> -0.30889953 | V45: =(V$43-V44)/V44 -> -0.38442977 | W45: =(W$43-W44)/W44 -> -0.42179742 | X45: =(X$43-X44)/X44 -> -0.37293325 | Y45: =(Y$43-Y44)/Y44 -> 0 | Z45: =(Z43-Z44)/Z44 -> 0.37137656 | AA45: =AVERAGE(N45:S45) -> 0.11689521 | AB45: =(AB43-AB44)/AB44 -> -0.29567225
M46: 2024 Outages | N46: 347.97645 | O46: 495 | P46: 237.86139 | Q46: 80.508333 | R46: 22.800161 | S46: 59.756667 | T46: 52.009677 | U46: 102.17081 | V46: 158.99667 | W46: 284.10855 | X46: 76.5545 | Y46: 0 | Z46: =(N46*(31/90))+(O46*(28/90))+(P46*(31/90)) -> 355.78859 | AA46: =AVERAGE(N46:S46) -> 207.31717 | AB46: =AVERAGE(S46:Y46) -> 104.79955 | AG46: bi
M47: vs 2026 | N47: =(N43-N46)/N46 -> -0.056713608 | O47: =(O43-O46)/O46 -> 0.1283153 | P47: =(P43-P46)/P46 -> 0.15312142 | Q47: =(Q43-Q46)/Q46 -> 1.5711624 | R47: =(R43-R46)/R46 -> 7.4648524 | S47: =(S$43-S46)/S46 -> 1.2256931 | T47: =(T43-T46)/T46 -> 1.4815481 | U47: =(U43-U46)/U46 -> 0.26937971 | V47: =(V43-V46)/V46 -> 0.25788801 | W47: =(W43-W46)/W46 -> -0.10949529 | X47: =(X43-X46)/X46 -> 1.0308506 | Y47: =(Y43-Y46)/Y46 -> #DIV/0! | Z47: =(Z43-Z46)/Z46 -> 0.071694789 | AA47: =AVERAGE(N47:S47) -> 1.7477385 | AB47: =(AB43-AB46)/AB46 -> 0.53794116 | AG47: Sum of [Selected_Measure_Yield] | AH47: Column Labels
M48: 2023 Outages | N48: 238.07847 | O48: 467.7776 | P48: 370.22563 | Q48: 218.85433 | R48: 116.55783 | S48: 63.005667 | T48: 1.7406667 | U48: 63.729 | V48: 165.49833 | W48: 445.019 | X48: 196.645 | Y48: 29.198333 | Z48: =(N48*(31/90))+(O48*(28/90))+(P48*(31/90)) -> 355.05778 | AA48: =AVERAGE(N48:S48) -> 245.74992 | AB48: =AVERAGE(S48:Y48) -> 137.83371 | AH48: 2023 | AI48: 2024 | AJ48: 2025 | AK48: 2026
M49: vs 2026 | N49: =(N43-N48)/N48 -> 0.37871121 | O49: =(O43-O48)/O48 -> 0.1939778 | P49: =(P43-P48)/P48 -> -0.25914621 | Q49: =(Q43-Q48)/Q48 -> -0.054165404 | R49: =(R43-R48)/R48 -> 0.65583037 | S49: =(S43-S48)/S48 -> 1.1109212 | T49: =(T43-T48)/T48 -> 73.146601 | U49: =(U43-U48)/U48 -> 1.035079 | ... Z49: =(Z43-Z48)/Z48 -> 0.073900652 | AA49: =AVERAGE(N49:S49) -> 0.33768817 | AB49: =(AB43-AB48)/AB48 -> 0.16934776 | AG49: Row Labels
...

Sheet P4 - 2026
B2: 46023 | C2: 46054 | D2: 46082 | E2: 46113 | F2: 46143 | G2: 46174 | H2: 46204 | I2: 46235 | J2: 46266 | K2: 46296 | L2: 46327 | M2: 46357
A3: 2026 Enhanced Golden Record | B3: =IFERROR(VLOOKUP(B2,'[1]PADD 4 Query'!$G:$M,7,FALSE),"") | C3: =IFERROR(VLOOKUP(C2,'[1]PADD 4 Query'!$G:$M,7,FALSE),"") -> 7.358625 | D3: =IFERROR(VLOOKUP(D2,'[1]PADD 4 Query'!$G:$M,7,FALSE),"") -> 26.81515 | E3: =IFERROR(VLOOKUP(E2,'[1]PADD 4 Query'!$G:$M,7,FALSE),"") -> 65.6752 | F3: =IFERROR(VLOOKUP(F2,'[1]PADD 4 Query'!$G:$M,7,FALSE),"") -> 31.8876 | G3: =IFERROR(VLOOKUP(G2,'[1]PADD 4 Query'!$G:$M,7,FALSE),"") -> 2.925 | H3: =IFERROR(VLOOKUP(H2,'[1]PADD 4 Query'!$G:$M,7,FALSE),"") | I3: =IFERROR(VLOOKUP(I2,'[1]PADD 4 Query'!$G:$M,7,FALSE),"") | ... M3: =IFERROR(VLOOKUP(M2,'[1]PADD 4 Query'!$G:$M,7,FALSE),"")
A4: 46192 | C4: 7.358625 | D4: 26.81515 | E4: 65.6752 | F4: 31.8876 | G4: 2.925 | K4: 3.353625
A5: 2026 Offline Outage file | C5: 18.75 | D5: 54.928548 | E5: 50.530833 | F5: 3.0141935 | K5: 8.1025613 | L5: 2.6101
A6: delta between outage dashboard and manual process | C6: =C5-C3 -> 11.391375 | D6: =D5-D3 -> 28.113398 | E6: =E5-E3 -> -15.144367 | F6: =F5-F3 -> -28.873406 | K6: =K5-K3 -> 4.7489363 | L6: =L5-L3 -> #VALUE!
A7: delta between outage dashboard and previous dashboard | C7: =C4-C3 -> 0 | D7: =D4-D3 -> 0 | E7: =E4-E3 -> 0 | F7: =F4-F3 -> 0 | G7: =G4-G3 -> 0 | H7: =H4-H3 -> #VALUE! | I7: =I4-I3 -> #VALUE! | J7: =J4-J3 -> #VALUE! | ... M7: =M4-M3 -> #VALUE!
D8: =C3-D3 -> -19.456525 | E8: =D3-E3 -> -38.86005 | F8: =E3-F3 -> 33.7876

Sheet P5 - 2026
Q2: P5 2025 Planned Offline Mogas Production (KBD)
R5: 46388 | S5: 46419 | T5: 46447 | U5: 46478 | V5: 46508 | W5: 46539 | X5: 46569 | Y5: 46600 | Z5: 46631 | AA5: 46661 | AB5: 46692 | AC5: 46722
Q6: 2027 Planned | R6: =IFERROR(VLOOKUP(R5,'[1]PADD 5 Planned'!$G:$M,7,FALSE),0) -> 62.325 | S6: =IFERROR(VLOOKUP(S5,'[1]PADD 5 Planned'!$G:$M,7,FALSE),0) -> 74.5459 | T6: =IFERROR(VLOOKUP(T5,'[1]PADD 5 Planned'!$G:$M,7,FALSE),0) -> 32.1112 | U6: =IFERROR(VLOOKUP(U5,'[1]PADD 5 Planned'!$G:$M,7,FALSE),0) -> 0.805875 | V6: =IFERROR(VLOOKUP(V5,'[1]PADD 5 Planned'!$G:$M,7,FALSE),0) -> 8.372 | W6: =IFERROR(VLOOKUP(W5,'[1]PADD 5 Planned'!$G:$M,7,FALSE),0) -> 0 | X6: =IFERROR(VLOOKUP(X5,'[1]PADD 5 Planned'!$G:$M,7,FALSE),0) -> 0 | Y6: =IFERROR(VLOOKUP(Y5,'[1]PADD 5 Planned'!$G:$M,7,FALSE),0) -> 0 | ... AC6: =IFERROR(VLOOKUP(AC5,'[1]PADD 5 Planned'!$G:$M,7,FALSE),0) -> 0
Q7: 2027 Planned with rationalizations | R7: =R6+103+65+19 -> 249.325 | S7: =S6+103+65+19 -> 261.5459 | T7: =T6+103+65+19 -> 219.1112 | U7: =U6+103+65+19 -> 187.80588 | V7: =V6+103+65+19 -> 195.372 | W7: =W6+103+65+19 -> 187 | X7: =X6+103+65+19 -> 187 | Y7: =Y6+103+65+19 -> 187 | ... AC7: =AC6+103+65+19 -> 187
Q8: 2026 Planned | R8: =IFERROR(VLOOKUP(R9,'[1]PADD 5 Planned'!$G:$M,7,FALSE),0) -> 18.624 | S8: =IFERROR(VLOOKUP(S9,'[1]PADD 5 Planned'!$G:$M,7,FALSE),0) -> 32.3515 | T8: =IFERROR(VLOOKUP(T9,'[1]PADD 5 Planned'!$G:$M,7,FALSE),0) -> 24.8035 | U8: =IFERROR(VLOOKUP(U9,'[1]PADD 5 Planned'!$G:$M,7,FALSE),0) -> 45.91725 | V8: =IFERROR(VLOOKUP(V9,'[1]PADD 5 Planned'!$G:$M,7,FALSE),0) -> 41.4345 | W8: =IFERROR(VLOOKUP(W9,'[1]PADD 5 Planned'!$G:$M,7,FALSE),0) -> 15.34525 | X8: =IFERROR(VLOOKUP(X9,'[1]PADD 5 Planned'!$G:$M,7,FALSE),0) -> 24.78575 | Y8: =IFERROR(VLOOKUP(Y9,'[1]PADD 5 Planned'!$G:$M,7,FALSE),0) -> 3.53275 | ... AC8: =IFERROR(VLOOKUP(AC9,'[1]PADD 5 Planned'!$G:$M,7,FALSE),0) -> 3.12
R9: 46023 | S9: 46054 | T9: 46082 | U9: 46113 | V9: 46143 | W9: 46174 | X9: 46204 | Y9: 46235 | Z9: 46266 | AA9: 46296 | AB9: 46327 | AC9: 46357
Q10: 2026 Enhanced Golden Record | R10: =IFERROR(VLOOKUP(R9,'[1]PADD 5 Query'!$G:$M,7,FALSE),0) -> 90.652 | S10: =IFERROR(VLOOKUP(S9,'[1]PADD 5 Query'!$G:$M,7,FALSE),0) -> 130.5155 | T10: =IFERROR(VLOOKUP(T9,'[1]PADD 5 Query'!$G:$M,7,FALSE),0) -> 90.93975 | U10: =IFERROR(VLOOKUP(U9,'[1]PADD 5 Query'!$G:$M,7,FALSE),0) -> 200.10333 | V10: =IFERROR(VLOOKUP(V9,'[1]PADD 5 Query'!$G:$M,7,FALSE),0) -> 94.5135 | W10: =IFERROR(VLOOKUP(W9,'[1]PADD 5 Query'!$G:$M,7,FALSE),0) -> 20.3925 | X10: =IFERROR(VLOOKUP(X9,'[1]PADD 5 Query'!$G:$M,7,FALSE),0) -> 19.7385 | Y10: =IFERROR(VLOOKUP(Y9,'[1]PADD 5 Query'!$G:$M,7,FALSE),0) -> 3.53275 | ... AC10: =IFERROR(VLOOKUP(AC9,'[1]PADD 5 Query'!$G:$M,7,FALSE),0) -> 3.12 | AH10: jan | AI10: feb | AJ10: mar | AK10: apr | AL10: may | AM10: jun
R11: =R10+R42+R43 -> 174.652 | S11: =S10+S42+S43+S45 -> 281.7155 | T11: =T10+T42+T43+T45 -> 277.93975 | U11: =U10+U42+U43+U45 -> 387.10333 | V11: =V10+V42+V43+V45 -> 281.5135 | W11: =W10+W42+W43+W45 -> 207.3925 | X11: =X10+X42+X43+X45 -> 206.7385 | Y11: =Y10+Y42+Y43+Y45 -> 190.53275 | Z11: =Z10+Z42+Z43+Z45 -> 214.175 | ... AC11: =AC10+AC42+AC43+AC45 -> 190.12
R12: =R15-R11 -> 7.3434875 | S12: =(S15)-S11 -> 4.0963475 | T12: =(T15+14)-T11 -> 16.16125 | U12: =U15-U11 -> 0 | V12: =V15-V11 -> -1.9605 | W12: =W15-W11 -> 21.63125 | X12: =X22-X11 -> 13.844 | Y12: =Y22-Y11 -> -3.53275 | Z12: =Z22-Z11 -> -12.175 | AA12: =AA22-AA11 -> 15.18075 | AB12: =AB22-AB11 -> 12.2247 | AC12: =AC22-AC11 -> 0
S13: =R15-S15 -> -103.81636 | T13: =S15-T15 -> 5.7108475 | U13: =T15-U15 -> -107.00233 | V13: =U15-V15 -> 107.55033 | W13: =V15-W15 -> 50.52925 | X13: =W15-X15 -> -23.75734 | Y13: =X15-Y15 -> 34.138267 | Z13: =Y15-Z15 -> -42.115511 | ... AC13: =AB15-AC15 -> 69.895474 | AH13: -107.51145 | AI13: -160.53304 | AJ13: -206.75565 | AK13: -256.96167 | AL13: -181.41016 | AM13: -102.61367
R14: Jan | S14: Feb | T14: Mar | U14: Apr | V14: May | W14: Jun | X14: Jul | Y14: Aug | Z14: Sep | AA14: Oct | AB14: Nov | AC14: Dec | AD14: Jan | AG14: 2025 | AH14: =AH13*-1 -> 107.51145 | AI14: =AI13*-1 -> 160.53304 | AJ14: =AJ13*-1 -> 206.75565 | AK14: =AK13*-1 -> 256.96167 | AL14: =AL13*-1 -> 181.41016 | AM14: =AM13*-1 -> 102.61367
O15: 26 ‘25, 24, & '23 Planned & Unplanned | Q15: 2026 Plan + Unplanned | R15: =138.9954875+43 -> 181.99549 | S15: 285.81185 | T15: 280.101 | U15: 387.10333 | V15: 279.553 | W15: =W22+W30 -> 229.02375 | X15: =X22+X30 -> 252.78109 | Y15: =Y22+Y30 -> 218.64282 | Z15: =Z22+Z30 -> 260.75833 | AA15: =AA22+AA30 -> 323.88601 | AB15: =AB22+AB30 -> 313.12322 | AC15: =AC22+AC30 -> 243.22774 | AD15: =AD22+AD30 -> 374.40627
Q16: 2025 Outages | R16: =R38 -> 107.51145 | S16: =S38 -> 160.53304 | T16: =T38 -> 206.75565 | U16: =U38 -> 256.96167 | V16: =V38 -> 181.41016 | W16: 102.614 | X16: 66.1371 | Y16: 74.2575 | Z16: 103.175 | AA16: 322.5731 | AB16: 355.53 | AC16: 159.79 | AD16: =AD38 -> 0
Q17: vs 2026 | R17: =(R$15-R16)/R16 -> 0.69280095 | S17: =(S$15-S16)/S16 -> 0.78039272 | T17: =(T$15-T16)/T16 -> 0.35474415 | U17: =(U$15-U16)/U16 -> 0.50646332 | V17: =(V$15-V16)/V16 -> 0.54099968 | W17: =(W$15-W16)/W16 -> 1.2318957 | X17: =(X$15-X16)/X16 -> 2.822077 | Y17: =(Y$15-Y16)/Y16 -> 1.9443871 | ... AD17: =(AD$15-AD16)/AD16 -> #DIV/0! | AH17: -76.529032 | AI17: -123.27586 | AJ17: -98.316129 | AK17: -103.94833 | AL17: -100.94839
Q18: 2024 Outages | R18: 76.529032 | S18: 123.27586 | T18: 98.316129 | U18: 103.94833 | V18: 100.94839 | W18: 185.8 | X18: 4.2 | Y18: 20.7 | Z18: 108.1 | AA18: 135.2 | AB18: 75.9 | AC18: 40.5 | AD18: 37.6 | AG18: 2024 | AH18: =-1*AH17 -> 76.529032 | AI18: =-1*AI17 -> 123.27586 | AJ18: =-1*AJ17 -> 98.316129 | AK18: =-1*AK17 -> 103.94833 | AL18: =-1*AL17 -> 100.94839
Q19: vs 2026 | R19: =(R15-R18)/R18 -> 1.3781235 | S19: =(S15-S18)/S18 -> 1.3184737 | T19: =(T15-T18)/T18 -> 1.8489832 | U19: =(U15-U18)/U18 -> 2.7239974 | V19: =(V15-V18)/V18 -> 1.7692666 | W19: =(W$15-W18)/W18 -> 0.2326359 | X19: =(X$15-X18)/X18 -> 59.185974 | Y19: =(Y$15-Y18)/Y18 -> 9.5624552 | Z19: =(Z$15-Z18)/Z18 -> 1.4121955 | AA19: =(AA$15-AA18)/AA18 -> 1.3956066 | AB19: =(AB$15-AB18)/AB18 -> 3.1254706 | AC19: =(AC$15-AC18)/AC18 -> 5.0056233 | AD19: =(AD$15-AD18)/AD18 -> 8.9576135
Q20: 2023 Outages | R20: 125.1 | S20: 118.5 | T20: 126.3 | U20: 17.7 | V20: 93.3 | W20: 30.6 | X20: 20.5 | Y20: 30.5 | Z20: 37.3 | AA20: 156 | AB20: 151.7 | AC20: 42.5 | AD20: 136.6
Q21: vs 2026 | R21: =(R15-R20)/R20 -> 0.45480006 | S21: =(S15-S20)/S20 -> 1.4119143 | T21: =(T15-T20)/T20 -> 1.2177435 | U21: =(U15-U20)/U20 -> 20.870244 | V21: =(V15-V20)/V20 -> 1.9962808 | W21: =(W15-W20)/W20 -> 6.4844363 | X21: =(X15-X20)/X20 -> 11.330785 | Y21: =(Y15-Y20)/Y20 -> 6.1686171 | ... AD21: =(AD15-AD20)/AD20 -> 1.7408951
O22: 26 ‘25, 24, & '23 Planned ONLY | Q22: 2026 Plan | R22: =R44+R45 -> 110.08425 | S22: =S44+S45 -> 186.08 | T22: =T44+T45 -> 216.8635 | U22: =U44+U45 -> 212.59225 | V22: =V44+V45 -> 210.96825 | W22: =W44+W45 -> 206.92025 | X22: =X44+X45 -> 220.5825 | Y22: =Y44+Y45 -> 187 | ... AC22: =AC44+AC45 -> 190.12 | AD22: =AD44 -> 404.67721 | AF22: =(#REF!-#REF!)*30*4 -> #REF! | AG22: =#REF!-148 -> #REF!
Q23: 2025 Outages | R23: 67.519355 | S23: 70.993088 | T23: 89.196774 | U23: 102.4 | V23: 41.532258 | W23: 19.7 | X23: 0.77419355 | Y23: 0.92903226 | Z23: 38 | AA23: 177.15237 | AB23: 192.38233 | AC23: 93.574516 | AD23: =AVERAGE(R23:AC23) -> 74.512826
Q24: vs 2026 | R24: =IFERROR((R22-R23)/R23,"") -> 0.63041028 | S24: =IFERROR((S22-S23)/S23,"") -> 1.6211003 | T24: =IFERROR((T22-T23)/T23,"") -> 1.4312931 | U24: =IFERROR((U22-U23)/U23,"") -> 1.0760962 | V24: =IFERROR((V22-V23)/V23,"") -> 4.0796239 | W24: =IFERROR((W22-W23)/W23,"") -> 9.503566 | X24: =IFERROR((X22-X23)/X23,"") -> 283.91906 | Y24: =IFERROR((Y22-Y23)/Y23,"") -> 200.28472 | ... AD24: =IFERROR((AD22-AD23)/AD23,"") -> 4.4309739 | AH24: 25.909677 | AI24: 8.3725 | AJ24: 11.34 | AK24: 118.53933 | AL24: 129.53409 | AM24: 117.55667 | AN24: 103.05 | AO24: 103.05 | AP24: 103.05 | AQ24: 103.05 | AR24: 103.05 | AS24: 103.05
Q25: 2024 Outages | R25: 33.18871 | S25: 51.103448 | T25: 71.543333 | U25: 107.34333 | V25: 163.27452 | W25: 151.4 | X25: 3.6 | Y25: 1.7 | Z25: 6.6 | AA25: 8.6 | AB25: 2.5 | AC25: 0.5 | AD25: 158.4 | AH25: =65+19 -> 84 | AI25: =65+19 -> 84 | AJ25: =65+19 -> 84 | AK25: =65+19 -> 84 | AL25: =65+19 -> 84 | AM25: =65+19 -> 84 | AN25: =65+19 -> 84 | AO25: =65+19 -> 84 | ... AS25: =65+19 -> 84
Q26: vs 2026 | R26: =(R22-R25)/R25 -> 2.3169186 | S26: =(S22-S25)/S25 -> 2.6412416 | T26: =(T22-T25)/T25 -> 2.0312188 | U26: =(U22-U25)/U25 -> 0.98048862 | V26: =(V22-V25)/V25 -> 0.29210764 | W26: =(W22-W25)/W25 -> 0.36671235 | X26: =(X22-X25)/X25 -> 60.272917 | Y26: =(Y22-Y25)/Y25 -> 109 | ... AD26: =(AD22-AD25)/AD25 -> 1.5547804 | AH26: =SUM(AH24:AH25) -> 109.90968 | AI26: =SUM(AI24:AI25) -> 92.3725 | AJ26: =SUM(AJ24:AJ25) -> 95.34 | AK26: =SUM(AK24:AK25) -> 202.53933 | AL26: =SUM(AL24:AL25) -> 213.53409 | AM26: =SUM(AM24:AM25) -> 201.55667 | AN26: =SUM(AN24:AN25) -> 187.05 | AO26: =SUM(AO24:AO25) -> 187.05 | ... AS26: =SUM(AS24:AS25) -> 187.05
Q27: 2023 Outages | R27: 80.9 | S27: 150.8 | T27: 65 | U27: 132.5 | V27: 93 | W27: 25.1 | X27: 0 | Y27: 27.9 | Z27: 27.7 | AA27: 149.3 | AB27: 108.3 | AC27: 27 | AD27: 32.1
Q28: vs 2026 | R28: =(R22-R27)/R27 -> 0.36074475 | S28: =(S22-S27)/S27 -> 0.23395225 | T28: =(T22-T27)/T27 -> 2.3363615 | U28: =(U22-U27)/U27 -> 0.60446981 | V28: =(V22-V27)/V27 -> 1.2684758 | W28: =(W22-W27)/W27 -> 7.2438347 | X28: =(X22-X27)/X27 -> #DIV/0! | Y28: =(Y22-Y27)/Y27 -> 5.702509 | ... AD28: =(AD22-AD27)/AD27 -> 11.606767
Q30: 2026 Unplanned Outages Estimate | R30: =R15-R22 -> 71.911237 | S30: =S15-S22 -> 99.731848 | T30: =T15-T22 -> 63.2375 | U30: =U15-U22 -> 174.51108 | V30: =V15-V22 -> 68.58475 | W30: =W35 -> 22.1035 | X30: =X35 -> 32.19859 | Y30: =Y35 -> 31.642823 | Z30: =Z35 -> 58.758333 | AA30: =AA35 -> 53.886009 | AB30: =AB35 -> 54.123216 | AC30: =AC35 -> 53.107742 | AD30: =AD35 -> -30.270942
Q31: 2025 Unplanned Outages | R31: =R16-R23 -> 39.992097 | S31: =S16-S23 -> 89.539948 | T31: =T16-T23 -> 117.55887 | U31: =U16-U23 -> 154.56167 | V31: =V16-V23 -> 139.8779 | W31: =W16-W23 -> 82.914 | X31: =X16-X23 -> 65.362906 | Y31: =Y16-Y23 -> 73.328468 | ... AD31: =AD16-AD23 -> -74.512826
Q32: 2024 Unplanned Outages | R32: =R18-R25 -> 43.340323 | S32: =S18-S25 -> 72.172414 | T32: =T18-T25 -> 26.772796 | U32: =U18-U25 -> -3.395 | V32: =V18-V25 -> -62.326129 | W32: =W18-W25 -> 34.4 | X32: =X18-X25 -> 0.6 | Y32: =Y18-Y25 -> 19 | ... AD32: =AD18-AD25 -> -120.8
Q33: 2023 Unplanned Outages | R33: =R20-R27 -> 44.2 | S33: =S20-S27 -> -32.3 | T33: =T20-T27 -> 61.3 | U33: =U20-U27 -> -114.8 | V33: =V20-V27 -> 0.3 | W33: =W20-W27 -> 5.5 | X33: =X20-X27 -> 20.5 | Y33: =Y20-Y27 -> 2.6 | ... AD33: =AD20-AD27 -> 104.5
Q34: 3yr avg | R34: =AVERAGE(R31:R33) -> 42.510806 | S34: =AVERAGE(S31:S33) -> 43.137454 | T34: =AVERAGE(T32:T33) -> 44.036398 | U34: =AVERAGE(U31:U32) -> 75.583333 | V34: =AVERAGE(V31) -> 139.8779 | W34: =AVERAGE(W31,W33) -> 44.207 | X34: =AVERAGE(X31,X33) -> 42.931453 | Y34: =AVERAGE(Y31:Y33) -> 31.642823 | Z34: =AVERAGE(Z31:Z33) -> 58.758333 | AA34: =AVERAGE(AA31:AA33) -> 92.906911 | AB34: =AVERAGE(AB31:AB33) -> 93.315889 | AC34: =AVERAGE(AC31:AC32) -> 53.107742 | AD34: =AVERAGE(AD31:AD33) -> -30.270942
R35: =R34*0.8 -> 34.008645 | S35: =S34*0.3 -> 12.941236 | T35: =T34 -> 44.036398 | U35: =U34*0.8 -> 60.466667 | V35: =V34*0.4 -> 55.951161 | W35: =W34*0.5 -> 22.1035 | X35: =X34*0.75 -> 32.19859 | Y35: =Y34 -> 31.642823 | Z35: =Z34 -> 58.758333 | AA35: =AA34*0.58 -> 53.886009 | AB35: =AB34*0.58 -> 54.123216 | AC35: =AC34*1 -> 53.107742 | AD35: =AD34 -> -30.270942
R38: =R39*-1 -> 107.51145 | S38: =S39*-1 -> 160.53304 | T38: =T39*-1 -> 206.75565 | U38: =U39*-1 -> 256.96167 | V38: =V39*-1 -> 181.41016 | W38: =W39*-1 -> 102.61367 | X38: =X39*-1 -> 66.137 | Y38: =Y39*-1 -> 0 | ... AD38: =AD39*-1 -> 0
R39: -107.51145 | S39: -160.53304 | T39: -206.75565 | U39: -256.96167 | V39: -181.41016 | W39: -102.61367 | X39: -66.137
R40: 25.909677 | S40: 8.3725 | T40: 11.34 | U40: =118.539333333333 -> 118.53933 | V40: 129.53409 | W40: 117.55667 | X40: 103.05 | Y40: -6.6471237 | Z40: -13.931962 | AA40: =118.539333333333 -> 118.53933 | AB40: 105.57925 | AC40: 93.601828 | AD40: -21.216801
R41: 26.08425 | S41: 34.88 | T41: 29.8635 | U41: 25.59225 | V41: 23.96825 | W41: 19.92025 | X41: 33.5825 | Z41: 15 | AA41: 83 | AB41: 72 | AC41: 3.12 | AD41: 320.67721
Q42: p66 wilimington | R42: 65 | S42: 65 | T42: 65 | U42: 65 | V42: 65 | W42: 65 | X42: 65 | Y42: 65 | Z42: 65 | AA42: 65 | AB42: 65 | AC42: 65 | AD42: 65
Q43: carson | R43: 19 | S43: 19 | T43: 19 | U43: 19 | V43: 19 | W43: 19 | X43: 19 | Y43: 19 | Z43: 19 | AA43: 19 | AB43: 19 | AC43: 19 | AD43: 19
R44: =R42+R41+R43 -> 110.08425 | S44: =S42+S41+S43 -> 118.88 | T44: =T42+T41+T43 -> 113.8635 | U44: =U42+U41+U43 -> 109.59225 | V44: =V42+V41+V43 -> 107.96825 | W44: =W42+W41+W43 -> 103.92025 | X44: =X42+X41+X43 -> 117.5825 | Y44: =Y42+Y41+Y43 -> 84 | ... AD44: =AD42+AD41+AD43 -> 404.67721
Q45: Benicia | R45: 0 | S45: 67.2 | T45: 103 | U45: 103 | V45: 103 | W45: 103 | X45: 103 | Y45: 103 | Z45: 103 | AA45: 103 | AB45: 103 | AC45: 103 | AD45: 103
Q47: 46192 | R47: 181.99549 | S47: 285.81185 | T47: 280.101 | U47: 387.10333 | V47: 279.553 | W47: 229.02375 | X47: 252.78109 | Y47: 218.64282 | Z47: 260.75833 | AA47: 323.88601 | AB47: 313.12322 | AC47: 243.22774
...

Sheet US
Q2: 2024 Planned Offline Mogas Production
B3: Sum of Capacity Offline for Area Chart (KBD) | C3: Column Labels | Q3: Sum of Capacity Offline for Area Chart (KBD) | R3: Column Labels
B4: Row Labels | C4: Jan | D4: Feb | E4: Mar | F4: Apr | G4: May | H4: Jun | I4: Sep | J4: Oct | K4: Nov | L4: Dec | M4: Grand Total | Q4: Row Labels | R4: Jan | S4: Feb | T4: Mar | U4: Apr | V4: May | W4: Jun | X4: Jul | Y4: Aug | Z4: Sep | AA4: Oct | AB4: Nov | AC4: Dec | AD4: Total
B5: Chalmette Refining LLC | C5: 220.76 | D5: 77.745714 | L5: 24.768571 | M5: 323.27429 | Q5: Chalmette Refining LLC | R5: =C5/4 -> 55.19 | S5: =D5/4 -> 19.436429 | T5: =E5/4 -> 0 | U5: =F5/4 -> 0 | V5: =G5/4 -> 0 | W5: =H5/4 -> 0 | X5: 0 | Y5: 0 | Z5: =I5/4 -> 0 | AA5: =J5/4 -> 0 | AB5: =K5/4 -> 0 | AC5: =L5/4 -> 6.1921429
B6: Chalmette Refinery | C6: 220.76 | D6: 77.745714 | L6: 24.768571 | M6: 323.27429 | Q6: Chalmette Refinery | R6: =C6/4 -> 55.19 | S6: =D6/4 -> 19.436429 | T6: =E6/4 -> 0 | U6: =F6/4 -> 0 | V6: =G6/4 -> 0 | W6: =H6/4 -> 0 | X6: 0 | Y6: 0 | Z6: =I6/4 -> 0 | AA6: =J6/4 -> 0 | AB6: =K6/4 -> 0 | AC6: =L6/4 -> 6.1921429
B7: Chevron Corporation | F7: 43.2 | G7: 86.4 | H7: 43.2 | M7: 172.8 | Q7: Chevron Corporation | R7: =C7/4 -> 0 | S7: =D7/4 -> 0 | T7: =E7/4 -> 0 | U7: =F7/4 -> 10.8 | V7: =G7/4 -> 21.6 | W7: =H7/4 -> 10.8 | X7: 0 | Y7: 0 | Z7: =I7/4 -> 0 | AA7: =J7/4 -> 0 | AB7: =K7/4 -> 0 | AC7: =L7/4 -> 0
B8: Pasadena Refinery | F8: 43.2 | G8: 86.4 | H8: 43.2 | M8: 172.8 | Q8: Pasadena Refinery | R8: =C8/4 -> 0 | S8: =D8/4 -> 0 | T8: =E8/4 -> 0 | U8: =F8/4 -> 10.8 | V8: =G8/4 -> 21.6 | W8: =H8/4 -> 10.8 | X8: 0 | Y8: 0 | Z8: =I8/4 -> 0 | AA8: =J8/4 -> 0 | AB8: =K8/4 -> 0 | AC8: =L8/4 -> 0
B9: CITGO Petroleum Corporation | C9: 19.942857 | D9: 267.2 | E9: 392.14 | F9: 97.8 | I9: 180.51429 | J9: 187.2 | K9: 33.428571 | M9: 1178.2257 | Q9: CITGO Petroleum Corporation | R9: =C9/4 -> 4.9857143 | S9: =D9/4 -> 66.8 | T9: =E9/4 -> 98.035 | U9: =F9/4 -> 24.45 | V9: =G9/4 -> 0 | W9: =H9/4 -> 0 | X9: 0 | Y9: 0 | Z9: =I9/4 -> 45.128571 | AA9: =J9/4 -> 46.8 | AB9: =K9/4 -> 8.3571429 | AC9: =L9/4 -> 0
B10: Corpus Christi Refinery - West (CITGO) | E10: 83.785714 | F10: 69.214286 | M10: 153 | Q10: Corpus Christi Refinery - West (CITGO) | R10: =C10/4 -> 0 | S10: =D10/4 -> 0 | T10: =E10/4 -> 20.946429 | U10: =F10/4 -> 17.303571 | V10: =G10/4 -> 0 | W10: =H10/4 -> 0 | X10: 0 | Y10: 0 | Z10: =I10/4 -> 0 | AA10: =J10/4 -> 0 | AB10: =K10/4 -> 0 | AC10: =L10/4 -> 0
B11: Corpus Christi Refinery-East | E11: 194.38286 | F11: 28.585714 | M11: 222.96857 | Q11: Corpus Christi Refinery-East | R11: =C11/4 -> 0 | S11: =D11/4 -> 0 | T11: =E11/4 -> 48.595714 | U11: =F11/4 -> 7.1464286 | V11: =G11/4 -> 0 | W11: =H11/4 -> 0 | X11: 0 | Y11: 0 | Z11: =I11/4 -> 0 | AA11: =J11/4 -> 0 | AB11: =K11/4 -> 0 | AC11: =L11/4 -> 0
B12: Lake Charles Refinery (CITGO) | C12: 19.942857 | D12: 267.2 | E12: 113.97143 | I12: 180.51429 | J12: 187.2 | K12: 33.428571 | M12: 802.25714 | Q12: Lake Charles Refinery (CITGO) | R12: =C12/4 -> 4.9857143 | S12: =D12/4 -> 66.8 | T12: =E12/4 -> 28.492857 | U12: =F12/4 -> 0 | V12: =G12/4 -> 0 | W12: =H12/4 -> 0 | X12: 0 | Y12: 0 | Z12: =I12/4 -> 45.128571 | AA12: =J12/4 -> 46.8 | AB12: =K12/4 -> 8.3571429 | AC12: =L12/4 -> 0
B13: Deer Park Refining LP | I13: 27.867857 | J13: 156.06 | K13: 11.147143 | M13: 195.075 | Q13: Deer Park Refining LP | R13: =C13/4 -> 0 | S13: =D13/4 -> 0 | T13: =E13/4 -> 0 | U13: =F13/4 -> 0 | V13: =G13/4 -> 0 | W13: =H13/4 -> 0 | X13: 0 | Y13: 0 | Z13: =I13/4 -> 6.9669643 | AA13: =J13/4 -> 39.015 | AB13: =K13/4 -> 2.7867857 | AC13: =L13/4 -> 0
B14: Deer Park Refinery | I14: 27.867857 | J14: 156.06 | K14: 11.147143 | M14: 195.075 | Q14: Deer Park Refinery | R14: =C14/4 -> 0 | S14: =D14/4 -> 0 | T14: =E14/4 -> 0 | U14: =F14/4 -> 0 | V14: =G14/4 -> 0 | W14: =H14/4 -> 0 | X14: 0 | Y14: 0 | Z14: =I14/4 -> 6.9669643 | AA14: =J14/4 -> 39.015 | AB14: =K14/4 -> 2.7867857 | AC14: =L14/4 -> 0
B15: Delek US Holdings | J15: 115.32857 | K15: 76.885714 | M15: 192.21429 | Q15: Delek US Holdings | R15: =C15/4 -> 0 | S15: =D15/4 -> 0 | T15: =E15/4 -> 0 | U15: =F15/4 -> 0 | V15: =G15/4 -> 0 | W15: =H15/4 -> 0 | X15: 0 | Y15: 0 | Z15: =I15/4 -> 0 | AA15: =J15/4 -> 28.832143 | AB15: =K15/4 -> 19.221429 | AC15: =L15/4 -> 0
B16: Krotz Springs Refinery | J16: 115.32857 | K16: 76.885714 | M16: 192.21429 | Q16: Krotz Springs Refinery | R16: =C16/4 -> 0 | S16: =D16/4 -> 0 | T16: =E16/4 -> 0 | U16: =F16/4 -> 0 | V16: =G16/4 -> 0 | W16: =H16/4 -> 0 | X16: 0 | Y16: 0 | Z16: =I16/4 -> 0 | AA16: =J16/4 -> 28.832143 | AB16: =K16/4 -> 19.221429 | AC16: =L16/4 -> 0
B17: ExxonMobil Corporation | C17: 433.67857 | D17: 413.73571 | L17: 18.228571 | M17: 865.64286 | Q17: ExxonMobil Corporation | R17: =C17/4 -> 108.41964 | S17: =D17/4 -> 103.43393 | T17: =E17/4 -> 0 | U17: =F17/4 -> 0 | V17: =G17/4 -> 0 | W17: =H17/4 -> 0 | X17: 0 | Y17: 0 | Z17: =I17/4 -> 0 | AA17: =J17/4 -> 0 | AB17: =K17/4 -> 0 | AC17: =L17/4 -> 4.5571429
B18: Baton Rouge Refinery | C18: 255.2 | D18: 45.571429 | L18: 18.228571 | M18: 319 | Q18: Baton Rouge Refinery | R18: =C18/4 -> 63.8 | S18: =D18/4 -> 11.392857 | T18: =E18/4 -> 0 | U18: =F18/4 -> 0 | V18: =G18/4 -> 0 | W18: =H18/4 -> 0 | X18: 0 | Y18: 0 | Z18: =I18/4 -> 0 | AA18: =J18/4 -> 0 | AB18: =K18/4 -> 0 | AC18: =L18/4 -> 4.5571429
B19: Baytown Refinery | C19: 159.19286 | D19: 117.66429 | M19: 276.85714 | Q19: Baytown Refinery | R19: =C19/4 -> 39.798214 | S19: =D19/4 -> 29.416071 | T19: =E19/4 -> 0 | U19: =F19/4 -> 0 | V19: =G19/4 -> 0 | W19: =H19/4 -> 0 | X19: 0 | Y19: 0 | Z19: =I19/4 -> 0 | AA19: =J19/4 -> 0 | AB19: =K19/4 -> 0 | AC19: =L19/4 -> 0
B20: Beaumont Refinery | C20: 19.285714 | D20: 250.5 | M20: 269.78571 | Q20: Beaumont Refinery | R20: =C20/4 -> 4.8214286 | S20: =D20/4 -> 62.625 | T20: =E20/4 -> 0 | U20: =F20/4 -> 0 | V20: =G20/4 -> 0 | W20: =H20/4 -> 0 | X20: 0 | Y20: 0 | Z20: =I20/4 -> 0 | AA20: =J20/4 -> 0 | AB20: =K20/4 -> 0 | AC20: =L20/4 -> 0
B21: Flint Hills Resources LLC | C21: 155.81429 | D21: 155.81429 | I21: 91.142857 | J21: 68.357143 | M21: 471.12857 | Q21: Flint Hills Resources LLC | R21: =C21/4 -> 38.953571 | S21: =D21/4 -> 38.953571 | T21: =E21/4 -> 0 | U21: =F21/4 -> 0 | V21: =G21/4 -> 0 | W21: =H21/4 -> 0 | X21: 0 | Y21: 0 | Z21: =I21/4 -> 22.785714 | AA21: =J21/4 -> 17.089286 | AB21: =K21/4 -> 0 | AC21: =L21/4 -> 0
B22: Corpus Christi Refinery - East | I22: 91.142857 | J22: 68.357143 | M22: 159.5 | Q22: Corpus Christi Refinery - East | R22: =C22/4 -> 0 | S22: =D22/4 -> 0 | T22: =E22/4 -> 0 | U22: =F22/4 -> 0 | V22: =G22/4 -> 0 | W22: =H22/4 -> 0 | X22: 0 | Y22: 0 | Z22: =I22/4 -> 22.785714 | AA22: =J22/4 -> 17.089286 | AB22: =K22/4 -> 0 | AC22: =L22/4 -> 0
B23: Corpus Christi Refinery - West (Flint Hills) | C23: 155.81429 | D23: 155.81429 | M23: 311.62857 | Q23: Corpus Christi Refinery - West (Flint Hills) | R23: =C23/4 -> 38.953571 | S23: =D23/4 -> 38.953571 | T23: =E23/4 -> 0 | U23: =F23/4 -> 0 | V23: =G23/4 -> 0 | W23: =H23/4 -> 0 | X23: 0 | Y23: 0 | Z23: =I23/4 -> 0 | AA23: =J23/4 -> 0 | AB23: =K23/4 -> 0 | AC23: =L23/4 -> 0
B24: Marathon Petroleum Corporation | C24: 160.82857 | D24: 49.485714 | M24: 210.31429 | Q24: Marathon Petroleum Corporation | R24: =C24/4 -> 40.207143 | S24: =D24/4 -> 12.371429 | T24: =E24/4 -> 0 | U24: =F24/4 -> 0 | V24: =G24/4 -> 0 | W24: =H24/4 -> 0 | X24: 0 | Y24: 0 | Z24: =I24/4 -> 0 | AA24: =J24/4 -> 0 | AB24: =K24/4 -> 0 | AC24: =L24/4 -> 0
B25: Texas City Refinery (Bay Plant) | C25: 160.82857 | D25: 49.485714 | M25: 210.31429 | Q25: Texas City Refinery (Bay Plant) | R25: =C25/4 -> 40.207143 | S25: =D25/4 -> 12.371429 | T25: =E25/4 -> 0 | U25: =F25/4 -> 0 | V25: =G25/4 -> 0 | W25: =H25/4 -> 0 | X25: 0 | Y25: 0 | Z25: =I25/4 -> 0 | AA25: =J25/4 -> 0 | AB25: =K25/4 -> 0 | AC25: =L25/4 -> 0
B26: Phillips 66 | D26: 9 | E26: 157.5 | F26: 22.5 | I26: 76.56 | J26: 107.184 | K26: 45.936 | M26: 418.68 | Q26: Phillips 66 | R26: =C26/4 -> 0 | S26: =D26/4 -> 2.25 | T26: =E26/4 -> 39.375 | U26: =F26/4 -> 5.625 | V26: =G26/4 -> 0 | W26: =H26/4 -> 0 | X26: 0 | Y26: 0 | Z26: =I26/4 -> 19.14 | AA26: =J26/4 -> 26.796 | AB26: =K26/4 -> 11.484 | AC26: =L26/4 -> 0
B27: Lake Charles Refinery (Phillips 66) | I27: 76.56 | J27: 107.184 | K27: 45.936 | M27: 229.68 | Q27: Lake Charles Refinery (Phillips 66) | R27: =C27/4 -> 0 | S27: =D27/4 -> 0 | T27: =E27/4 -> 0 | U27: =F27/4 -> 0 | V27: =G27/4 -> 0 | W27: =H27/4 -> 0 | X27: 0 | Y27: 0 | Z27: =I27/4 -> 19.14 | AA27: =J27/4 -> 26.796 | AB27: =K27/4 -> 11.484 | AC27: =L27/4 -> 0
B28: Sweeny Refinery | D28: 9 | E28: 157.5 | F28: 22.5 | M28: 189 | Q28: Sweeny Refinery | R28: =C28/4 -> 0 | S28: =D28/4 -> 2.25 | T28: =E28/4 -> 39.375 | U28: =F28/4 -> 5.625 | V28: =G28/4 -> 0 | W28: =H28/4 -> 0 | X28: 0 | Y28: 0 | Z28: =I28/4 -> 0 | AA28: =J28/4 -> 0 | AB28: =K28/4 -> 0 | AC28: =L28/4 -> 0
B29: Valero Refining Company | C29: 374.16 | D29: 319.51714 | E29: 51.04 | I29: 19.794286 | J29: 277.12 | K29: 98.971429 | L29: 26.725714 | M29: 1167.3286 | Q29: Valero Refining Company | R29: =C29/4 -> 93.54 | S29: =D29/4 -> 79.879286 | T29: =E29/4 -> 12.76 | U29: =F29/4 -> 0 | V29: =G29/4 -> 0 | W29: =H29/4 -> 0 | X29: 0 | Y29: 0 | Z29: =I29/4 -> 4.9485714 | AA29: =J29/4 -> 69.28 | AB29: =K29/4 -> 24.742857 | AC29: =L29/4 -> 6.6814286
